Workbook

Sheet 본사창고
A1: 카페 쿠피 1월 입출고 관리 대장 (본사창고)
A4: 협력사 | B4: 품목명 | C4: 규격 | D4: 단위 | E4: 입고단가 | F4: 입고단위 | G4: 입고단위단가 | H4: 전월 재고 | I4: 1주차 입고 | J4: 2주차 입고 | K4: 3주차 입고 | L4: 4주차 입고 | M4: 5주차 입고 | N4: 월 입고량 | O4: 월 입고 금액 | P4: 1주차 출고량 | Q4: 2주차 출고량 | R4: 3주차 출고량 | S4: 4주차 출고량 | T4: 5주차 출고량 | U4: 월 출고량 | V4: 월 출고 금액 | W4: 현재고 | X4: 현재고 금액 | Y4: 24년 1,2,3월 출고량 | Z4: 발주량 | AA4: 발주금액 | AB4: 발주합계 (부가세 별도) | AC4: 발주합계 (부가세 포함)
A5: 비스토리코리아 | B5: 종이컵(-12oz) | C5: 1box=1000ea | D5: ea | E5: 37 | F5: 1000 | G5: 37000 | H5: 4000 | N5: =I5+J5+K5+L5+M5 -> 0 | O5: =E5*N5 -> 0 | P5: =캠퍼스타운_외부원두영업!I5+잇다카페_외부원두영업!I5+푸른솔!J5+의과대학!I5+중앙도서관!I5+학생회관!I5+멀티미디어관!I5+제2기숙사!I5+선승관!I5+예술디자인대!I5+공학관!I5 -> 0 | Q5: =캠퍼스타운_외부원두영업!J5+잇다카페_외부원두영업!J5+푸른솔!K5+의과대학!J5+중앙도서관!J5+학생회관!J5+멀티미디어관!J5+제2기숙사!J5+선승관!J5+예술디자인대!J5+공학관!J5 -> 1000 | R5: =캠퍼스타운_외부원두영업!K5+잇다카페_외부원두영업!K5+푸른솔!L5+의과대학!K5+중앙도서관!K5+학생회관!K5+제2기숙사!K5+멀티미디어관!K5+선승관!K5+예술디자인대!K5+공학관!K5 -> 0 | S5: =캠퍼스타운_외부원두영업!L5+잇다카페_외부원두영업!L5+푸른솔!M5+의과대학!L5+중앙도서관!L5+학생회관!L5+멀티미디어관!L5+제2기숙사!L5+선승관!L5+예술디자인대!L5+공학관!L5 -> 0 | T5: =캠퍼스타운_외부원두영업!M5+잇다카페_외부원두영업!M5+푸른솔!N5+의과대학!M5+중앙도서관!M5+학생회관!M5+멀티미디어관!M5+제2기숙사!M5+선승관!M5+예술디자인대!M5+공학관!M5 -> 0 | U5: =P5+Q5+R5+S5+T5 -> 1000 | V5: =E5*U5 -> 37000 | W5: =(H5+N5)-U5 -> 3000 | X5: =E5*W5 -> 111000 | Y5: 1000 | Z5: 0 | AA5: =Z5*E5 -> 0 | AB5: =SUM(AA5:AA40) -> 4954000 | AC5: =AB5*1.1 -> 5449400
B6: 종이컵-16oz | C6: 1box=1000ea | D6: ea | E6: 43 | F6: 1000 | G6: 43000 | H6: 1000 | K6: 10000 | N6: =I6+J6+K6+L6+M6 -> 10000 | O6: =E6*N6 -> 430000 | P6: =캠퍼스타운_외부원두영업!I6+잇다카페_외부원두영업!I6+푸른솔!J6+의과대학!I6+중앙도서관!I6+학생회관!I6+제2기숙사!I6+멀티미디어관!I6+선승관!I6+예술디자인대!I6+공학관!I6 -> 0 | Q6: =캠퍼스타운_외부원두영업!J6+잇다카페_외부원두영업!J6+푸른솔!K6+의과대학!J6+중앙도서관!J6+학생회관!J6+멀티미디어관!J6+제2기숙사!J6+선승관!J6+예술디자인대!J6+공학관!J6 -> 1000 | R6: =캠퍼스타운_외부원두영업!K6+잇다카페_외부원두영업!K6+푸른솔!L6+의과대학!K6+중앙도서관!K6+학생회관!K6+제2기숙사!K6+멀티미디어관!K6+선승관!K6+예술디자인대!K6+공학관!K6 -> 0 | S6: =캠퍼스타운_외부원두영업!L6+잇다카페_외부원두영업!L6+푸른솔!M6+의과대학!L6+중앙도서관!L6+학생회관!L6+멀티미디어관!L6+제2기숙사!L6+선승관!L6+예술디자인대!L6+공학관!L6 -> 1000 | T6: =캠퍼스타운_외부원두영업!M6+잇다카페_외부원두영업!M6+푸른솔!N6+의과대학!M6+중앙도서관!M6+학생회관!M6+멀티미디어관!M6+제2기숙사!M6+선승관!M6+예술디자인대!M6+공학관!M6 -> 0 | U6: =P6+Q6+R6+S6+T6 -> 2000 | V6: =E6*U6 -> 86000 | W6: =(H6+N6)-U6 -> 9000 | X6: =E6*W6 -> 387000 | Y6: 12000 | Z6: 10000 | AA6: =Z6*E6 -> 430000
B7: 종이컵뚜껑 (12,16oz) | C7: 1box=1000ea | D7: ea | E7: 20 | F7: 1000 | G7: 20000 | H7: 4000 | K7: 7000 | N7: =I7+J7+K7+L7+M7 -> 7000 | O7: =E7*N7 -> 140000 | P7: =캠퍼스타운_외부원두영업!I7+잇다카페_외부원두영업!I7+푸른솔!J7+의과대학!I7+중앙도서관!I7+학생회관!I7+제2기숙사!I7+멀티미디어관!I7+선승관!I7+예술디자인대!I7+공학관!I7 -> 0 | Q7: =캠퍼스타운_외부원두영업!J7+잇다카페_외부원두영업!J7+푸른솔!K7+의과대학!J7+중앙도서관!J7+학생회관!J7+멀티미디어관!J7+제2기숙사!J7+선승관!J7+예술디자인대!J7+공학관!J7 -> 1000 | R7: =캠퍼스타운_외부원두영업!K7+잇다카페_외부원두영업!K7+푸른솔!L7+의과대학!K7+중앙도서관!K7+학생회관!K7+제2기숙사!K7+멀티미디어관!K7+선승관!K7+예술디자인대!K7+공학관!K7 -> 0 | S7: =캠퍼스타운_외부원두영업!L7+잇다카페_외부원두영업!L7+푸른솔!M7+의과대학!L7+중앙도서관!L7+학생회관!L7+멀티미디어관!L7+제2기숙사!L7+선승관!L7+예술디자인대!L7+공학관!L7 -> 3000 | T7: =캠퍼스타운_외부원두영업!M7+잇다카페_외부원두영업!M7+푸른솔!N7+의과대학!M7+중앙도서관!M7+학생회관!M7+멀티미디어관!M7+제2기숙사!M7+선승관!M7+예술디자인대!M7+공학관!M7 -> 0 | U7: =P7+Q7+R7+S7+T7 -> 4000 | V7: =E7*U7 -> 80000 | W7: =(H7+N7)-U7 -> 7000 | X7: =E7*W7 -> 140000 | Y7: 12000 | Z7: 7000 | AA7: =Z7*E7 -> 140000
B8: 아이스(페트)컵(14oz) | C8: 1box=1000ea | D8: ea | E8: 42 | F8: 1000 | G8: 42000 | H8: 0 | N8: =I8+J8+K8+L8+M8 -> 0 | O8: =E8*N8 -> 0 | P8: =캠퍼스타운_외부원두영업!I8+잇다카페_외부원두영업!I8+푸른솔!J8+의과대학!I8+중앙도서관!I8+학생회관!I8+제2기숙사!I8+멀티미디어관!I8+선승관!I8+예술디자인대!I8+공학관!I8 -> 0 | Q8: =캠퍼스타운_외부원두영업!J8+잇다카페_외부원두영업!J8+푸른솔!K8+의과대학!J8+중앙도서관!J8+학생회관!J8+멀티미디어관!J8+제2기숙사!J8+선승관!J8+예술디자인대!J8+공학관!J8 -> 0 | R8: =캠퍼스타운_외부원두영업!K8+잇다카페_외부원두영업!K8+푸른솔!L8+의과대학!K8+중앙도서관!K8+학생회관!K8+제2기숙사!K8+멀티미디어관!K8+선승관!K8+예술디자인대!K8+공학관!K8 -> 0 | S8: =캠퍼스타운_외부원두영업!L8+잇다카페_외부원두영업!L8+푸른솔!M8+의과대학!L8+중앙도서관!L8+학생회관!L8+멀티미디어관!L8+제2기숙사!L8+선승관!L8+예술디자인대!L8+공학관!L8 -> 0 | T8: =캠퍼스타운_외부원두영업!M8+잇다카페_외부원두영업!M8+푸른솔!N8+의과대학!M8+중앙도서관!M8+학생회관!M8+멀티미디어관!M8+제2기숙사!M8+선승관!M8+예술디자인대!M8+공학관!M8 -> 0 | U8: =P8+Q8+R8+S8+T8 -> 0 | V8: =E8*U8 -> 0 | W8: =(H8+N8)-U8 -> 0 | X8: =E8*W8 -> 0 | Y8: 0 | Z8: 0 | AA8: =Z8*E8 -> 0
B9: 아이스컵(16oz) | C9: 1box=1000ea | D9: ea | E9: 53 | F9: 1000 | G9: 53000 | H9: 6000 | K9: 14000 | N9: =I9+J9+K9+L9+M9 -> 14000 | O9: =E9*N9 -> 742000 | P9: =캠퍼스타운_외부원두영업!I9+잇다카페_외부원두영업!I9+푸른솔!J9+의과대학!I9+중앙도서관!I9+학생회관!I9+제2기숙사!I9+멀티미디어관!I9+선승관!I9+예술디자인대!I9+공학관!I9 -> 0 | Q9: =캠퍼스타운_외부원두영업!J9+잇다카페_외부원두영업!J9+푸른솔!K9+의과대학!J9+중앙도서관!J9+학생회관!J9+멀티미디어관!J9+제2기숙사!J9+선승관!J9+예술디자인대!J9+공학관!J9 -> 0 | R9: =캠퍼스타운_외부원두영업!K9+잇다카페_외부원두영업!K9+푸른솔!L9+의과대학!K9+중앙도서관!K9+학생회관!K9+제2기숙사!K9+멀티미디어관!K9+선승관!K9+예술디자인대!K9+공학관!K9 -> 0 | S9: =캠퍼스타운_외부원두영업!L9+잇다카페_외부원두영업!L9+푸른솔!M9+의과대학!L9+중앙도서관!L9+학생회관!L9+멀티미디어관!L9+제2기숙사!L9+선승관!L9+예술디자인대!L9+공학관!L9 -> 1000 | T9: =캠퍼스타운_외부원두영업!M9+잇다카페_외부원두영업!M9+푸른솔!N9+의과대학!M9+중앙도서관!M9+학생회관!M9+멀티미디어관!M9+제2기숙사!M9+선승관!M9+예술디자인대!M9+공학관!M9 -> 0 | U9: =P9+Q9+R9+S9+T9 -> 1000 | V9: =E9*U9 -> 53000 | W9: =(H9+N9)-U9 -> 19000 | X9: =E9*W9 -> 1007000 | Y9: 22000 | Z9: 14000 | AA9: =Z9*E9 -> 742000
B10: 아이스컵(24oz) | C10: 1box=1000ea | D10: ea | E10: 65 | F10: 1000 | G10: 65000 | H10: 4000 | K10: 6000 | N10: =I10+J10+K10+L10+M10 -> 6000 | O10: =E10*N10 -> 390000 | P10: =캠퍼스타운_외부원두영업!I10+잇다카페_외부원두영업!I10+푸른솔!J10+의과대학!I10+중앙도서관!I10+학생회관!I10+제2기숙사!I10+멀티미디어관!I10+선승관!I10+예술디자인대!I10+공학관!I10 -> 0 | Q10: =캠퍼스타운_외부원두영업!J10+잇다카페_외부원두영업!J10+푸른솔!K10+의과대학!J10+중앙도서관!J10+학생회관!J10+멀티미디어관!J10+제2기숙사!J10+선승관!J10+예술디자인대!J10+공학관!J10 -> 0 | R10: =캠퍼스타운_외부원두영업!K10+잇다카페_외부원두영업!K10+푸른솔!L10+의과대학!K10+중앙도서관!K10+학생회관!K10+제2기숙사!K10+멀티미디어관!K10+선승관!K10+예술디자인대!K10+공학관!K10 -> 0 | S10: =캠퍼스타운_외부원두영업!L10+잇다카페_외부원두영업!L10+푸른솔!M10+의과대학!L10+중앙도서관!L10+학생회관!L10+멀티미디어관!L10+제2기숙사!L10+선승관!L10+예술디자인대!L10+공학관!L10 -> 1000 | T10: =캠퍼스타운_외부원두영업!M10+잇다카페_외부원두영업!M10+푸른솔!N10+의과대학!M10+중앙도서관!M10+학생회관!M10+멀티미디어관!M10+제2기숙사!M10+선승관!M10+예술디자인대!M10+공학관!M10 -> 0 | U10: =P10+Q10+R10+S10+T10 -> 1000 | V10: =E10*U10 -> 65000 | W10: =(H10+N10)-U10 -> 9000 | X10: =E10*W10 -> 585000 | Y10: 4000 | Z10: 6000 | AA10: =Z10*E10 -> 390000
B11: 아이스컵 돔뚜껑(93Ø) | C11: 1box=1000ea | D11: ea | E11: 18.5 | F11: 1000 | G11: 18500 | H11: 6000 | K11: 14000 | N11: =I11+J11+K11+L11+M11 -> 14000 | O11: =E11*N11 -> 259000 | P11: =캠퍼스타운_외부원두영업!I11+잇다카페_외부원두영업!I11+푸른솔!J11+의과대학!I11+중앙도서관!I11+학생회관!I11+제2기숙사!I11+멀티미디어관!I11+선승관!I11+예술디자인대!I11+공학관!I11 -> 0 | Q11: =캠퍼스타운_외부원두영업!J11+잇다카페_외부원두영업!J11+푸른솔!K11+의과대학!J11+중앙도서관!J11+학생회관!J11+멀티미디어관!J11+제2기숙사!J11+선승관!J11+예술디자인대!J11+공학관!J11 -> 0 | R11: =캠퍼스타운_외부원두영업!K11+잇다카페_외부원두영업!K11+푸른솔!L11+의과대학!K11+중앙도서관!K11+학생회관!K11+제2기숙사!K11+멀티미디어관!K11+선승관!K11+예술디자인대!K11+공학관!K11 -> 0 | S11: =캠퍼스타운_외부원두영업!L11+잇다카페_외부원두영업!L11+푸른솔!M11+의과대학!L11+중앙도서관!L11+학생회관!L11+멀티미디어관!L11+제2기숙사!L11+선승관!L11+예술디자인대!L11+공학관!L11 -> 4000 | T11: =캠퍼스타운_외부원두영업!M11+잇다카페_외부원두영업!M11+푸른솔!N11+의과대학!M11+중앙도서관!M11+학생회관!M11+멀티미디어관!M11+제2기숙사!M11+선승관!M11+예술디자인대!M11+공학관!M11 -> 0 | U11: =P11+Q11+R11+S11+T11 -> 4000 | V11: =E11*U11 -> 74000 | W11: =(H11+N11)-U11 -> 16000 | X11: =E11*W11 -> 296000 | Y11: 23000 | Z11: 14000 | AA11: =Z11*E11 -> 259000
B12: 아이스컵 돔뚜껑(98Ø) | C12: 1box=1000ea | D12: ea | E12: 20 | F12: 1000 | G12: 20000 | H12: 3000 | K12: 7000 | N12: =I12+J12+K12+L12+M12 -> 7000 | O12: =E12*N12 -> 140000 | P12: =캠퍼스타운_외부원두영업!I12+잇다카페_외부원두영업!I12+푸른솔!J12+의과대학!I12+중앙도서관!I12+학생회관!I12+제2기숙사!I12+멀티미디어관!I12+선승관!I12+예술디자인대!I12+공학관!I12 -> 0 | Q12: =캠퍼스타운_외부원두영업!J12+잇다카페_외부원두영업!J12+푸른솔!K12+의과대학!J12+중앙도서관!J12+학생회관!J12+멀티미디어관!J12+제2기숙사!J12+선승관!J12+예술디자인대!J12+공학관!J12 -> 0 | R12: =캠퍼스타운_외부원두영업!K12+잇다카페_외부원두영업!K12+푸른솔!L12+의과대학!K12+중앙도서관!K12+학생회관!K12+제2기숙사!K12+멀티미디어관!K12+선승관!K12+예술디자인대!K12+공학관!K12 -> 0 | S12: =캠퍼스타운_외부원두영업!L12+잇다카페_외부원두영업!L12+푸른솔!M12+의과대학!L12+중앙도서관!L12+학생회관!L12+멀티미디어관!L12+제2기숙사!L12+선승관!L12+예술디자인대!L12+공학관!L12 -> 0 | T12: =캠퍼스타운_외부원두영업!M12+잇다카페_외부원두영업!M12+푸른솔!N12+의과대학!M12+중앙도서관!M12+학생회관!M12+멀티미디어관!M12+제2기숙사!M12+선승관!M12+예술디자인대!M12+공학관!M12 -> 0 | U12: =P12+Q12+R12+S12+T12 -> 0 | V12: =E12*U12 -> 0 | W12: =(H12+N12)-U12 -> 10000 | X12: =E12*W12 -> 200000 | Y12: 3000 | Z12: 7000 | AA12: =Z12*E12 -> 140000
B13: 아이스컵 평뚜껑(98Ø) | C13: 1box=1000ea | D13: ea | E13: 19 | F13: 1000 | G13: 19000 | H13: 0 | N13: =I13+J13+K13+L13+M13 -> 0 | O13: =E13*N13 -> 0 | P13: =캠퍼스타운_외부원두영업!I13+잇다카페_외부원두영업!I13+푸른솔!J13+의과대학!I13+중앙도서관!I13+학생회관!I13+제2기숙사!I13+멀티미디어관!I13+선승관!I13+예술디자인대!I13+공학관!I13 -> 0 | Q13: =캠퍼스타운_외부원두영업!J13+잇다카페_외부원두영업!J13+푸른솔!K13+의과대학!J13+중앙도서관!J13+학생회관!J13+멀티미디어관!J13+제2기숙사!J13+선승관!J13+예술디자인대!J13+공학관!J13 -> 0 | R13: =캠퍼스타운_외부원두영업!K13+잇다카페_외부원두영업!K13+푸른솔!L13+의과대학!K13+중앙도서관!K13+학생회관!K13+제2기숙사!K13+멀티미디어관!K13+선승관!K13+예술디자인대!K13+공학관!K13 -> 0 | S13: =캠퍼스타운_외부원두영업!L13+잇다카페_외부원두영업!L13+푸른솔!M13+의과대학!L13+중앙도서관!L13+학생회관!L13+멀티미디어관!L13+제2기숙사!L13+선승관!L13+예술디자인대!L13+공학관!L13 -> 0 | T13: =캠퍼스타운_외부원두영업!M13+잇다카페_외부원두영업!M13+푸른솔!N13+의과대학!M13+중앙도서관!M13+학생회관!M13+멀티미디어관!M13+제2기숙사!M13+선승관!M13+예술디자인대!M13+공학관!M13 -> 0 | U13: =P13+Q13+R13+S13+T13 -> 0 | V13: =E13*U13 -> 0 | W13: =(H13+N13)-U13 -> 0 | X13: =E13*W13 -> 0 | Y13: 1000 | Z13: 0 | AA13: =Z13*E13 -> 0
B14: 10/13홀더 | C14: 1box=1000ea | D14: ea | E14: 17.5 | F14: 1000 | G14: 17500 | H14: 3000 | N14: =I14+J14+K14+L14+M14 -> 0 | O14: =E14*N14 -> 0 | P14: =캠퍼스타운_외부원두영업!I14+잇다카페_외부원두영업!I14+푸른솔!J14+의과대학!I14+중앙도서관!I14+학생회관!I14+제2기숙사!I14+멀티미디어관!I14+선승관!I14+예술디자인대!I14+공학관!I14 -> 0 | Q14: =캠퍼스타운_외부원두영업!J14+잇다카페_외부원두영업!J14+푸른솔!K14+의과대학!J14+중앙도서관!J14+학생회관!J14+멀티미디어관!J14+제2기숙사!J14+선승관!J14+예술디자인대!J14+공학관!J14 -> 0 | R14: =캠퍼스타운_외부원두영업!K14+잇다카페_외부원두영업!K14+푸른솔!L14+의과대학!K14+중앙도서관!K14+학생회관!K14+제2기숙사!K14+멀티미디어관!K14+선승관!K14+예술디자인대!K14+공학관!K14 -> 0 | S14: =캠퍼스타운_외부원두영업!L14+잇다카페_외부원두영업!L14+푸른솔!M14+의과대학!L14+중앙도서관!L14+학생회관!L14+멀티미디어관!L14+제2기숙사!L14+선승관!L14+예술디자인대!L14+공학관!L14 -> 0 | T14: =캠퍼스타운_외부원두영업!M14+잇다카페_외부원두영업!M14+푸른솔!N14+의과대학!M14+중앙도서관!M14+학생회관!M14+멀티미디어관!M14+제2기숙사!M14+선승관!M14+예술디자인대!M14+공학관!M14 -> 0 | U14: =P14+Q14+R14+S14+T14 -> 0 | V14: =E14*U14 -> 0 | W14: =(H14+N14)-U14 -> 3000 | X14: =E14*W14 -> 52500 | Y14: 1000 | Z14: 0 | AA14: =Z14*E14 -> 0
B15: 12/16홀더 | C15: 1box=1000ea | D15: ea | E15: 18 | F15: 1000 | G15: 18000 | H15: 4000 | K15: 30000 | N15: =I15+J15+K15+L15+M15 -> 30000 | O15: =E15*N15 -> 540000 | P15: =캠퍼스타운_외부원두영업!I15+잇다카페_외부원두영업!I15+푸른솔!J15+의과대학!I15+중앙도서관!I15+학생회관!I15+제2기숙사!I15+멀티미디어관!I15+선승관!I15+예술디자인대!I15+공학관!I15 -> 0 | Q15: =캠퍼스타운_외부원두영업!J15+잇다카페_외부원두영업!J15+푸른솔!K15+의과대학!J15+중앙도서관!J15+학생회관!J15+멀티미디어관!J15+제2기숙사!J15+선승관!J15+예술디자인대!J15+공학관!J15 -> 2000 | R15: =캠퍼스타운_외부원두영업!K15+잇다카페_외부원두영업!K15+푸른솔!L15+의과대학!K15+중앙도서관!K15+학생회관!K15+제2기숙사!K15+멀티미디어관!K15+선승관!K15+예술디자인대!K15+공학관!K15 -> 0 | S15: =캠퍼스타운_외부원두영업!L15+잇다카페_외부원두영업!L15+푸른솔!M15+의과대학!L15+중앙도서관!L15+학생회관!L15+멀티미디어관!L15+제2기숙사!L15+선승관!L15+예술디자인대!L15+공학관!L15 -> 6000 | T15: =캠퍼스타운_외부원두영업!M15+잇다카페_외부원두영업!M15+푸른솔!N15+의과대학!M15+중앙도서관!M15+학생회관!M15+멀티미디어관!M15+제2기숙사!M15+선승관!M15+예술디자인대!M15+공학관!M15 -> 0 | U15: =P15+Q15+R15+S15+T15 -> 8000 | V15: =E15*U15 -> 144000 | W15: =(H15+N15)-U15 -> 26000 | X15: =E15*W15 -> 468000 | Y15: 35000 | Z15: 30000 | AA15: =Z15*E15 -> 540000
B16: 21cm 일자 스트로우 (투명) | C16: 1box=10000ea | D16: ea | E16: 6.9 | F16: 10000 | G16: 69000 | H16: 11000 | N16: =I16+J16+K16+L16+M16 -> 0 | O16: =E16*N16 -> 0 | P16: =캠퍼스타운_외부원두영업!I16+잇다카페_외부원두영업!I16+푸른솔!J16+의과대학!I16+중앙도서관!I16+학생회관!I16+제2기숙사!I16+멀티미디어관!I16+선승관!I16+예술디자인대!I16+공학관!I16 -> 0 | Q16: =캠퍼스타운_외부원두영업!J16+잇다카페_외부원두영업!J16+푸른솔!K16+의과대학!J16+중앙도서관!J16+학생회관!J16+멀티미디어관!J16+제2기숙사!J16+선승관!J16+예술디자인대!J16+공학관!J16 -> 500 | R16: =캠퍼스타운_외부원두영업!K16+잇다카페_외부원두영업!K16+푸른솔!L16+의과대학!K16+중앙도서관!K16+학생회관!K16+제2기숙사!K16+멀티미디어관!K16+선승관!K16+예술디자인대!K16+공학관!K16 -> 0 | S16: =캠퍼스타운_외부원두영업!L16+잇다카페_외부원두영업!L16+푸른솔!M16+의과대학!L16+중앙도서관!L16+학생회관!L16+멀티미디어관!L16+제2기숙사!L16+선승관!L16+예술디자인대!L16+공학관!L16 -> 1000 | T16: =캠퍼스타운_외부원두영업!M16+잇다카페_외부원두영업!M16+푸른솔!N16+의과대학!M16+중앙도서관!M16+학생회관!M16+멀티미디어관!M16+제2기숙사!M16+선승관!M16+예술디자인대!M16+공학관!M16 -> 0 | U16: =P16+Q16+R16+S16+T16 -> 1500 | V16: =E16*U16 -> 10350 | W16: =(H16+N16)-U16 -> 9500 | X16: =E16*W16 -> 65550 | Y16: 14500 | Z16: 0 | AA16: =Z16*E16 -> 0
B17: 21cm 버블티 스트로우 | C17: 1box=3200ea | D17: ea | E17: 22.1875 | F17: 3200 | G17: 71000 | H17: 5000 | N17: =I17+J17+K17+L17+M17 -> 0 | O17: =E17*N17 -> 0 | P17: =캠퍼스타운_외부원두영업!I17+잇다카페_외부원두영업!I17+푸른솔!J17+의과대학!I17+중앙도서관!I17+학생회관!I17+제2기숙사!I17+멀티미디어관!I17+선승관!I17+예술디자인대!I17+공학관!I17 -> 0 | Q17: =캠퍼스타운_외부원두영업!J17+잇다카페_외부원두영업!J17+푸른솔!K17+의과대학!J17+중앙도서관!J17+학생회관!J17+멀티미디어관!J17+제2기숙사!J17+선승관!J17+예술디자인대!J17+공학관!J17 -> 200 | R17: =캠퍼스타운_외부원두영업!K17+잇다카페_외부원두영업!K17+푸른솔!L17+의과대학!K17+중앙도서관!K17+학생회관!K17+제2기숙사!K17+멀티미디어관!K17+선승관!K17+예술디자인대!K17+공학관!K17 -> 0 | S17: =캠퍼스타운_외부원두영업!L17+잇다카페_외부원두영업!L17+푸른솔!M17+의과대학!L17+중앙도서관!L17+학생회관!L17+멀티미디어관!L17+제2기숙사!L17+선승관!L17+예술디자인대!L17+공학관!L17 -> 0 | T17: =캠퍼스타운_외부원두영업!M17+잇다카페_외부원두영업!M17+푸른솔!N17+의과대학!M17+중앙도서관!M17+학생회관!M17+멀티미디어관!M17+제2기숙사!M17+선승관!M17+예술디자인대!M17+공학관!M17 -> 0 | U17: =P17+Q17+R17+S17+T17 -> 200 | V17: =E17*U17 -> 4437.5 | W17: =(H17+N17)-U17 -> 4800 | X17: =E17*W17 -> 106500 | Y17: 1200 | Z17: 0 | AA17: =Z17*E17 -> 0
B18: 25cm 일자 스트로우 (블랙) | C18: 1box=10000ea | D18: ea | E18: 7.2 | F18: 10000 | G18: 72000 | H18: 6000 | K18: 10000 | N18: =I18+J18+K18+L18+M18 -> 10000 | O18: =E18*N18 -> 72000 | P18: =캠퍼스타운_외부원두영업!I18+잇다카페_외부원두영업!I18+푸른솔!J18+의과대학!I18+중앙도서관!I18+학생회관!I18+제2기숙사!I18+멀티미디어관!I18+선승관!I18+예술디자인대!I18+공학관!I18 -> 0 | Q18: =캠퍼스타운_외부원두영업!J18+잇다카페_외부원두영업!J18+푸른솔!K18+의과대학!J18+중앙도서관!J18+학생회관!J18+멀티미디어관!J18+제2기숙사!J18+선승관!J18+예술디자인대!J18+공학관!J18 -> 1000 | R18: =캠퍼스타운_외부원두영업!K18+잇다카페_외부원두영업!K18+푸른솔!L18+의과대학!K18+중앙도서관!K18+학생회관!K18+제2기숙사!K18+멀티미디어관!K18+선승관!K18+예술디자인대!K18+공학관!K18 -> 0 | S18: =캠퍼스타운_외부원두영업!L18+잇다카페_외부원두영업!L18+푸른솔!M18+의과대학!L18+중앙도서관!L18+학생회관!L18+멀티미디어관!L18+제2기숙사!L18+선승관!L18+예술디자인대!L18+공학관!L18 -> 1000 | T18: =캠퍼스타운_외부원두영업!M18+잇다카페_외부원두영업!M18+푸른솔!N18+의과대학!M18+중앙도서관!M18+학생회관!M18+멀티미디어관!M18+제2기숙사!M18+선승관!M18+예술디자인대!M18+공학관!M18 -> 0 | U18: =P18+Q18+R18+S18+T18 -> 2000 | V18: =E18*U18 -> 14400 | W18: =(H18+N18)-U18 -> 14000 | X18: =E18*W18 -> 100800 | Y18: 8000 | Z18: 10000 | AA18: =Z18*E18 -> 72000
B19: 21cm 종이 스트로우 | C19: 1box=5000ea | D19: ea | E19: 18 | F19: 5000 | G19: 90000 | H19: 3500 | N19: =I19+J19+K19+L19+M19 -> 0 | O19: =E19*N19 -> 0 | P19: =캠퍼스타운_외부원두영업!I19+잇다카페_외부원두영업!I19+푸른솔!J19+의과대학!I19+중앙도서관!I19+학생회관!I19+제2기숙사!I19+멀티미디어관!I19+선승관!I19+예술디자인대!I19+공학관!I19 -> 0 | Q19: =캠퍼스타운_외부원두영업!J19+잇다카페_외부원두영업!J19+푸른솔!K19+의과대학!J19+중앙도서관!J19+학생회관!J19+멀티미디어관!J19+제2기숙사!J19+선승관!J19+예술디자인대!J19+공학관!J19 -> 0 | R19: =캠퍼스타운_외부원두영업!K19+잇다카페_외부원두영업!K19+푸른솔!L19+의과대학!K19+중앙도서관!K19+학생회관!K19+제2기숙사!K19+멀티미디어관!K19+선승관!K19+예술디자인대!K19+공학관!K19 -> 0 | S19: =캠퍼스타운_외부원두영업!L19+잇다카페_외부원두영업!L19+푸른솔!M19+의과대학!L19+중앙도서관!L19+학생회관!L19+멀티미디어관!L19+제2기숙사!L19+선승관!L19+예술디자인대!L19+공학관!L19 -> 0 | T19: =캠퍼스타운_외부원두영업!M19+잇다카페_외부원두영업!M19+푸른솔!N19+의과대학!M19+중앙도서관!M19+학생회관!M19+멀티미디어관!M19+제2기숙사!M19+선승관!M19+예술디자인대!M19+공학관!M19 -> 0 | U19: =P19+Q19+R19+S19+T19 -> 0 | V19: =E19*U19 -> 0 | W19: =(H19+N19)-U19 -> 3500 | X19: =E19*W19 -> 63000 | Y19: 750 | Z19: 0 | AA19: =Z19*E19 -> 0
B20: 21cm 종이 버블 스트로우 | C20: 1box=4000ea | D20: ea | E20: 26.7 | F20: 4000 | G20: 106800 | H20: 4600 | N20: =I20+J20+K20+L20+M20 -> 0 | O20: =E20*N20 -> 0 | P20: =캠퍼스타운_외부원두영업!I20+잇다카페_외부원두영업!I20+푸른솔!J20+의과대학!I20+중앙도서관!I20+학생회관!I20+제2기숙사!I20+멀티미디어관!I20+선승관!I20+예술디자인대!I20+공학관!I20 -> 0 | Q20: =캠퍼스타운_외부원두영업!J20+잇다카페_외부원두영업!J20+푸른솔!K20+의과대학!J20+중앙도서관!J20+학생회관!J20+멀티미디어관!J20+제2기숙사!J20+선승관!J20+예술디자인대!J20+공학관!J20 -> 0 | R20: =캠퍼스타운_외부원두영업!K20+잇다카페_외부원두영업!K20+푸른솔!L20+의과대학!K20+중앙도서관!K20+학생회관!K20+제2기숙사!K20+멀티미디어관!K20+선승관!K20+예술디자인대!K20+공학관!K20 -> 0 | S20: =캠퍼스타운_외부원두영업!L20+잇다카페_외부원두영업!L20+푸른솔!M20+의과대학!L20+중앙도서관!L20+학생회관!L20+멀티미디어관!L20+제2기숙사!L20+선승관!L20+예술디자인대!L20+공학관!L20 -> 0 | T20: =캠퍼스타운_외부원두영업!M20+잇다카페_외부원두영업!M20+푸른솔!N20+의과대학!M20+중앙도서관!M20+학생회관!M20+멀티미디어관!M20+제2기숙사!M20+선승관!M20+예술디자인대!M20+공학관!M20 -> 0 | U20: =P20+Q20+R20+S20+T20 -> 0 | V20: =E20*U20 -> 0 | W20: =(H20+N20)-U20 -> 4600 | X20: =E20*W20 -> 122820 | Y20: 400 | Z20: 0 | AA20: =Z20*E20 -> 0
B21: 25cm 버블티 스트로우 | C21: 1box=3200ea | D21: ea | E21: 22.8125 | F21: 3200 | G21: 73000 | H21: 3800 | N21: =I21+J21+K21+L21+M21 -> 0 | O21: =E21*N21 -> 0 | P21: =캠퍼스타운_외부원두영업!I21+잇다카페_외부원두영업!I21+푸른솔!J21+의과대학!I21+중앙도서관!I21+학생회관!I21+제2기숙사!I21+멀티미디어관!I21+선승관!I21+예술디자인대!I21+공학관!I21 -> 0 | Q21: =캠퍼스타운_외부원두영업!J21+잇다카페_외부원두영업!J21+푸른솔!K21+의과대학!J21+중앙도서관!J21+학생회관!J21+멀티미디어관!J21+제2기숙사!J21+선승관!J21+예술디자인대!J21+공학관!J21 -> 0 | R21: =캠퍼스타운_외부원두영업!K21+잇다카페_외부원두영업!K21+푸른솔!L21+의과대학!K21+중앙도서관!K21+학생회관!K21+제2기숙사!K21+멀티미디어관!K21+선승관!K21+예술디자인대!K21+공학관!K21 -> 0 | S21: =캠퍼스타운_외부원두영업!L21+잇다카페_외부원두영업!L21+푸른솔!M21+의과대학!L21+중앙도서관!L21+학생회관!L21+멀티미디어관!L21+제2기숙사!L21+선승관!L21+예술디자인대!L21+공학관!L21 -> 0 | T21: =캠퍼스타운_외부원두영업!M21+잇다카페_외부원두영업!M21+푸른솔!N21+의과대학!M21+중앙도서관!M21+학생회관!M21+멀티미디어관!M21+제2기숙사!M21+선승관!M21+예술디자인대!M21+공학관!M21 -> 0 | U21: =P21+Q21+R21+S21+T21 -> 0 | V21: =E21*U21 -> 0 | W21: =(H21+N21)-U21 -> 3800 | X21: =E21*W21 -> 86687.5 | Y21: 200 | Z21: 0 | AA21: =Z21*E21 -> 0
B22: 캐리어 무지(크라프트지) | C22: 1box=200ea | D22: ea | E22: 112.5 | F22: 200 | G22: 22500 | H22: 600 | K22: 2000 | N22: =I22+J22+K22+L22+M22 -> 2000 | O22: =E22*N22 -> 225000 | P22: =캠퍼스타운_외부원두영업!I22+잇다카페_외부원두영업!I22+푸른솔!J22+의과대학!I22+중앙도서관!I22+학생회관!I22+제2기숙사!I22+멀티미디어관!I22+선승관!I22+예술디자인대!I22+공학관!I22 -> 0 | Q22: =캠퍼스타운_외부원두영업!J22+잇다카페_외부원두영업!J22+푸른솔!K22+의과대학!J22+중앙도서관!J22+학생회관!J22+멀티미디어관!J22+제2기숙사!J22+선승관!J22+예술디자인대!J22+공학관!J22 -> 400 | R22: =캠퍼스타운_외부원두영업!K22+잇다카페_외부원두영업!K22+푸른솔!L22+의과대학!K22+중앙도서관!K22+학생회관!K22+제2기숙사!K22+멀티미디어관!K22+선승관!K22+예술디자인대!K22+공학관!K22 -> 0 | S22: =캠퍼스타운_외부원두영업!L22+잇다카페_외부원두영업!L22+푸른솔!M22+의과대학!L22+중앙도서관!L22+학생회관!L22+멀티미디어관!L22+제2기숙사!L22+선승관!L22+예술디자인대!L22+공학관!L22 -> 600 | T22: =캠퍼스타운_외부원두영업!M22+잇다카페_외부원두영업!M22+푸른솔!N22+의과대학!M22+중앙도서관!M22+학생회관!M22+멀티미디어관!M22+제2기숙사!M22+선승관!M22+예술디자인대!M22+공학관!M22 -> 0 | U22: =P22+Q22+R22+S22+T22 -> 1000 | V22: =E22*U22 -> 112500 | W22: =(H22+N22)-U22 -> 1600 | X22: =E22*W22 -> 180000 | Y22: 2200 | Z22: 2000 | AA22: =Z22*E22 -> 225000
B23: 갈색무지냅킨 | C23: 1box=8000ea | D23: ea | E23: 3.625 | F23: 8000 | G23: 29000 | H23: 32000 | N23: =I23+J23+K23+L23+M23 -> 0 | O23: =E23*N23 -> 0 | P23: =캠퍼스타운_외부원두영업!I23+잇다카페_외부원두영업!I23+푸른솔!J23+의과대학!I23+중앙도서관!I23+학생회관!I23+제2기숙사!I23+멀티미디어관!I23+선승관!I23+예술디자인대!I23+공학관!I23 -> 0 | Q23: =캠퍼스타운_외부원두영업!J23+잇다카페_외부원두영업!J23+푸른솔!K23+의과대학!J23+중앙도서관!J23+학생회관!J23+멀티미디어관!J23+제2기숙사!J23+선승관!J23+예술디자인대!J23+공학관!J23 -> 0 | R23: =캠퍼스타운_외부원두영업!K23+잇다카페_외부원두영업!K23+푸른솔!L23+의과대학!K23+중앙도서관!K23+학생회관!K23+제2기숙사!K23+멀티미디어관!K23+선승관!K23+예술디자인대!K23+공학관!K23 -> 0 | S23: =캠퍼스타운_외부원두영업!L23+잇다카페_외부원두영업!L23+푸른솔!M23+의과대학!L23+중앙도서관!L23+학생회관!L23+멀티미디어관!L23+제2기숙사!L23+선승관!L23+예술디자인대!L23+공학관!L23 -> 8000 | T23: =캠퍼스타운_외부원두영업!M23+잇다카페_외부원두영업!M23+푸른솔!N23+의과대학!M23+중앙도서관!M23+학생회관!M23+멀티미디어관!M23+제2기숙사!M23+선승관!M23+예술디자인대!M23+공학관!M23 -> 0 | U23: =P23+Q23+R23+S23+T23 -> 8000 | V23: =E23*U23 -> 29000 | W23: =(H23+N23)-U23 -> 24000 | X23: =E23*W23 -> 87000 | Y23: 24000 | Z23: 0 | AA23: =Z23*E23 -> 0
B24: 커피머신세정제 | C24: 1ea | D24: kg | E24: 12000 | F24: 1 | G24: 12000 | H24: 3 | N24: =I24+J24+K24+L24+M24 -> 0 | O24: =E24*N24 -> 0 | P24: =캠퍼스타운_외부원두영업!I24+잇다카페_외부원두영업!I24+푸른솔!J24+의과대학!I24+중앙도서관!I24+학생회관!I24+제2기숙사!I24+멀티미디어관!I24+선승관!I24+예술디자인대!I24+공학관!I24 -> 0 | Q24: =캠퍼스타운_외부원두영업!J24+잇다카페_외부원두영업!J24+푸른솔!K24+의과대학!J24+중앙도서관!J24+학생회관!J24+멀티미디어관!J24+제2기숙사!J24+선승관!J24+예술디자인대!J24+공학관!J24 -> 0 | R24: =캠퍼스타운_외부원두영업!K24+잇다카페_외부원두영업!K24+푸른솔!L24+의과대학!K24+중앙도서관!K24+학생회관!K24+제2기숙사!K24+멀티미디어관!K24+선승관!K24+예술디자인대!K24+공학관!K24 -> 0 | S24: =캠퍼스타운_외부원두영업!L24+잇다카페_외부원두영업!L24+푸른솔!M24+의과대학!L24+중앙도서관!L24+학생회관!L24+멀티미디어관!L24+제2기숙사!L24+선승관!L24+예술디자인대!L24+공학관!L24 -> 1 | T24: =캠퍼스타운_외부원두영업!M24+잇다카페_외부원두영업!M24+푸른솔!N24+의과대학!M24+중앙도서관!M24+학생회관!M24+멀티미디어관!M24+제2기숙사!M24+선승관!M24+예술디자인대!M24+공학관!M24 -> 0 | U24: =P24+Q24+R24+S24+T24 -> 1 | V24: =E24*U24 -> 12000 | W24: =(H24+N24)-U24 -> 2 | X24: =E24*W24 -> 24000 | Y24: 0 | Z24: 0 | AA24: =Z24*E24 -> 0
B25: 15cm 개별포장커피스틱 | C25: 1box=10000ea | D25: ea | E25: 6.4 | F25: 10000 | G25: 64000 | H25: 13000 | N25: =I25+J25+K25+L25+M25 -> 0 | O25: =E25*N25 -> 0 | P25: =캠퍼스타운_외부원두영업!I25+잇다카페_외부원두영업!I25+푸른솔!J25+의과대학!I25+중앙도서관!I25+학생회관!I25+제2기숙사!I25+멀티미디어관!I25+선승관!I25+예술디자인대!I25+공학관!I25 -> 0 | Q25: =캠퍼스타운_외부원두영업!J25+잇다카페_외부원두영업!J25+푸른솔!K25+의과대학!J25+중앙도서관!J25+학생회관!J25+멀티미디어관!J25+제2기숙사!J25+선승관!J25+예술디자인대!J25+공학관!J25 -> 0 | R25: =캠퍼스타운_외부원두영업!K25+잇다카페_외부원두영업!K25+푸른솔!L25+의과대학!K25+중앙도서관!K25+학생회관!K25+제2기숙사!K25+멀티미디어관!K25+선승관!K25+예술디자인대!K25+공학관!K25 -> 0 | S25: =캠퍼스타운_외부원두영업!L25+잇다카페_외부원두영업!L25+푸른솔!M25+의과대학!L25+중앙도서관!L25+학생회관!L25+멀티미디어관!L25+제2기숙사!L25+선승관!L25+예술디자인대!L25+공학관!L25 -> 0 | T25: =캠퍼스타운_외부원두영업!M25+잇다카페_외부원두영업!M25+푸른솔!N25+의과대학!M25+중앙도서관!M25+학생회관!M25+멀티미디어관!M25+제2기숙사!M25+선승관!M25+예술디자인대!M25+공학관!M25 -> 0 | U25: =P25+Q25+R25+S25+T25 -> 0 | V25: =E25*U25 -> 0 | W25: =(H25+N25)-U25 -> 13000 | X25: =E25*W25 -> 83200 | Y25: 0 | Z25: 0 | AA25: =Z25*E25 -> 0
B26: 18cm 개별포장커피스틱 | C26: 1box=10000ea | D26: ea | E26: 6.8 | F26: 10000 | G26: 68000 | H26: 11000 | N26: =I26+J26+K26+L26+M26 -> 0 | O26: =E26*N26 -> 0 | P26: =캠퍼스타운_외부원두영업!I26+잇다카페_외부원두영업!I26+푸른솔!J26+의과대학!I26+중앙도서관!I26+학생회관!I26+제2기숙사!I26+멀티미디어관!I26+선승관!I26+예술디자인대!I26+공학관!I26 -> 0 | Q26: =캠퍼스타운_외부원두영업!J26+잇다카페_외부원두영업!J26+푸른솔!K26+의과대학!J26+중앙도서관!J26+학생회관!J26+멀티미디어관!J26+제2기숙사!J26+선승관!J26+예술디자인대!J26+공학관!J26 -> 0 | R26: =캠퍼스타운_외부원두영업!K26+잇다카페_외부원두영업!K26+푸른솔!L26+의과대학!K26+중앙도서관!K26+학생회관!K26+제2기숙사!K26+멀티미디어관!K26+선승관!K26+예술디자인대!K26+공학관!K26 -> 0 | S26: =캠퍼스타운_외부원두영업!L26+잇다카페_외부원두영업!L26+푸른솔!M26+의과대학!L26+중앙도서관!L26+학생회관!L26+멀티미디어관!L26+제2기숙사!L26+선승관!L26+예술디자인대!L26+공학관!L26 -> 0 | T26: =캠퍼스타운_외부원두영업!M26+잇다카페_외부원두영업!M26+푸른솔!N26+의과대학!M26+중앙도서관!M26+학생회관!M26+멀티미디어관!M26+제2기숙사!M26+선승관!M26+예술디자인대!M26+공학관!M26 -> 0 | U26: =P26+Q26+R26+S26+T26 -> 0 | V26: =E26*U26 -> 0 | W26: =(H26+N26)-U26 -> 11000 | X26: =E26*W26 -> 74800 | Y26: 1000 | Z26: 0 | AA26: =Z26*E26 -> 0
B27: opp 비닐봉투 18*25 | C27: 1pack=200ea | D27: ea | E27: 25 | F27: 200 | G27: 5000 | H27: 600 | N27: =I27+J27+K27+L27+M27 -> 0 | O27: =E27*N27 -> 0 | P27: =캠퍼스타운_외부원두영업!I27+잇다카페_외부원두영업!I27+푸른솔!J27+의과대학!I27+중앙도서관!I27+학생회관!I27+제2기숙사!I27+멀티미디어관!I27+선승관!I27+예술디자인대!I27+공학관!I27 -> 0 | Q27: =캠퍼스타운_외부원두영업!J27+잇다카페_외부원두영업!J27+푸른솔!K27+의과대학!J27+중앙도서관!J27+학생회관!J27+멀티미디어관!J27+제2기숙사!J27+선승관!J27+예술디자인대!J27+공학관!J27 -> 0 | R27: =캠퍼스타운_외부원두영업!K27+잇다카페_외부원두영업!K27+푸른솔!L27+의과대학!K27+중앙도서관!K27+학생회관!K27+제2기숙사!K27+멀티미디어관!K27+선승관!K27+예술디자인대!K27+공학관!K27 -> 0 | S27: =캠퍼스타운_외부원두영업!L27+잇다카페_외부원두영업!L27+푸른솔!M27+의과대학!L27+중앙도서관!L27+학생회관!L27+멀티미디어관!L27+제2기숙사!L27+선승관!L27+예술디자인대!L27+공학관!L27 -> 0 | T27: =캠퍼스타운_외부원두영업!M27+잇다카페_외부원두영업!M27+푸른솔!N27+의과대학!M27+중앙도서관!M27+학생회관!M27+멀티미디어관!M27+제2기숙사!M27+선승관!M27+예술디자인대!M27+공학관!M27 -> 0 | U27: =P27+Q27+R27+S27+T27 -> 0 | V27: =E27*U27 -> 0 | W27: =(H27+N27)-U27 -> 600 | X27: =E27*W27 -> 15000 | Y27: 0 | Z27: 0 | AA27: =Z27*E27 -> 0
B28: 콤부차오리지날 | C28: 1box=12ea | D28: ea | E28: 2100 | F28: 12 | G28: 25200 | H28: 20 | K28: 12 | N28: =I28+J28+K28+L28+M28 -> 12 | O28: =E28*N28 -> 25200 | P28: =캠퍼스타운_외부원두영업!I28+잇다카페_외부원두영업!I28+푸른솔!J28+의과대학!I28+중앙도서관!I28+학생회관!I28+제2기숙사!I28+멀티미디어관!I28+선승관!I28+예술디자인대!I28+공학관!I28 -> 0 | Q28: =캠퍼스타운_외부원두영업!J28+잇다카페_외부원두영업!J28+푸른솔!K28+의과대학!J28+중앙도서관!J28+학생회관!J28+멀티미디어관!J28+제2기숙사!J28+선승관!J28+예술디자인대!J28+공학관!J28 -> 0 | R28: =캠퍼스타운_외부원두영업!K28+잇다카페_외부원두영업!K28+푸른솔!L28+의과대학!K28+중앙도서관!K28+학생회관!K28+제2기숙사!K28+멀티미디어관!K28+선승관!K28+예술디자인대!K28+공학관!K28 -> 0 | S28: =캠퍼스타운_외부원두영업!L28+잇다카페_외부원두영업!L28+푸른솔!M28+의과대학!L28+중앙도서관!L28+학생회관!L28+멀티미디어관!L28+제2기숙사!L28+선승관!L28+예술디자인대!L28+공학관!L28 -> 0 | T28: =캠퍼스타운_외부원두영업!M28+잇다카페_외부원두영업!M28+푸른솔!N28+의과대학!M28+중앙도서관!M28+학생회관!M28+멀티미디어관!M28+제2기숙사!M28+선승관!M28+예술디자인대!M28+공학관!M28 -> 0 | U28: =P28+Q28+R28+S28+T28 -> 0 | V28: =E28*U28 -> 0 | W28: =(H28+N28)-U28 -> 32 | X28: =E28*W28 -> 67200 | Y28: 24 | Z28: 12 | AA28: =Z28*E28 -> 25200
B29: 콤부차진저레몬 | C29: 1box=12ea | D29: ea | E29: 2100 | F29: 12 | G29: 25200 | H29: 22 | K29: 36 | N29: =I29+J29+K29+L29+M29 -> 36 | O29: =E29*N29 -> 75600 | P29: =캠퍼스타운_외부원두영업!I29+잇다카페_외부원두영업!I29+푸른솔!J29+의과대학!I29+중앙도서관!I29+학생회관!I29+제2기숙사!I29+멀티미디어관!I29+선승관!I29+예술디자인대!I29+공학관!I29 -> 0 | Q29: =캠퍼스타운_외부원두영업!J29+잇다카페_외부원두영업!J29+푸른솔!K29+의과대학!J29+중앙도서관!J29+학생회관!J29+멀티미디어관!J29+제2기숙사!J29+선승관!J29+예술디자인대!J29+공학관!J29 -> 0 | R29: =캠퍼스타운_외부원두영업!K29+잇다카페_외부원두영업!K29+푸른솔!L29+의과대학!K29+중앙도서관!K29+학생회관!K29+제2기숙사!K29+멀티미디어관!K29+선승관!K29+예술디자인대!K29+공학관!K29 -> 0 | S29: =캠퍼스타운_외부원두영업!L29+잇다카페_외부원두영업!L29+푸른솔!M29+의과대학!L29+중앙도서관!L29+학생회관!L29+멀티미디어관!L29+제2기숙사!L29+선승관!L29+예술디자인대!L29+공학관!L29 -> 0 | T29: =캠퍼스타운_외부원두영업!M29+잇다카페_외부원두영업!M29+푸른솔!N29+의과대학!M29+중앙도서관!M29+학생회관!M29+멀티미디어관!M29+제2기숙사!M29+선승관!M29+예술디자인대!M29+공학관!M29 -> 0 | U29: =P29+Q29+R29+S29+T29 -> 0 | V29: =E29*U29 -> 0 | W29: =(H29+N29)-U29 -> 58 | X29: =E29*W29 -> 121800 | Y29: 44 | Z29: 36 | AA29: =Z29*E29 -> 75600
B30: 콤부차석류 | C30: 1box=12ea | D30: ea | E30: 2100 | F30: 12 | G30: 25200 | H30: 30 | K30: 24 | N30: =I30+J30+K30+L30+M30 -> 24 | O30: =E30*N30 -> 50400 | P30: =캠퍼스타운_외부원두영업!I30+잇다카페_외부원두영업!I30+푸른솔!J30+의과대학!I30+중앙도서관!I30+학생회관!I30+제2기숙사!I30+멀티미디어관!I30+선승관!I30+예술디자인대!I30+공학관!I30 -> 0 | Q30: =캠퍼스타운_외부원두영업!J30+잇다카페_외부원두영업!J30+푸른솔!K30+의과대학!J30+중앙도서관!J30+학생회관!J30+멀티미디어관!J30+제2기숙사!J30+선승관!J30+예술디자인대!J30+공학관!J30 -> 0 | R30: =캠퍼스타운_외부원두영업!K30+잇다카페_외부원두영업!K30+푸른솔!L30+의과대학!K30+중앙도서관!K30+학생회관!K30+제2기숙사!K30+멀티미디어관!K30+선승관!K30+예술디자인대!K30+공학관!K30 -> 0 | S30: =캠퍼스타운_외부원두영업!L30+잇다카페_외부원두영업!L30+푸른솔!M30+의과대학!L30+중앙도서관!L30+학생회관!L30+멀티미디어관!L30+제2기숙사!L30+선승관!L30+예술디자인대!L30+공학관!L30 -> 6 | T30: =캠퍼스타운_외부원두영업!M30+잇다카페_외부원두영업!M30+푸른솔!N30+의과대학!M30+중앙도서관!M30+학생회관!M30+멀티미디어관!M30+제2기숙사!M30+선승관!M30+예술디자인대!M30+공학관!M30 -> 0 | U30: =P30+Q30+R30+S30+T30 -> 6 | V30: =E30*U30 -> 12600 | W30: =(H30+N30)-U30 -> 48 | X30: =E30*W30 -> 100800 | Y30: 39 | Z30: 24 | AA30: =Z30*E30 -> 50400
B31: 슈가시럽 | C31: 1box=6ea | D31: ea | E31: 2800 | F31: 6 | G31: 16800 | H31: 0 | N31: =I31+J31+K31+L31+M31 -> 0 | O31: =E31*N31 -> 0 | P31: =캠퍼스타운_외부원두영업!I31+잇다카페_외부원두영업!I31+푸른솔!J31+의과대학!I31+중앙도서관!I31+학생회관!I31+제2기숙사!I31+멀티미디어관!I31+선승관!I31+예술디자인대!I31+공학관!I31 -> 0 | Q31: =캠퍼스타운_외부원두영업!J31+잇다카페_외부원두영업!J31+푸른솔!K31+의과대학!J31+중앙도서관!J31+학생회관!J31+멀티미디어관!J31+제2기숙사!J31+선승관!J31+예술디자인대!J31+공학관!J31 -> 0 | R31: =캠퍼스타운_외부원두영업!K31+잇다카페_외부원두영업!K31+푸른솔!L31+의과대학!K31+중앙도서관!K31+학생회관!K31+제2기숙사!K31+멀티미디어관!K31+선승관!K31+예술디자인대!K31+공학관!K31 -> 0 | S31: =캠퍼스타운_외부원두영업!L31+잇다카페_외부원두영업!L31+푸른솔!M31+의과대학!L31+중앙도서관!L31+학생회관!L31+멀티미디어관!L31+제2기숙사!L31+선승관!L31+예술디자인대!L31+공학관!L31 -> 0 | T31: =캠퍼스타운_외부원두영업!M31+잇다카페_외부원두영업!M31+푸른솔!N31+의과대학!M31+중앙도서관!M31+학생회관!M31+멀티미디어관!M31+제2기숙사!M31+선승관!M31+예술디자인대!M31+공학관!M31 -> 0 | U31: =P31+Q31+R31+S31+T31 -> 0 | V31: =E31*U31 -> 0 | W31: =(H31+N31)-U31 -> 0 | X31: =E31*W31 -> 0 | AA31: =Z31*E31 -> 0
B32: 슈가시럽(24년인상) | C32: 1box=6ea | D32: ea | E32: 3200 | F32: 6 | G32: 19200 | H32: 23 | K32: 18 | N32: =I32+J32+K32+L32+M32 -> 18 | O32: =E32*N32 -> 57600 | P32: =캠퍼스타운_외부원두영업!I32+잇다카페_외부원두영업!I32+푸른솔!J32+의과대학!I32+중앙도서관!I32+학생회관!I32+제2기숙사!I32+멀티미디어관!I32+선승관!I32+예술디자인대!I32+공학관!I32 -> 0 | Q32: =캠퍼스타운_외부원두영업!J32+잇다카페_외부원두영업!J32+푸른솔!K32+의과대학!J32+중앙도서관!J32+학생회관!J32+멀티미디어관!J32+제2기숙사!J32+선승관!J32+예술디자인대!J32+공학관!J32 -> 3 | R32: =캠퍼스타운_외부원두영업!K32+잇다카페_외부원두영업!K32+푸른솔!L32+의과대학!K32+중앙도서관!K32+학생회관!K32+제2기숙사!K32+멀티미디어관!K32+선승관!K32+예술디자인대!K32+공학관!K32 -> 0 | S32: =캠퍼스타운_외부원두영업!L32+잇다카페_외부원두영업!L32+푸른솔!M32+의과대학!L32+중앙도서관!L32+학생회관!L32+멀티미디어관!L32+제2기숙사!L32+선승관!L32+예술디자인대!L32+공학관!L32 -> 2 | T32: =캠퍼스타운_외부원두영업!M32+잇다카페_외부원두영업!M32+푸른솔!N32+의과대학!M32+중앙도서관!M32+학생회관!M32+멀티미디어관!M32+제2기숙사!M32+선승관!M32+예술디자인대!M32+공학관!M32 -> 0 | U32: =P32+Q32+R32+S32+T32 -> 5 | V32: =E32*U32 -> 16000 | W32: =(H32+N32)-U32 -> 36 | X32: =E32*W32 -> 115200 | Y32: 38 | Z32: 18 | AA32: =Z32*E32 -> 57600
B33: 삼다수 | C33: 1box=20ea | D33: ea | E33: 410 | F33: 20 | G33: 8200 | H33: 40 | N33: =I33+J33+K33+L33+M33 -> 0 | O33: =E33*N33 -> 0 | P33: =캠퍼스타운_외부원두영업!I33+잇다카페_외부원두영업!I33+푸른솔!J33+의과대학!I33+중앙도서관!I33+학생회관!I33+제2기숙사!I33+멀티미디어관!I33+선승관!I33+예술디자인대!I33+공학관!I33 -> 0 | Q33: =캠퍼스타운_외부원두영업!J33+잇다카페_외부원두영업!J33+푸른솔!K33+의과대학!J33+중앙도서관!J33+학생회관!J33+멀티미디어관!J33+제2기숙사!J33+선승관!J33+예술디자인대!J33+공학관!J33 -> 0 | R33: =캠퍼스타운_외부원두영업!K33+잇다카페_외부원두영업!K33+푸른솔!L33+의과대학!K33+중앙도서관!K33+학생회관!K33+제2기숙사!K33+멀티미디어관!K33+선승관!K33+예술디자인대!K33+공학관!K33 -> 0 | S33: =캠퍼스타운_외부원두영업!L33+잇다카페_외부원두영업!L33+푸른솔!M33+의과대학!L33+중앙도서관!L33+학생회관!L33+멀티미디어관!L33+제2기숙사!L33+선승관!L33+예술디자인대!L33+공학관!L33 -> 0 | T33: =캠퍼스타운_외부원두영업!M33+잇다카페_외부원두영업!M33+푸른솔!N33+의과대학!M33+중앙도서관!M33+학생회관!M33+멀티미디어관!M33+제2기숙사!M33+선승관!M33+예술디자인대!M33+공학관!M33 -> 0 | U33: =P33+Q33+R33+S33+T33 -> 0 | V33: =E33*U33 -> 0 | W33: =(H33+N33)-U33 -> 40 | X33: =E33*W33 -> 16400 | Y33: 180 | Z33: 0 | AA33: =Z33*E33 -> 0
B34: 립톤 복숭아파우더(907g) | C34: 1box=12ea | D34: ea | E34: 7200 | F34: 12 | G34: 86400 | H34: 0 | N34: =I34+J34+K34+L34+M34 -> 0 | O34: =E34*N34 -> 0 | P34: =캠퍼스타운_외부원두영업!I34+잇다카페_외부원두영업!I34+푸른솔!J34+의과대학!I34+중앙도서관!I34+학생회관!I34+제2기숙사!I34+멀티미디어관!I34+선승관!I34+예술디자인대!I34+공학관!I34 -> 0 | Q34: =캠퍼스타운_외부원두영업!J34+잇다카페_외부원두영업!J34+푸른솔!K34+의과대학!J34+중앙도서관!J34+학생회관!J34+멀티미디어관!J34+제2기숙사!J34+선승관!J34+예술디자인대!J34+공학관!J34 -> 0 | R34: =캠퍼스타운_외부원두영업!K34+잇다카페_외부원두영업!K34+푸른솔!L34+의과대학!K34+중앙도서관!K34+학생회관!K34+제2기숙사!K34+멀티미디어관!K34+선승관!K34+예술디자인대!K34+공학관!K34 -> 0 | S34: =캠퍼스타운_외부원두영업!L34+잇다카페_외부원두영업!L34+푸른솔!M34+의과대학!L34+중앙도서관!L34+학생회관!L34+멀티미디어관!L34+제2기숙사!L34+선승관!L34+예술디자인대!L34+공학관!L34 -> 0 | T34: =캠퍼스타운_외부원두영업!M34+잇다카페_외부원두영업!M34+푸른솔!N34+의과대학!M34+중앙도서관!M34+학생회관!M34+멀티미디어관!M34+제2기숙사!M34+선승관!M34+예술디자인대!M34+공학관!M34 -> 0 | U34: =P34+Q34+R34+S34+T34 -> 0 | V34: =E34*U34 -> 0 | W34: =(H34+N34)-U34 -> 0 | X34: =E34*W34 -> 0 | AA34: =Z34*E34 -> 0
B35: 립톤 복숭아파우더(907g) 가격인상 | C35: 1box=12ea | D35: ea | E35: 7700 | F35: 12 | G35: =E35*F35 -> 92400 | H35: 108 | K35: 120 | N35: =I35+J35+K35+L35+M35 -> 120 | O35: =E35*N35 -> 924000 | P35: =캠퍼스타운_외부원두영업!I35+잇다카페_외부원두영업!I35+푸른솔!J35+의과대학!I35+중앙도서관!I35+학생회관!I35+제2기숙사!I35+멀티미디어관!I35+선승관!I35+예술디자인대!I35+공학관!I35 -> 0 | Q35: =캠퍼스타운_외부원두영업!J35+잇다카페_외부원두영업!J35+푸른솔!K35+의과대학!J35+중앙도서관!J35+학생회관!J35+멀티미디어관!J35+제2기숙사!J35+선승관!J35+예술디자인대!J35+공학관!J35 -> 14 | R35: =캠퍼스타운_외부원두영업!K35+잇다카페_외부원두영업!K35+푸른솔!L35+의과대학!K35+중앙도서관!K35+학생회관!K35+제2기숙사!K35+멀티미디어관!K35+선승관!K35+예술디자인대!K35+공학관!K35 -> 0 | S35: =캠퍼스타운_외부원두영업!L35+잇다카페_외부원두영업!L35+푸른솔!M35+의과대학!L35+중앙도서관!L35+학생회관!L35+멀티미디어관!L35+제2기숙사!L35+선승관!L35+예술디자인대!L35+공학관!L35 -> 23 | T35: =캠퍼스타운_외부원두영업!M35+잇다카페_외부원두영업!M35+푸른솔!N35+의과대학!M35+중앙도서관!M35+학생회관!M35+멀티미디어관!M35+제2기숙사!M35+선승관!M35+예술디자인대!M35+공학관!M35 -> 0 | U35: =P35+Q35+R35+S35+T35 -> 37 | V35: =E35*U35 -> 284900 | W35: =(H35+N35)-U35 -> 191 | X35: =E35*W35 -> 1470700 | Y35: 277 | Z35: 120 | AA35: =Z35*E35 -> 924000
B36: 초정탄산수(1.5L) | C36: 1box=12ea | D36: ea | E36: 1350 | F36: 12 | G36: 16200 | H36: 88 | N36: =I36+J36+K36+L36+M36 -> 0 | O36: =E36*N36 -> 0 | P36: =캠퍼스타운_외부원두영업!I36+잇다카페_외부원두영업!I36+푸른솔!J36+의과대학!I36+중앙도서관!I36+학생회관!I36+제2기숙사!I36+멀티미디어관!I36+선승관!I36+예술디자인대!I36+공학관!I36 -> 0 | Q36: =캠퍼스타운_외부원두영업!J36+잇다카페_외부원두영업!J36+푸른솔!K36+의과대학!J36+중앙도서관!J36+학생회관!J36+멀티미디어관!J36+제2기숙사!J36+선승관!J36+예술디자인대!J36+공학관!J36 -> 11 | R36: =캠퍼스타운_외부원두영업!K36+잇다카페_외부원두영업!K36+푸른솔!L36+의과대학!K36+중앙도서관!K36+학생회관!K36+제2기숙사!K36+멀티미디어관!K36+선승관!K36+예술디자인대!K36+공학관!K36 -> 0 | S36: =캠퍼스타운_외부원두영업!L36+잇다카페_외부원두영업!L36+푸른솔!M36+의과대학!L36+중앙도서관!L36+학생회관!L36+멀티미디어관!L36+제2기숙사!L36+선승관!L36+예술디자인대!L36+공학관!L36 -> 8 | T36: =캠퍼스타운_외부원두영업!M36+잇다카페_외부원두영업!M36+푸른솔!N36+의과대학!M36+중앙도서관!M36+학생회관!M36+멀티미디어관!M36+제2기숙사!M36+선승관!M36+예술디자인대!M36+공학관!M36 -> 0 | U36: =P36+Q36+R36+S36+T36 -> 19 | V36: =E36*U36 -> 25650 | W36: =(H36+N36)-U36 -> 69 | X36: =E36*W36 -> 93150 | Y36: 114 | Z36: 0 | AA36: =Z36*E36 -> 0
B37: 메티에 바닐라시럽(700ml) | C37: 1box=8ea | D37: ea | E37: 6870 | F37: 8 | G37: 54960 | H37: 0 | N37: =I37+J37+K37+L37+M37 -> 0 | O37: =E37*N37 -> 0 | P37: =캠퍼스타운_외부원두영업!I37+잇다카페_외부원두영업!I37+푸른솔!J37+의과대학!I37+중앙도서관!I37+학생회관!I37+제2기숙사!I37+멀티미디어관!I37+선승관!I37+예술디자인대!I37+공학관!I37 -> 0 | Q37: =캠퍼스타운_외부원두영업!J37+잇다카페_외부원두영업!J37+푸른솔!K37+의과대학!J37+중앙도서관!J37+학생회관!J37+멀티미디어관!J37+제2기숙사!J37+선승관!J37+예술디자인대!J37+공학관!J37 -> 0 | R37: =캠퍼스타운_외부원두영업!K37+잇다카페_외부원두영업!K37+푸른솔!L37+의과대학!K37+중앙도서관!K37+학생회관!K37+제2기숙사!K37+멀티미디어관!K37+선승관!K37+예술디자인대!K37+공학관!K37 -> 0 | S37: =캠퍼스타운_외부원두영업!L37+잇다카페_외부원두영업!L37+푸른솔!M37+의과대학!L37+중앙도서관!L37+학생회관!L37+멀티미디어관!L37+제2기숙사!L37+선승관!L37+예술디자인대!L37+공학관!L37 -> 0 | T37: =캠퍼스타운_외부원두영업!M37+잇다카페_외부원두영업!M37+푸른솔!N37+의과대학!M37+중앙도서관!M37+학생회관!M37+멀티미디어관!M37+제2기숙사!M37+선승관!M37+예술디자인대!M37+공학관!M37 -> 0 | U37: =P37+Q37+R37+S37+T37 -> 0 | V37: =E37*U37 -> 0 | W37: =(H37+N37)-U37 -> 0 | X37: =E37*W37 -> 0 | AA37: =Z37*E37 -> 0
B38: 메티에 헤이즐럿시럽(700ml) | C38: 1box=8ea | D38: ea | E38: 6870 | F38: 8 | G38: 54960 | H38: 0 | N38: =I38+J38+K38+L38+M38 -> 0 | O38: =E38*N38 -> 0 | P38: =캠퍼스타운_외부원두영업!I38+잇다카페_외부원두영업!I38+푸른솔!J38+의과대학!I38+중앙도서관!I38+학생회관!I38+제2기숙사!I38+멀티미디어관!I38+선승관!I38+예술디자인대!I38+공학관!I38 -> 0 | Q38: =캠퍼스타운_외부원두영업!J38+잇다카페_외부원두영업!J38+푸른솔!K38+의과대학!J38+중앙도서관!J38+학생회관!J38+멀티미디어관!J38+제2기숙사!J38+선승관!J38+예술디자인대!J38+공학관!J38 -> 0 | R38: =캠퍼스타운_외부원두영업!K38+잇다카페_외부원두영업!K38+푸른솔!L38+의과대학!K38+중앙도서관!K38+학생회관!K38+제2기숙사!K38+멀티미디어관!K38+선승관!K38+예술디자인대!K38+공학관!K38 -> 0 | S38: =캠퍼스타운_외부원두영업!L38+잇다카페_외부원두영업!L38+푸른솔!M38+의과대학!L38+중앙도서관!L38+학생회관!L38+멀티미디어관!L38+제2기숙사!L38+선승관!L38+예술디자인대!L38+공학관!L38 -> 0 | T38: =캠퍼스타운_외부원두영업!M38+잇다카페_외부원두영업!M38+푸른솔!N38+의과대학!M38+중앙도서관!M38+학생회관!M38+멀티미디어관!M38+제2기숙사!M38+선승관!M38+예술디자인대!M38+공학관!M38 -> 0 | U38: =P38+Q38+R38+S38+T38 -> 0 | V38: =E38*U38 -> 0 | W38: =(H38+N38)-U38 -> 0 | X38: =E38*W38 -> 0 | AA38: =Z38*E38 -> 0
B39: 메티에 바닐라시럽(750ml) | C39: 1box=8ea | D39: ea | E39: 7360 | F39: 8 | G39: =E39*F39 -> 58880 | H39: 25 | K39: 80 | N39: =I39+J39+K39+L39+M39 -> 80 | O39: =E39*N39 -> 588800 | P39: =캠퍼스타운_외부원두영업!I39+잇다카페_외부원두영업!I39+푸른솔!J39+의과대학!I39+중앙도서관!I39+학생회관!I39+제2기숙사!I39+멀티미디어관!I39+선승관!I39+예술디자인대!I39+공학관!I39 -> 0 | Q39: =캠퍼스타운_외부원두영업!J39+잇다카페_외부원두영업!J39+푸른솔!K39+의과대학!J39+중앙도서관!J39+학생회관!J39+멀티미디어관!J39+제2기숙사!J39+선승관!J39+예술디자인대!J39+공학관!J39 -> 2 | R39: =캠퍼스타운_외부원두영업!K39+잇다카페_외부원두영업!K39+푸른솔!L39+의과대학!K39+중앙도서관!K39+학생회관!K39+제2기숙사!K39+멀티미디어관!K39+선승관!K39+예술디자인대!K39+공학관!K39 -> 0 | S39: =캠퍼스타운_외부원두영업!L39+잇다카페_외부원두영업!L39+푸른솔!M39+의과대학!L39+중앙도서관!L39+학생회관!L39+멀티미디어관!L39+제2기숙사!L39+선승관!L39+예술디자인대!L39+공학관!L39 -> 11 | T39: =캠퍼스타운_외부원두영업!M39+잇다카페_외부원두영업!M39+푸른솔!N39+의과대학!M39+중앙도서관!M39+학생회관!M39+멀티미디어관!M39+제2기숙사!M39+선승관!M39+예술디자인대!M39+공학관!M39 -> 0 | U39: =P39+Q39+R39+S39+T39 -> 13 | V39: =E39*U39 -> 95680 | W39: =(H39+N39)-U39 -> 92 | X39: =E39*W39 -> 677120 | Y39: 146 | Z39: 80 | AA39: =Z39*E39 -> 588800
B40: 메티에 헤이즐럿시럽(750ml) | C40: 1box=8ea | D40: ea | E40: 7360 | F40: 8 | G40: =E40*F40 -> 58880 | H40: 8 | K40: 40 | N40: =I40+J40+K40+L40+M40 -> 40 | O40: =E40*N40 -> 294400 | P40: =캠퍼스타운_외부원두영업!I40+잇다카페_외부원두영업!I40+푸른솔!J40+의과대학!I40+중앙도서관!I40+학생회관!I40+제2기숙사!I40+멀티미디어관!I40+선승관!I40+예술디자인대!I40+공학관!I40 -> 0 | Q40: =캠퍼스타운_외부원두영업!J40+잇다카페_외부원두영업!J40+푸른솔!K40+의과대학!J40+중앙도서관!J40+학생회관!J40+멀티미디어관!J40+제2기숙사!J40+선승관!J40+예술디자인대!J40+공학관!J40 -> 3 | R40: =캠퍼스타운_외부원두영업!K40+잇다카페_외부원두영업!K40+푸른솔!L40+의과대학!K40+중앙도서관!K40+학생회관!K40+제2기숙사!K40+멀티미디어관!K40+선승관!K40+예술디자인대!K40+공학관!K40 -> 0 | S40: =캠퍼스타운_외부원두영업!L40+잇다카페_외부원두영업!L40+푸른솔!M40+의과대학!L40+중앙도서관!L40+학생회관!L40+멀티미디어관!L40+제2기숙사!L40+선승관!L40+예술디자인대!L40+공학관!L40 -> 5 | T40: =캠퍼스타운_외부원두영업!M40+잇다카페_외부원두영업!M40+푸른솔!N40+의과대학!M40+중앙도서관!M40+학생회관!M40+멀티미디어관!M40+제2기숙사!M40+선승관!M40+예술디자인대!M40+공학관!M40 -> 0 | U40: =P40+Q40+R40+S40+T40 -> 8 | V40: =E40*U40 -> 58880 | W40: =(H40+N40)-U40 -> 40 | X40: =E40*W40 -> 294400 | Y40: 37 | Z40: 40 | AA40: =Z40*E40 -> 294400
A41: 성원애드피아 | B41: 적립쿠폰 | C41: 1bundle=500ea | D41: ea | E41: 6.4 | F41: 500 | G41: 3200 | H41: 19000 | N41: =I41+J41+K41+L41+M41 -> 0 | O41: =E41*N41 -> 0 | P41: =캠퍼스타운_외부원두영업!I41+잇다카페_외부원두영업!I41+푸른솔!J41+의과대학!I41+중앙도서관!I41+학생회관!I41+제2기숙사!I41+멀티미디어관!I41+선승관!I41+예술디자인대!I41+공학관!I41 -> 0 | Q41: =캠퍼스타운_외부원두영업!J41+잇다카페_외부원두영업!J41+푸른솔!K41+의과대학!J41+중앙도서관!J41+학생회관!J41+멀티미디어관!J41+제2기숙사!J41+선승관!J41+예술디자인대!J41+공학관!J41 -> 300 | R41: =캠퍼스타운_외부원두영업!K41+잇다카페_외부원두영업!K41+푸른솔!L41+의과대학!K41+중앙도서관!K41+학생회관!K41+제2기숙사!K41+멀티미디어관!K41+선승관!K41+예술디자인대!K41+공학관!K41 -> 0 | S41: =캠퍼스타운_외부원두영업!L41+잇다카페_외부원두영업!L41+푸른솔!M41+의과대학!L41+중앙도서관!L41+학생회관!L41+멀티미디어관!L41+제2기숙사!L41+선승관!L41+예술디자인대!L41+공학관!L41 -> 100 | T41: =캠퍼스타운_외부원두영업!M41+잇다카페_외부원두영업!M41+푸른솔!N41+의과대학!M41+중앙도서관!M41+학생회관!M41+멀티미디어관!M41+제2기숙사!M41+선승관!M41+예술디자인대!M41+공학관!M41 -> 0 | U41: =P41+Q41+R41+S41+T41 -> 400 | V41: =E41*U41 -> 2560 | W41: =(H41+N41)-U41 -> 18600 | X41: =E41*W41 -> 119040 | Y41: 5600 | AA41: =Z41*E41 -> 0 | AB41: =SUM(AA41:AA42) -> 0 | AC41: =AB41*1.1 -> 0
B42: 유통기한 스티커 | C42: 1bundle=1000ea | D42: ea | E42: 4.69 | F42: 1000 | G42: 4690 | H42: 1700 | N42: =I42+J42+K42+L42+M42 -> 0 | O42: =E42*N42 -> 0 | P42: =캠퍼스타운_외부원두영업!I42+잇다카페_외부원두영업!I42+푸른솔!J42+의과대학!I42+중앙도서관!I42+학생회관!I42+제2기숙사!I42+멀티미디어관!I42+선승관!I42+예술디자인대!I42+공학관!I42 -> 0 | Q42: =캠퍼스타운_외부원두영업!J42+잇다카페_외부원두영업!J42+푸른솔!K42+의과대학!J42+중앙도서관!J42+학생회관!J42+멀티미디어관!J42+제2기숙사!J42+선승관!J42+예술디자인대!J42+공학관!J42 -> 0 | R42: =캠퍼스타운_외부원두영업!K42+잇다카페_외부원두영업!K42+푸른솔!L42+의과대학!K42+중앙도서관!K42+학생회관!K42+제2기숙사!K42+멀티미디어관!K42+선승관!K42+예술디자인대!K42+공학관!K42 -> 0 | S42: =캠퍼스타운_외부원두영업!L42+잇다카페_외부원두영업!L42+푸른솔!M42+의과대학!L42+중앙도서관!L42+학생회관!L42+멀티미디어관!L42+제2기숙사!L42+선승관!L42+예술디자인대!L42+공학관!L42 -> 0 | T42: =캠퍼스타운_외부원두영업!M42+잇다카페_외부원두영업!M42+푸른솔!N42+의과대학!M42+중앙도서관!M42+학생회관!M42+멀티미디어관!M42+제2기숙사!M42+선승관!M42+예술디자인대!M42+공학관!M42 -> 0 | U42: =P42+Q42+R42+S42+T42 -> 0 | V42: =E42*U42 -> 0 | W42: =(H42+N42)-U42 -> 1700 | X42: =E42*W42 -> 7973 | Y42: 80 | AA42: =Z42*E42 -> 0
...

Sheet 캠퍼스타운_외부원두영업
A1: 카페 쿠피 1월 발주 관리 대장 (교육용,R&D,삼의원(잇다카페))
A4: 협력사 | B4: 품목명 | C4: 규격 | D4: 단위 | E4: 입고단가 | F4: 입고단위 | G4: 입고단위단가 | H4: 전월 재고 | I4: 1주차 발주 | J4: 2주차 발주 | K4: 3주차 발주 | L4: 4주차 발주 | M4: 5주차 발주 | N4: 월 발주량 | O4: 월 발주 금액
A5: 비스토리코리아 | B5: 종이컵(-12oz) | C5: 1box=1000ea | D5: ea | E5: 37 | F5: 1000 | G5: 37000 | N5: =I5+J5+K5+L5+M5 -> 0 | O5: =E5*N5 -> 0
B6: 종이컵-16oz | C6: 1box=1000ea | D6: ea | E6: 43 | F6: 1000 | G6: 43000 | N6: =I6+J6+K6+L6+M6 -> 0 | O6: =E6*N6 -> 0
B7: 종이컵뚜껑 (12,16oz) | C7: 1box=1000ea | D7: ea | E7: 20 | F7: 1000 | G7: 20000 | N7: =I7+J7+K7+L7+M7 -> 0 | O7: =E7*N7 -> 0
B8: 아이스(페트)컵(14oz) | C8: 1box=1000ea | D8: ea | E8: 42 | F8: 1000 | G8: 42000 | N8: =I8+J8+K8+L8+M8 -> 0 | O8: =E8*N8 -> 0
B9: 아이스컵(16oz) | C9: 1box=1000ea | D9: ea | E9: 53 | F9: 1000 | G9: 53000 | N9: =I9+J9+K9+L9+M9 -> 0 | O9: =E9*N9 -> 0
B10: 아이스컵(24oz) | C10: 1box=1000ea | D10: ea | E10: 65 | F10: 1000 | G10: 65000 | N10: =I10+J10+K10+L10+M10 -> 0 | O10: =E10*N10 -> 0
B11: 아이스컵 돔뚜껑(93Ø) | C11: 1box=1000ea | D11: ea | E11: 18.5 | F11: 1000 | G11: 18500 | N11: =I11+J11+K11+L11+M11 -> 0 | O11: =E11*N11 -> 0
B12: 아이스컵 돔뚜껑(98Ø) | C12: 1box=1000ea | D12: ea | E12: 20 | F12: 1000 | G12: 20000 | N12: =I12+J12+K12+L12+M12 -> 0 | O12: =E12*N12 -> 0
B13: 아이스컵 평뚜껑(98Ø) | C13: 1box=1000ea | D13: ea | E13: 19 | F13: 1000 | G13: 19000 | N13: =I13+J13+K13+L13+M13 -> 0 | O13: =E13*N13 -> 0
B14: 10/13홀더 (1도인쇄) | C14: 1box=1000ea | D14: ea | E14: 17.5 | F14: 1000 | G14: 17500 | N14: =I14+J14+K14+L14+M14 -> 0 | O14: =E14*N14 -> 0
B15: 12/16홀더(1도인쇄) | C15: 1box=1000ea | D15: ea | E15: 18 | F15: 1000 | G15: 18000 | N15: =I15+J15+K15+L15+M15 -> 0 | O15: =E15*N15 -> 0
B16: 21cm 일자 스트로우 (투명) | C16: 1box=10000ea | D16: ea | E16: 6.9 | F16: 10000 | G16: 69000 | N16: =I16+J16+K16+L16+M16 -> 0 | O16: =E16*N16 -> 0
B17: 21cm 버블티 스트로우 | C17: 1box=3200ea | D17: ea | E17: 22.1875 | F17: 3200 | G17: 71000 | N17: =I17+J17+K17+L17+M17 -> 0 | O17: =E17*N17 -> 0
... B34: 립톤 복숭아파우더(907g) | C34: 1box=12ea | D34: ea | E34: 7200 | F34: 12 | G34: 86400 | N34: =I34+J34+K34+L34+M34 -> 0 | O34: =E34*N34 -> 0
B35: 립톤 복숭아파우더(907g)(24년인상) | C35: 1box=12ea | D35: ea | E35: 7700 | F35: 12 | G35: =E35*F35 -> 92400
B36: 초정탄산수(1.5L) | C36: 1box=12ea | D36: ea | E36: 1350 | F36: 12 | G36: 16200 | N36: =I36+J36+K36+L36+M36 -> 0 | O36: =E36*N36 -> 0
B37: 메티에 바닐라시럽(700ml) | C37: 1box=8ea | D37: ea | E37: 6870 | F37: 8 | G37: 54960 | N37: =I37+J37+K37+L37+M37 -> 0 | O37: =E37*N37 -> 0
B38: 메티에 헤이즐럿시럽(700ml) | C38: 1box=8ea | D38: ea | E38: 6870 | F38: 8 | G38: 54960 | N38: =I38+J38+K38+L38+M38 -> 0 | O38: =E38*N38 -> 0
B39: 메티에 바닐라시럽(750ml) | C39: 1box=8ea | D39: ea | E39: 7360 | F39: 8 | G39: =E39*F39 -> 58880 | N39: =I39+J39+K39+L39+M39 -> 0 | O39: =E39*N39 -> 0
B40: 메티에 헤이즐럿시럽(750ml) | C40: 1box=8ea | D40: ea | E40: 7360 | F40: 8 | G40: =E40*F40 -> 58880 | N40: =I40+J40+K40+L40+M40 -> 0 | O40: =E40*N40 -> 0
A41: 성원애드피아 | B41: 적립쿠폰 | C41: 1bundle=500ea | D41: ea | E41: 6.4 | F41: 500 | G41: 3200 | N41: =I41+J41+K41+L41+M41 -> 0 | O41: =E41*N41 -> 0
B42: 유통기한 스티커 | C42: 1bundle=1000ea | D42: ea | E42: 4.69 | F42: 1000 | G42: 4690 | N42: =I42+J42+K42+L42+M42 -> 0 | O42: =E42*N42 -> 0
A43: 휴럼 | B43: 민트초코파우더 | C43: 1box = 12ea | D43: ea | E43: 7700 | F43: 12 | G43: 92400 | N43: =I43+J43+K43+L43+M43 -> 0 | O43: =E43*N43 -> 0
B44: 다크초코파우더 | C44: 1box = 12ea | D44: ea | E44: 6200 | F44: 12 | G44: 74400 | N44: =I44+J44+K44+L44+M44 -> 0 | O44: =E44*N44 -> 0
B45: 청귤베이스 | C45: 1box = 12ea | D45: ea | E45: 6700 | F45: 12 | G45: 80400 | N45: =I45+J45+K45+L45+M45 -> 0 | O45: =E45*N45 -> 0
B46: 요거에스플레인 | C46: 1box=12ea | D46: ea | E46: 7250 | F46: 12 | G46: 87000 | N46: =I46+J46+K46+L46+M46 -> 0 | O46: =E46*N46 -> 0
B47: 흑당베이스 | C47: 1kg x 12ea | D47: ea | E47: 5300 | F47: 12 | G47: 63600 | N47: =I47+J47+K47+L47+M47 -> 0 | O47: =E47*N47 -> 0
B48: 쿠키앤크림 파우더 | C48: 1kg x 12ea | D48: ea | E48: 6600 | F48: 12 | G48: 79200 | N48: =I48+J48+K48+L48+M48 -> 0 | O48: =E48*N48 -> 0
B49: 자몽 베이스 | C49: 1.8kg x 6ea | D49: ea | E49: 14500 | F49: 6 | G49: 87000 | N49: =I49+J49+K49+L49+M49 -> 0 | O49: =E49*N49 -> 0
B50: 수박 베이스 | C50: 1.8kg x 6ea | D50: ea | E50: 11000 | F50: 6 | G50: 66000 | N50: =I50+J50+K50+L50+M50 -> 0 | O50: =E50*N50 -> 0
B51: 자두 스무디 | C51: 1.8kg x 6ea | D51: ea | E51: 7000 | F51: 6 | G51: =E51*F51 -> 42000 | N51: =I51+J51+K51+L51+M51 -> 0 | O51: =E51*N51 -> 0
B52: 크림소다 베이스 | C52: 1.8kg x 6ea | D52: ea | E52: 9000 | F52: 6 | G52: =E52*F52 -> 54000 | N52: =I52+J52+K52+L52+M52 -> 0 | O52: =E52*N52 -> 0
B53: 제주하늘 말차 파우더 (24년 추가) | C53: 500g * 12ea | D53: ea | E53: 5300 | F53: 12 | G53: =F53*E53 -> 63600 | N53: =I53+J53+K53+L53+M53 -> 0 | O53: =E53*N53 -> 0
B54: 공주밤 베이스 파우더 (24년 추가) | C54: 1kg x 12ea | D54: ea | E54: 7900 | F54: 12 | G54: =F54*E54 -> 94800 | N54: =I54+J54+K54+L54+M54 -> 0 | O54: =E54*N54 -> 0
B55: 피스타치오 파우더 (24년 추가) | C55: 1kg x 12ea | D55: ea | E55: 8400 | F55: 12 | G55: =F55*E55 -> 100800 | N55: =I55+J55+K55+L55+M55 -> 0 | O55: =E55*N55 -> 0
B56: 17곡 파우더 | C56: 1kg x 12ea | D56: ea | E56: 4500 | F56: 12 | G56: 54000 | N56: =I56+J56+K56+L56+M56 -> 0 | O56: =E56*N56 -> 0
B57: 토피넛파우더 | C57: 1box=12ea | D57: ea | E57: 6700 | F57: 12 | G57: 80400 | N57: =I57+J57+K57+L57+M57 -> 0 | O57: =E57*N57 -> 0
A58: 세미기업 | B58: 딸기스무디 원액 | C58: 1.8kg x 6ea | D58: ea | E58: 6900 | F58: 6 | G58: 41400 | N58: =I58+J58+K58+L58+M58 -> 0 | O58: =E58*N58 -> 0
...

Sheet 잇다카페_외부원두영업
A1: 카페 쿠피 1월 발주 관리 대장 (교육용,R&D,삼의원(잇다카페))
A4: 협력사 | B4: 품목명 | C4: 규격 | D4: 단위 | E4: 입고단가 | F4: 입고단위 | G4: 입고단위단가 | H4: 전월 재고 | I4: 1주차 발주 | J4: 2주차 발주 | K4: 3주차 발주 | L4: 4주차 발주 | M4: 5주차 발주 | N4: 월 발주량 | O4: 월 발주 금액
A5: 비스토리코리아 | B5: 종이컵(-12oz) | C5: 1box=1000ea | D5: ea | E5: 37 | F5: 1000 | G5: 37000 | N5: =I5+J5+K5+L5+M5 -> 0 | O5: =E5*N5 -> 0
B6: 종이컵-16oz | C6: 1box=1000ea | D6: ea | E6: 43 | F6: 1000 | G6: 43000 | N6: =I6+J6+K6+L6+M6 -> 0 | O6: =E6*N6 -> 0
B7: 종이컵뚜껑 (12,16oz) | C7: 1box=1000ea | D7: ea | E7: 20 | F7: 1000 | G7: 20000 | N7: =I7+J7+K7+L7+M7 -> 0 | O7: =E7*N7 -> 0
B8: 아이스(페트)컵(14oz) | C8: 1box=1000ea | D8: ea | E8: 42 | F8: 1000 | G8: 42000 | N8: =I8+J8+K8+L8+M8 -> 0 | O8: =E8*N8 -> 0
B9: 아이스컵(16oz) | C9: 1box=1000ea | D9: ea | E9: 53 | F9: 1000 | G9: 53000 | N9: =I9+J9+K9+L9+M9 -> 0 | O9: =E9*N9 -> 0
B10: 아이스컵(24oz) | C10: 1box=1000ea | D10: ea | E10: 65 | F10: 1000 | G10: 65000 | N10: =I10+J10+K10+L10+M10 -> 0 | O10: =E10*N10 -> 0
B11: 아이스컵 돔뚜껑(93Ø) | C11: 1box=1000ea | D11: ea | E11: 18.5 | F11: 1000 | G11: 18500 | N11: =I11+J11+K11+L11+M11 -> 0 | O11: =E11*N11 -> 0
B12: 아이스컵 돔뚜껑(98Ø) | C12: 1box=1000ea | D12: ea | E12: 20 | F12: 1000 | G12: 20000 | N12: =I12+J12+K12+L12+M12 -> 0 | O12: =E12*N12 -> 0
B13: 아이스컵 평뚜껑(98Ø) | C13: 1box=1000ea | D13: ea | E13: 19 | F13: 1000 | G13: 19000 | N13: =I13+J13+K13+L13+M13 -> 0 | O13: =E13*N13 -> 0
B14: 10/13홀더 (1도인쇄) | C14: 1box=1000ea | D14: ea | E14: 17.5 | F14: 1000 | G14: 17500 | N14: =I14+J14+K14+L14+M14 -> 0 | O14: =E14*N14 -> 0
B15: 12/16홀더(1도인쇄) | C15: 1box=1000ea | D15: ea | E15: 18 | F15: 1000 | G15: 18000 | N15: =I15+J15+K15+L15+M15 -> 0 | O15: =E15*N15 -> 0
B16: 21cm 일자 스트로우 (투명) | C16: 1box=10000ea | D16: ea | E16: 6.9 | F16: 10000 | G16: 69000 | N16: =I16+J16+K16+L16+M16 -> 0 | O16: =E16*N16 -> 0
B17: 21cm 버블티 스트로우 | C17: 1box=3200ea | D17: ea | E17: 22.1875 | F17: 3200 | G17: 71000 | N17: =I17+J17+K17+L17+M17 -> 0 | O17: =E17*N17 -> 0
... B34: 립톤 복숭아파우더(907g) | C34: 1box=12ea | D34: ea | E34: 7200 | F34: 12 | G34: 86400 | N34: =I34+J34+K34+L34+M34 -> 0 | O34: =E34*N34 -> 0
B35: 립톤 복숭아파우더(907g)(24년인상) | C35: 1box=12ea | D35: ea | E35: 7700 | F35: 12 | G35: =E35*F35 -> 92400
B36: 초정탄산수(1.5L) | C36: 1box=12ea | D36: ea | E36: 1350 | F36: 12 | G36: 16200 | N36: =I36+J36+K36+L36+M36 -> 0 | O36: =E36*N36 -> 0
B37: 메티에 바닐라시럽(700ml) | C37: 1box=8ea | D37: ea | E37: 6870 | F37: 8 | G37: 54960 | N37: =I37+J37+K37+L37+M37 -> 0 | O37: =E37*N37 -> 0
B38: 메티에 헤이즐럿시럽(700ml) | C38: 1box=8ea | D38: ea | E38: 6870 | F38: 8 | G38: 54960 | N38: =I38+J38+K38+L38+M38 -> 0 | O38: =E38*N38 -> 0
B39: 메티에 바닐라시럽(750ml) | C39: 1box=8ea | D39: ea | E39: 7360 | F39: 8 | G39: =E39*F39 -> 58880 | N39: =I39+J39+K39+L39+M39 -> 0 | O39: =E39*N39 -> 0
B40: 메티에 헤이즐럿시럽(750ml) | C40: 1box=8ea | D40: ea | E40: 7360 | F40: 8 | G40: =E40*F40 -> 58880 | N40: =I40+J40+K40+L40+M40 -> 0 | O40: =E40*N40 -> 0
A41: 성원애드피아 | B41: 적립쿠폰 | C41: 1bundle=500ea | D41: ea | E41: 6.4 | F41: 500 | G41: 3200 | N41: =I41+J41+K41+L41+M41 -> 0 | O41: =E41*N41 -> 0
B42: 유통기한 스티커 | C42: 1bundle=1000ea | D42: ea | E42: 4.69 | F42: 1000 | G42: 4690 | N42: =I42+J42+K42+L42+M42 -> 0 | O42: =E42*N42 -> 0
A43: 휴럼 | B43: 민트초코파우더 | C43: 1box = 12ea | D43: ea | E43: 7700 | F43: 12 | G43: 92400 | N43: =I43+J43+K43+L43+M43 -> 0 | O43: =E43*N43 -> 0
B44: 다크초코파우더 | C44: 1box = 12ea | D44: ea | E44: 6200 | F44: 12 | G44: 74400 | N44: =I44+J44+K44+L44+M44 -> 0 | O44: =E44*N44 -> 0
B45: 청귤베이스 | C45: 1box = 12ea | D45: ea | E45: 6700 | F45: 12 | G45: 80400 | N45: =I45+J45+K45+L45+M45 -> 0 | O45: =E45*N45 -> 0
B46: 요거에스플레인 | C46: 1box=12ea | D46: ea | E46: 7250 | F46: 12 | G46: 87000 | N46: =I46+J46+K46+L46+M46 -> 0 | O46: =E46*N46 -> 0
B47: 흑당베이스 | C47: 1kg x 12ea | D47: ea | E47: 5300 | F47: 12 | G47: 63600 | N47: =I47+J47+K47+L47+M47 -> 0 | O47: =E47*N47 -> 0
B48: 쿠키앤크림 파우더 | C48: 1kg x 12ea | D48: ea | E48: 6600 | F48: 12 | G48: 79200 | N48: =I48+J48+K48+L48+M48 -> 0 | O48: =E48*N48 -> 0
B49: 자몽 베이스 | C49: 1.8kg x 6ea | D49: ea | E49: 14500 | F49: 6 | G49: 87000 | N49: =I49+J49+K49+L49+M49 -> 0 | O49: =E49*N49 -> 0
B50: 수박 베이스 | C50: 1.8kg x 6ea | D50: ea | E50: 11000 | F50: 6 | G50: 66000 | N50: =I50+J50+K50+L50+M50 -> 0 | O50: =E50*N50 -> 0
B51: 자두 스무디 | C51: 1.8kg x 6ea | D51: ea | E51: 7000 | F51: 6 | G51: =E51*F51 -> 42000 | N51: =I51+J51+K51+L51+M51 -> 0 | O51: =E51*N51 -> 0
B52: 크림소다 베이스 | C52: 1.8kg x 6ea | D52: ea | E52: 9000 | F52: 6 | G52: =E52*F52 -> 54000 | N52: =I52+J52+K52+L52+M52 -> 0 | O52: =E52*N52 -> 0
B53: 제주하늘 말차 파우더 (24년 추가) | C53: 500g * 12ea | D53: ea | E53: 5300 | F53: 12 | G53: =F53*E53 -> 63600 | N53: =I53+J53+K53+L53+M53 -> 0 | O53: =E53*N53 -> 0
B54: 공주밤 베이스 파우더 (24년 추가) | C54: 1kg x 12ea | D54: ea | E54: 7900 | F54: 12 | G54: =F54*E54 -> 94800 | N54: =I54+J54+K54+L54+M54 -> 0 | O54: =E54*N54 -> 0
B55: 피스타치오 파우더 (24년 추가) | C55: 1kg x 12ea | D55: ea | E55: 8400 | F55: 12 | G55: =F55*E55 -> 100800 | N55: =I55+J55+K55+L55+M55 -> 0 | O55: =E55*N55 -> 0
B56: 17곡 파우더 | C56: 1kg x 12ea | D56: ea | E56: 4500 | F56: 12 | G56: 54000 | N56: =I56+J56+K56+L56+M56 -> 0 | O56: =E56*N56 -> 0
B57: 토피넛파우더 | C57: 1box=12ea | D57: ea | E57: 6700 | F57: 12 | G57: 80400 | N57: =I57+J57+K57+L57+M57 -> 0 | O57: =E57*N57 -> 0
A58: 세미기업 | B58: 딸기스무디 원액 | C58: 1.8kg x 6ea | D58: ea | E58: 6900 | F58: 6 | G58: 41400 | N58: =I58+J58+K58+L58+M58 -> 0 | O58: =E58*N58 -> 0
...

Sheet 푸른솔
A1: 카페 쿠피 1월 발주 관리 대장 (푸른솔)
A4: 협력사 | B4: 품목명 | C4: 규격 | D4: 단위 | E4: 입고단가 | F4: 입고단위 | G4: 출고단위 | H4: 입고단위단가 | I4: 전월 재고 | J4: 1주차 발주 | K4: 2주차 발주 | L4: 3주차 발주 | M4: 4주차 발주 | N4: 5주차 발주 | O4: 월 발주량 | P4: 월 발주 금액
A5: 비스토리코리아 | B5: 종이컵(-12oz) | C5: 1box=1000ea | D5: ea | E5: 37 | F5: 1000 | G5: 1000 | H5: 37000 | K5: 1000 | O5: =J5+K5+L5+M5+N5 -> 1000 | P5: =E5*O5 -> 37000
B6: 종이컵-16oz | C6: 1box=1000ea | D6: ea | E6: 43 | F6: 1000 | G6: 1000 | H6: 43000 | I6: 1350 | O6: =J6+K6+L6+M6+N6 -> 0 | P6: =E6*O6 -> 0
B7: 종이컵뚜껑 (12,16oz) | C7: 1box=1000ea | D7: ea | E7: 20 | F7: 1000 | G7: 1000 | H7: 20000 | I7: 1400 | O7: =J7+K7+L7+M7+N7 -> 0 | P7: =E7*O7 -> 0
B8: 아이스(페트)컵(14oz) | C8: 1box=1000ea | D8: ea | E8: 42 | F8: 1000 | G8: 1000 | H8: 42000 | O8: =J8+K8+L8+M8+N8 -> 0 | P8: =E8*O8 -> 0
B9: 아이스컵(16oz) | C9: 1box=1000ea | D9: ea | E9: 53 | F9: 1000 | G9: 1000 | H9: 53000 | I9: 950 | O9: =J9+K9+L9+M9+N9 -> 0 | P9: =E9*O9 -> 0
B10: 아이스컵(24oz) | C10: 1box=1000ea | D10: ea | E10: 65 | F10: 1000 | G10: 1000 | H10: 65000 | I10: 900 | O10: =J10+K10+L10+M10+N10 -> 0 | P10: =E10*O10 -> 0
B11: 아이스컵 돔뚜껑(93Ø) | C11: 1box=1000ea | D11: ea | E11: 18.5 | F11: 1000 | G11: 1000 | H11: 18500 | I11: 900 | O11: =J11+K11+L11+M11+N11 -> 0 | P11: =E11*O11 -> 0
B12: 아이스컵 돔뚜껑(98Ø) | C12: 1box=1000ea | D12: ea | E12: 20 | F12: 1000 | G12: 1000 | H12: 20000 | I12: 800 | O12: =J12+K12+L12+M12+N12 -> 0 | P12: =E12*O12 -> 0
B13: 아이스컵 평뚜껑(98Ø) | C13: 1box=1000ea | D13: ea | E13: 19 | F13: 1000 | G13: 1000 | H13: 19000 | O13: =J13+K13+L13+M13+N13 -> 0 | P13: =E13*O13 -> 0
B14: 10/13홀더 (1도인쇄) | C14: 1box=1000ea | D14: ea | E14: 17.5 | F14: 1000 | G14: 1000 | H14: 17500 | O14: =J14+K14+L14+M14+N14 -> 0 | P14: =E14*O14 -> 0
B15: 12/16홀더(1도인쇄) | C15: 1box=1000ea | D15: ea | E15: 18 | F15: 1000 | G15: 1000 | H15: 18000 | K15: 1000 | M15: 1000 | O15: =J15+K15+L15+M15+N15 -> 2000 | P15: =E15*O15 -> 36000
B16: 21cm 일자 스트로우 (투명) | C16: 1box=10000ea | D16: ea | E16: 6.9 | F16: 10000 | G16: 500 | H16: 69000 | K16: 500 | O16: =J16+K16+L16+M16+N16 -> 500 | P16: =E16*O16 -> 3450
B17: 21cm 버블티 스트로우 | C17: 1box=3200ea | D17: ea | E17: 22.1875 | F17: 3200 | G17: 250 | H17: 71000 | I17: 200 | O17: =J17+K17+L17+M17+N17 -> 0 | P17: =E17*O17 -> 0
B18: 25cm 일자 스트로우 (블랙) | C18: 1box=10000ea | D18: ea | E18: 7.2 | F18: 10000 | G18: 500 | H18: 72000 | K18: 500 | O18: =J18+K18+L18+M18+N18 -> 500 | P18: =E18*O18 -> 3600
B19: 21cm 종이 스트로우 | C19: 1box=5000ea | D19: ea | E19: 18 | F19: 5000 | G19: 250 | H19: 90000 | O19: =J19+K19+L19+M19+N19 -> 0 | P19: =E19*O19 -> 0
B20: 21cm 종이 버블 스트로우 | C20: 1box=4000ea | D20: ea | E20: 26.7 | F20: 4000 | G20: 250 | H20: 106800 | O20: =J20+K20+L20+M20+N20 -> 0 | P20: =E20*O20 -> 0
B21: 25cm 버블티 스트로우 | C21: 1box=3200ea | D21: ea | E21: 22.8125 | F21: 3200 | G21: 250 | H21: 73000 | I21: 200 | O21: =J21+K21+L21+M21+N21 -> 0 | P21: =E21*O21 -> 0
B22: 캐리어 무지(크라프트지) | C22: 1box=200ea | D22: ea | E22: 112.5 | F22: 200 | G22: 200 | H22: 22500 | I22: 75 | O22: =J22+K22+L22+M22+N22 -> 0 | P22: =E22*O22 -> 0
B23: 갈색무지냅킨 | C23: 1box=8000ea | D23: ea | E23: 3.625 | F23: 8000 | G23: 8000 | H23: 29000 | I23: 6000 | O23: =J23+K23+L23+M23+N23 -> 0 | P23: =E23*O23 -> 0
B24: 커피머신세정제 | C24: 1ea | D24: kg | E24: 12000 | F24: 1 | G24: 1 | H24: 12000 | M24: 1 | O24: =J24+K24+L24+M24+N24 -> 1 | P24: =E24*O24 -> 12000
B25: 15cm 개별포장커피스틱 | C25: 1box=10000ea | D25: ea | E25: 6.4 | F25: 10000 | G25: 1000 | H25: 64000 | I25: 1000 | O25: =J25+K25+L25+M25+N25 -> 0 | P25: =E25*O25 -> 0
B26: 18cm 개별포장커피스틱 | C26: 1box=10000ea | D26: ea | E26: 6.8 | F26: 10000 | G26: 1000 | H26: 68000 | O26: =J26+K26+L26+M26+N26 -> 0 | P26: =E26*O26 -> 0
B27: opp 비닐봉투 18*25 | C27: 1pack=200ea | D27: ea | E27: 25 | F27: 200 | G27: 200 | H27: 5000 | O27: =J27+K27+L27+M27+N27 -> 0 | P27: =E27*O27 -> 0
B28: 콤부차오리지날 | C28: 1box=12ea | D28: ea | E28: 2100 | F28: 12 | G28: 1 | H28: 25200 | I28: 6 | O28: =J28+K28+L28+M28+N28 -> 0 | P28: =E28*O28 -> 0
B29: 콤부차진저레몬 | C29: 1box=12ea | D29: ea | E29: 2100 | F29: 12 | G29: 1 | H29: 25200 | I29: 5 | O29: =J29+K29+L29+M29+N29 -> 0 | P29: =E29*O29 -> 0
B30: 콤부차석류 | C30: 1box=12ea | D30: ea | E30: 2100 | F30: 12 | G30: 1 | H30: 25200 | I30: 4 | O30: =J30+K30+L30+M30+N30 -> 0 | P30: =E30*O30 -> 0
B31: 슈가시럽 | C31: 1box=6ea | D31: ea | E31: 2800 | F31: 6 | G31: 1 | H31: 16800 | O31: =J31+K31+L31+M31+N31 -> 0 | P31: =E31*O31 -> 0
B32: 슈가시럽(24년인상) | C32: 1box=6ea | D32: ea | E32: 3200 | F32: 6 | G32: 1 | H32: 19200 | I32: 1 | M32: 1 | O32: =J32+K32+L32+M32+N32 -> 1 | P32: =E32*O32 -> 3200
B33: 삼다수 | C33: 1box=20ea | D33: ea | E33: 410 | F33: 20 | G33: 1 | H33: 8200 | I33: 3 | O33: =J33+K33+L33+M33+N33 -> 0 | P33: =E33*O33 -> 0
B34: 립톤 복숭아파우더(907g) | C34: 1box=12ea | D34: ea | E34: 7200 | F34: 12 | G34: 1 | H34: 86400 | O34: =J34+K34+L34+M34+N34 -> 0 | P34: =E34*O34 -> 0
B35: 립톤 복숭아파우더(907g)(24년인상) | C35: 1box=12ea | D35: ea | E35: 7700 | F35: 12 | G35: 1 | H35: 92400 | I35: 4 | K35: 2 | M35: 2 | O35: =J35+K35+L35+M35+N35 -> 4 | P35: =E35*O35 -> 30800
B36: 초정탄산수(1.5L) | C36: 1box=12ea | D36: ea | E36: 1350 | F36: 12 | G36: 1 | H36: 16200 | I36: 2 | K36: 3 | M36: 5 | O36: =J36+K36+L36+M36+N36 -> 8 | P36: =E36*O36 -> 10800
B37: 메티에 바닐라시럽(700ml) | C37: 1box=8ea | D37: ea | E37: 6870 | F37: 8 | G37: 1 | H37: 54960 | O37: =J37+K37+L37+M37+N37 -> 0 | P37: =E37*O37 -> 0
B38: 메티에 헤이즐럿시럽(700ml) | C38: 1box=8ea | D38: ea | E38: 6870 | F38: 8 | G38: 1 | H38: 54960 | O38: =J38+K38+L38+M38+N38 -> 0 | P38: =E38*O38 -> 0
B39: 메티에 바닐라시럽(750ml) | C39: 1box=8ea | D39: ea | E39: 7360 | F39: 8 | G39: 1 | H39: 58880 | I39: 1 | K39: 1 | M39: 2 | O39: =J39+K39+L39+M39+N39 -> 3 | P39: =E39*O39 -> 22080
B40: 메티에 헤이즐럿시럽(750ml) | C40: 1box=8ea | D40: ea | E40: 7360 | F40: 8 | G40: 1 | H40: 58880 | I40: 1 | K40: 1 | M40: 1 | O40: =J40+K40+L40+M40+N40 -> 2 | P40: =E40*O40 -> 14720
A41: 성원애드피아 | B41: 적립쿠폰 | C41: 1bundle=500ea | D41: ea | E41: 6.4 | F41: 500 | G41: 100 | H41: 3200 | K41: 100 | M41: 100 | O41: =J41+K41+L41+M41+N41 -> 200 | P41: =E41*O41 -> 1280
B42: 유통기한 스티커 | C42: 1bundle=1000ea | D42: ea | E42: 4.69 | F42: 1000 | G42: 100 | H42: 4690 | O42: =J42+K42+L42+M42+N42 -> 0 | P42: =E42*O42 -> 0
...

Sheet 의과대학
A1: 카페 쿠피 1월 발주 관리 대장 (의과대학)
A4: 협력사 | B4: 품목명 | C4: 규격 | D4: 단위 | E4: 입고단가 | F4: 입고단위 | G4: 입고단위단가 | H4: 전월 재고 | I4: 1주차 발주 | J4: 2주차 발주 | K4: 3주차 발주 | L4: 4주차 발주 | M4: 5주차 발주 | N4: 월 발주량 | O4: 월 발주 금액
A5: 비스토리코리아 | B5: 종이컵(-12oz) | C5: 1box=1000ea | D5: ea | E5: 37 | F5: 1000 | G5: 37000 | N5: =I5+J5+K5+L5+M5 -> 0 | O5: =E5*N5 -> 0
B6: 종이컵-16oz | C6: 1box=1000ea | D6: ea | E6: 43 | F6: 1000 | G6: 43000 | H6: 300 | N6: =I6+J6+K6+L6+M6 -> 0 | O6: =E6*N6 -> 0
B7: 종이컵뚜껑 (12,16oz) | C7: 1box=1000ea | D7: ea | E7: 20 | F7: 1000 | G7: 20000 | H7: 600 | N7: =I7+J7+K7+L7+M7 -> 0 | O7: =E7*N7 -> 0
B8: 아이스(페트)컵(14oz) | C8: 1box=1000ea | D8: ea | E8: 42 | F8: 1000 | G8: 42000 | N8: =I8+J8+K8+L8+M8 -> 0 | O8: =E8*N8 -> 0
B9: 아이스컵(16oz) | C9: 1box=1000ea | D9: ea | E9: 53 | F9: 1000 | G9: 53000 | H9: 1300 | N9: =I9+J9+K9+L9+M9 -> 0 | O9: =E9*N9 -> 0
B10: 아이스컵(24oz) | C10: 1box=1000ea | D10: ea | E10: 65 | F10: 1000 | G10: 65000 | H10: 900 | N10: =I10+J10+K10+L10+M10 -> 0 | O10: =E10*N10 -> 0
B11: 아이스컵 돔뚜껑(93Ø) | C11: 1box=1000ea | D11: ea | E11: 18.5 | F11: 1000 | G11: 18500 | H11: 1050 | N11: =I11+J11+K11+L11+M11 -> 0 | O11: =E11*N11 -> 0
B12: 아이스컵 돔뚜껑(98Ø) | C12: 1box=1000ea | D12: ea | E12: 20 | F12: 1000 | G12: 20000 | H12: 950 | N12: =I12+J12+K12+L12+M12 -> 0 | O12: =E12*N12 -> 0
B13: 아이스컵 평뚜껑(98Ø) | C13: 1box=1000ea | D13: ea | E13: 19 | F13: 1000 | G13: 19000 | N13: =I13+J13+K13+L13+M13 -> 0 | O13: =E13*N13 -> 0
B14: 10/13홀더 (1도인쇄) | C14: 1box=1000ea | D14: ea | E14: 17.5 | F14: 1000 | G14: 17500 | N14: =I14+J14+K14+L14+M14 -> 0 | O14: =E14*N14 -> 0
B15: 12/16홀더(1도인쇄) | C15: 1box=1000ea | D15: ea | E15: 18 | F15: 1000 | G15: 18000 | L15: 1000 | N15: =I15+J15+K15+L15+M15 -> 1000 | O15: =E15*N15 -> 18000
B16: 21cm 일자 스트로우 (투명) | C16: 1box=10000ea | D16: ea | E16: 6.9 | F16: 10000 | G16: 69000 | H16: 500 | N16: =I16+J16+K16+L16+M16 -> 0 | O16: =E16*N16 -> 0
B17: 21cm 버블티 스트로우 | C17: 1box=3200ea | D17: ea | E17: 22.1875 | F17: 3200 | G17: 71000 | J17: 200 | N17: =I17+J17+K17+L17+M17 -> 200 | O17: =E17*N17 -> 4437.5
B18: 25cm 일자 스트로우 (블랙) | C18: 1box=10000ea | D18: ea | E18: 7.2 | F18: 10000 | G18: 72000 | H18: 500 | N18: =I18+J18+K18+L18+M18 -> 0 | O18: =E18*N18 -> 0
B19: 21cm 종이 스트로우 | C19: 1box=5000ea | D19: ea | E19: 18 | F19: 5000 | G19: 90000 | N19: =I19+J19+K19+L19+M19 -> 0 | O19: =E19*N19 -> 0
B20: 21cm 종이 버블 스트로우 | C20: 1box=4000ea | D20: ea | E20: 26.7 | F20: 4000 | G20: 106800 | N20: =I20+J20+K20+L20+M20 -> 0 | O20: =E20*N20 -> 0
B21: 25cm 버블티 스트로우 | C21: 1box=3200ea | D21: ea | E21: 22.8125 | F21: 3200 | G21: 73000 | N21: =I21+J21+K21+L21+M21 -> 0 | O21: =E21*N21 -> 0
B22: 캐리어 무지(크라프트지) | C22: 1box=200ea | D22: ea | E22: 112.5 | F22: 200 | G22: 22500 | H22: 75 | N22: =I22+J22+K22+L22+M22 -> 0 | O22: =E22*N22 -> 0
B23: 갈색무지냅킨 | C23: 1box=8000ea | D23: ea | E23: 3.625 | F23: 8000 | G23: 29000 | H23: 4000 | N23: =I23+J23+K23+L23+M23 -> 0 | O23: =E23*N23 -> 0
B24: 커피머신세정제 | C24: 1ea | D24: kg | E24: 12000 | F24: 1 | G24: 12000 | N24: =I24+J24+K24+L24+M24 -> 0 | O24: =E24*N24 -> 0
B25: 15cm 개별포장커피스틱 | C25: 1box=10000ea | D25: ea | E25: 6.4 | F25: 10000 | G25: 64000 | H25: 3000 | N25: =I25+J25+K25+L25+M25 -> 0 | O25: =E25*N25 -> 0
B26: 18cm 개별포장커피스틱 | C26: 1box=10000ea | D26: ea | E26: 6.8 | F26: 10000 | G26: 68000 | N26: =I26+J26+K26+L26+M26 -> 0 | O26: =E26*N26 -> 0
B27: opp 비닐봉투 18*25 | C27: 1pack=200ea | D27: ea | E27: 25 | F27: 200 | G27: 5000 | N27: =I27+J27+K27+L27+M27 -> 0 | O27: =E27*N27 -> 0
B28: 콤부차오리지날 | C28: 1box=12ea | D28: ea | E28: 2100 | F28: 12 | G28: 25200 | N28: =I28+J28+K28+L28+M28 -> 0 | O28: =E28*N28 -> 0
B29: 콤부차진저레몬 | C29: 1box=12ea | D29: ea | E29: 2100 | F29: 12 | G29: 25200 | N29: =I29+J29+K29+L29+M29 -> 0 | O29: =E29*N29 -> 0
B30: 콤부차석류 | C30: 1box=12ea | D30: ea | E30: 2100 | F30: 12 | G30: 25200 | N30: =I30+J30+K30+L30+M30 -> 0 | O30: =E30*N30 -> 0
B31: 슈가시럽 | C31: 1box=6ea | D31: ea | E31: 2800 | F31: 6 | G31: 16800 | N31: =I31+J31+K31+L31+M31 -> 0 | O31: =E31*N31 -> 0
B32: 슈가시럽(24년인상) | C32: 1box=6ea | D32: ea | E32: 3200 | F32: 6 | G32: 19200 | H32: 1 | N32: =I32+J32+K32+L32+M32 -> 0 | O32: =E32*N32 -> 0
B33: 삼다수 | C33: 1box=20ea | D33: ea | E33: 410 | F33: 20 | G33: 8200 | N33: =I33+J33+K33+L33+M33 -> 0 | O33: =E33*N33 -> 0
B34: 립톤 복숭아파우더(907g) | C34: 1box=12ea | D34: ea | E34: 7200 | F34: 12 | G34: 86400 | N34: =I34+J34+K34+L34+M34 -> 0 | O34: =E34*N34 -> 0
B35: 립톤 복숭아파우더(907g)(24년인상) | C35: 1box=12ea | D35: ea | E35: 7700 | F35: 12 | G35: 92400 | H35: 5 | N35: =I35+J35+K35+L35+M35 -> 0 | O35: =E35*N35 -> 0
B36: 초정탄산수(1.5L) | C36: 1box=12ea | D36: ea | E36: 1350 | F36: 12 | G36: 16200 | J36: 3 | N36: =I36+J36+K36+L36+M36 -> 3 | O36: =E36*N36 -> 4050
B37: 메티에 바닐라시럽(700ml) | C37: 1box=8ea | D37: ea | E37: 6870 | F37: 8 | G37: 54960 | N37: =I37+J37+K37+L37+M37 -> 0 | O37: =E37*N37 -> 0
B38: 메티에 헤이즐럿시럽(700ml) | C38: 1box=8ea | D38: ea | E38: 6870 | F38: 8 | G38: 54960 | N38: =I38+J38+K38+L38+M38 -> 0 | O38: =E38*N38 -> 0
B39: 메티에 바닐라시럽(750ml) | C39: 1box=8ea | D39: ea | E39: 7360 | F39: 8 | G39: 58880 | H39: 1 | L39: 1 | N39: =I39+J39+K39+L39+M39 -> 1 | O39: =E39*N39 -> 7360
B40: 메티에 헤이즐럿시럽(750ml) | C40: 1box=8ea | D40: ea | E40: 7360 | F40: 8 | G40: 58880 | H40: 1 | N40: =I40+J40+K40+L40+M40 -> 0 | O40: =E40*N40 -> 0
A41: 성원애드피아 | B41: 적립쿠폰 | C41: 1bundle=500ea | D41: ea | E41: 6.4 | F41: 500 | G41: 3200 | J41: 100 | N41: =I41+J41+K41+L41+M41 -> 100 | O41: =E41*N41 -> 640
B42: 유통기한 스티커 | C42: 1bundle=1000ea | D42: ea | E42: 4.69 | F42: 1000 | G42: 4690 | N42: =I42+J42+K42+L42+M42 -> 0 | O42: =E42*N42 -> 0
...

Sheet 중앙도서관
A1: 카페 쿠피 1월 발주 관리 대장 (중앙도서관)
A4: 협력사 | B4: 품목명 | C4: 규격 | D4: 단위 | E4: 입고단가 | F4: 입고단위 | G4: 입고단위단가 | H4: 전월 재고 | I4: 1주차 발주 | J4: 2주차 발주 | K4: 3주차 발주 | L4: 4주차 발주 | M4: 5주차 발주 | N4: 월 발주량 | O4: 월 발주 금액
A5: 비스토리코리아 | B5: 종이컵(-12oz) | C5: 1box=1000ea | D5: ea | E5: 37 | F5: 1000 | G5: 37000 | N5: =I5+J5+K5+L5+M5 -> 0 | O5: =E5*N5 -> 0
B6: 종이컵-16oz | C6: 1box=1000ea | D6: ea | E6: 43 | F6: 1000 | G6: 43000 | H6: 1000 | N6: =I6+J6+K6+L6+M6 -> 0 | O6: =E6*N6 -> 0
B7: 종이컵뚜껑 (12,16oz) | C7: 1box=1000ea | D7: ea | E7: 20 | F7: 1000 | G7: 20000 | H7: 700 | L7: 1000 | N7: =I7+J7+K7+L7+M7 -> 1000 | O7: =E7*N7 -> 20000
B8: 아이스(페트)컵(14oz) | C8: 1box=1000ea | D8: ea | E8: 42 | F8: 1000 | G8: 42000 | N8: =I8+J8+K8+L8+M8 -> 0 | O8: =E8*N8 -> 0
B9: 아이스컵(16oz) | C9: 1box=1000ea | D9: ea | E9: 53 | F9: 1000 | G9: 53000 | H9: 1600 | N9: =I9+J9+K9+L9+M9 -> 0 | O9: =E9*N9 -> 0
