Workbook

Sheet 본사창고
A1: 카페 쿠피 12월 입출고 관리 대장 (본사창고)
A4: 협력사 | B4: 품목명 | C4: 규격 | D4: 단위 | E4: 입고단가 | F4: 입고단위 | G4: 입고단위단가 | H4: 전월 재고 | I4: 1주차 입고 | J4: 2주차 입고 | K4: 3주차 입고 | L4: 4주차 입고 | M4: 5주차 입고 | N4: 월 입고량 | O4: 월 입고 금액 | P4: 1주차 출고량 | Q4: 2주차 출고량 | R4: 3주차 출고량 | S4: 4주차 출고량 | T4: 5주차 출고량 | U4: 월 출고량 | V4: 월 출고 금액 | W4: 현재고 | X4: 현재고 금액 | Y4: 비고 | Z4: 발주량 | AA4: 발주금액 | AB4: 발주합계 (부가세 별도) | AC4: 발주합계 (부가세 포함)
A5: 비스토리코리아 | B5: 종이컵(-12oz) | C5: 1box=1000ea | D5: ea | E5: 37 | F5: 1000 | G5: 37000 | H5: 5000 | I5: 0 | N5: =I5+J5+K5+L5+M5 -> 0 | O5: =E5*N5 -> 0 | P5: ='교육용,R&D,삼의원(잇다카페)'!I5+푸른솔!I5+의과대학!I5+중앙도서관!I5+학생회관!I5+멀티미디어관!I5+제2기숙사!I5+선승관!I5+예술디자인대!I5+공학관!I5 -> 0 | Q5: ='교육용,R&D,삼의원(잇다카페)'!J5+푸른솔!J5+의과대학!J5+중앙도서관!J5+학생회관!J5+멀티미디어관!J5+제2기숙사!J5+선승관!J5+예술디자인대!J5+공학관!J5 -> 0 | R5: ='교육용,R&D,삼의원(잇다카페)'!K5+푸른솔!K5+의과대학!K5+중앙도서관!K5+학생회관!K5+멀티미디어관!K5+제2기숙사!K5+선승관!K5+예술디자인대!K5+공학관!K5 -> 0 | S5: ='교육용,R&D,삼의원(잇다카페)'!L5+푸른솔!L5+의과대학!L5+중앙도서관!L5+학생회관!L5+멀티미디어관!L5+제2기숙사!L5+선승관!L5+예술디자인대!L5+공학관!L5 -> 0 | T5: ='교육용,R&D,삼의원(잇다카페)'!M5+푸른솔!M5+의과대학!M5+중앙도서관!M5+학생회관!M5+멀티미디어관!M5+제2기숙사!M5+선승관!M5+예술디자인대!M5+공학관!M5 -> 0 | U5: =P5+Q5+R5+S5+T5 -> 0 | V5: =E5*U5 -> 0 | W5: =(H5+N5)-U5 -> 5000 | X5: =E5*W5 -> 185000 | Z5: 0 | AA5: =Z5*E5 -> 0 | AB5: =SUM(AA5:AA36) -> 0 | AC5: =AB5*1.1 -> 0
B6: 종이컵-16oz | C6: 1box=1000ea | D6: ea | E6: 43 | F6: 1000 | G6: 43000 | H6: 8000 | I6: 0 | N6: =I6+J6+K6+L6+M6 -> 0 | O6: =E6*N6 -> 0 | P6: ='교육용,R&D,삼의원(잇다카페)'!I6+푸른솔!I6+의과대학!I6+중앙도서관!I6+학생회관!I6+멀티미디어관!I6+제2기숙사!I6+선승관!I6+예술디자인대!I6+공학관!I6 -> 1000 | Q6: ='교육용,R&D,삼의원(잇다카페)'!J6+푸른솔!J6+의과대학!J6+중앙도서관!J6+학생회관!J6+멀티미디어관!J6+제2기숙사!J6+선승관!J6+예술디자인대!J6+공학관!J6 -> 3000 | R6: ='교육용,R&D,삼의원(잇다카페)'!K6+푸른솔!K6+의과대학!K6+중앙도서관!K6+학생회관!K6+멀티미디어관!K6+제2기숙사!K6+선승관!K6+예술디자인대!K6+공학관!K6 -> 1000 | S6: ='교육용,R&D,삼의원(잇다카페)'!L6+푸른솔!L6+의과대학!L6+중앙도서관!L6+학생회관!L6+멀티미디어관!L6+제2기숙사!L6+선승관!L6+예술디자인대!L6+공학관!L6 -> 0 | T6: ='교육용,R&D,삼의원(잇다카페)'!M6+푸른솔!M6+의과대학!M6+중앙도서관!M6+학생회관!M6+멀티미디어관!M6+제2기숙사!M6+선승관!M6+예술디자인대!M6+공학관!M6 -> 0 | U6: =P6+Q6+R6+S6+T6 -> 5000 | V6: =E6*U6 -> 215000 | W6: =(H6+N6)-U6 -> 3000 | X6: =E6*W6 -> 129000 | Z6: 0 | AA6: =Z6*E6 -> 0
B7: 종이컵뚜껑 (12,16oz) | C7: 1box=1000ea | D7: ea | E7: 20 | F7: 1000 | G7: 20000 | H7: 6000 | I7: 2000 | N7: =I7+J7+K7+L7+M7 -> 2000 | O7: =E7*N7 -> 40000 | P7: ='교육용,R&D,삼의원(잇다카페)'!I7+푸른솔!I7+의과대학!I7+중앙도서관!I7+학생회관!I7+멀티미디어관!I7+제2기숙사!I7+선승관!I7+예술디자인대!I7+공학관!I7 -> 4000 | Q7: ='교육용,R&D,삼의원(잇다카페)'!J7+푸른솔!J7+의과대학!J7+중앙도서관!J7+학생회관!J7+멀티미디어관!J7+제2기숙사!J7+선승관!J7+예술디자인대!J7+공학관!J7 -> 0 | R7: ='교육용,R&D,삼의원(잇다카페)'!K7+푸른솔!K7+의과대학!K7+중앙도서관!K7+학생회관!K7+멀티미디어관!K7+제2기숙사!K7+선승관!K7+예술디자인대!K7+공학관!K7 -> 1000 | S7: ='교육용,R&D,삼의원(잇다카페)'!L7+푸른솔!L7+의과대학!L7+중앙도서관!L7+학생회관!L7+멀티미디어관!L7+제2기숙사!L7+선승관!L7+예술디자인대!L7+공학관!L7 -> 0 | T7: ='교육용,R&D,삼의원(잇다카페)'!M7+푸른솔!M7+의과대학!M7+중앙도서관!M7+학생회관!M7+멀티미디어관!M7+제2기숙사!M7+선승관!M7+예술디자인대!M7+공학관!M7 -> 0 | U7: =P7+Q7+R7+S7+T7 -> 5000 | V7: =E7*U7 -> 100000 | W7: =(H7+N7)-U7 -> 3000 | X7: =E7*W7 -> 60000 | Z7: 0 | AA7: =Z7*E7 -> 0
B8: 아이스(페트)컵(14oz) | C8: 1box=1000ea | D8: ea | E8: 42 | F8: 1000 | G8: 42000 | H8: 0 | I8: 0 | N8: =I8+J8+K8+L8+M8 -> 0 | O8: =E8*N8 -> 0 | P8: ='교육용,R&D,삼의원(잇다카페)'!I8+푸른솔!I8+의과대학!I8+중앙도서관!I8+학생회관!I8+멀티미디어관!I8+제2기숙사!I8+선승관!I8+예술디자인대!I8+공학관!I8 -> 0 | Q8: ='교육용,R&D,삼의원(잇다카페)'!J8+푸른솔!J8+의과대학!J8+중앙도서관!J8+학생회관!J8+멀티미디어관!J8+제2기숙사!J8+선승관!J8+예술디자인대!J8+공학관!J8 -> 0 | R8: ='교육용,R&D,삼의원(잇다카페)'!K8+푸른솔!K8+의과대학!K8+중앙도서관!K8+학생회관!K8+멀티미디어관!K8+제2기숙사!K8+선승관!K8+예술디자인대!K8+공학관!K8 -> 0 | S8: ='교육용,R&D,삼의원(잇다카페)'!L8+푸른솔!L8+의과대학!L8+중앙도서관!L8+학생회관!L8+멀티미디어관!L8+제2기숙사!L8+선승관!L8+예술디자인대!L8+공학관!L8 -> 0 | T8: ='교육용,R&D,삼의원(잇다카페)'!M8+푸른솔!M8+의과대학!M8+중앙도서관!M8+학생회관!M8+멀티미디어관!M8+제2기숙사!M8+선승관!M8+예술디자인대!M8+공학관!M8 -> 0 | U8: =P8+Q8+R8+S8+T8 -> 0 | V8: =E8*U8 -> 0 | W8: =(H8+N8)-U8 -> 0 | X8: =E8*W8 -> 0 | Z8: 0 | AA8: =Z8*E8 -> 0
B9: 아이스컵(16oz) | C9: 1box=1000ea | D9: ea | E9: 53 | F9: 1000 | G9: 53000 | H9: 4000 | I9: 6000 | N9: =I9+J9+K9+L9+M9 -> 6000 | O9: =E9*N9 -> 318000 | P9: ='교육용,R&D,삼의원(잇다카페)'!I9+푸른솔!I9+의과대학!I9+중앙도서관!I9+학생회관!I9+멀티미디어관!I9+제2기숙사!I9+선승관!I9+예술디자인대!I9+공학관!I9 -> 2000 | Q9: ='교육용,R&D,삼의원(잇다카페)'!J9+푸른솔!J9+의과대학!J9+중앙도서관!J9+학생회관!J9+멀티미디어관!J9+제2기숙사!J9+선승관!J9+예술디자인대!J9+공학관!J9 -> 1000 | R9: ='교육용,R&D,삼의원(잇다카페)'!K9+푸른솔!K9+의과대학!K9+중앙도서관!K9+학생회관!K9+멀티미디어관!K9+제2기숙사!K9+선승관!K9+예술디자인대!K9+공학관!K9 -> 3000 | S9: ='교육용,R&D,삼의원(잇다카페)'!L9+푸른솔!L9+의과대학!L9+중앙도서관!L9+학생회관!L9+멀티미디어관!L9+제2기숙사!L9+선승관!L9+예술디자인대!L9+공학관!L9 -> 0 | T9: ='교육용,R&D,삼의원(잇다카페)'!M9+푸른솔!M9+의과대학!M9+중앙도서관!M9+학생회관!M9+멀티미디어관!M9+제2기숙사!M9+선승관!M9+예술디자인대!M9+공학관!M9 -> 0 | U9: =P9+Q9+R9+S9+T9 -> 6000 | V9: =E9*U9 -> 318000 | W9: =(H9+N9)-U9 -> 4000 | X9: =E9*W9 -> 212000 | Z9: 0 | AA9: =Z9*E9 -> 0
B10: 아이스컵(24oz) | C10: 1box=1000ea | D10: ea | E10: 65 | F10: 1000 | G10: 65000 | H10: 7000 | I10: 0 | N10: =I10+J10+K10+L10+M10 -> 0 | O10: =E10*N10 -> 0 | P10: ='교육용,R&D,삼의원(잇다카페)'!I10+푸른솔!I10+의과대학!I10+중앙도서관!I10+학생회관!I10+멀티미디어관!I10+제2기숙사!I10+선승관!I10+예술디자인대!I10+공학관!I10 -> 0 | Q10: ='교육용,R&D,삼의원(잇다카페)'!J10+푸른솔!J10+의과대학!J10+중앙도서관!J10+학생회관!J10+멀티미디어관!J10+제2기숙사!J10+선승관!J10+예술디자인대!J10+공학관!J10 -> 0 | R10: ='교육용,R&D,삼의원(잇다카페)'!K10+푸른솔!K10+의과대학!K10+중앙도서관!K10+학생회관!K10+멀티미디어관!K10+제2기숙사!K10+선승관!K10+예술디자인대!K10+공학관!K10 -> 0 | S10: ='교육용,R&D,삼의원(잇다카페)'!L10+푸른솔!L10+의과대학!L10+중앙도서관!L10+학생회관!L10+멀티미디어관!L10+제2기숙사!L10+선승관!L10+예술디자인대!L10+공학관!L10 -> 0 | T10: ='교육용,R&D,삼의원(잇다카페)'!M10+푸른솔!M10+의과대학!M10+중앙도서관!M10+학생회관!M10+멀티미디어관!M10+제2기숙사!M10+선승관!M10+예술디자인대!M10+공학관!M10 -> 0 | U10: =P10+Q10+R10+S10+T10 -> 0 | V10: =E10*U10 -> 0 | W10: =(H10+N10)-U10 -> 7000 | X10: =E10*W10 -> 455000 | Z10: 0 | AA10: =Z10*E10 -> 0
B11: 아이스컵 돔뚜껑(93Ø) | C11: 1box=1000ea | D11: ea | E11: 18.5 | F11: 1000 | G11: 18500 | H11: 3000 | I11: 7000 | N11: =I11+J11+K11+L11+M11 -> 7000 | O11: =E11*N11 -> 129500 | P11: ='교육용,R&D,삼의원(잇다카페)'!I11+푸른솔!I11+의과대학!I11+중앙도서관!I11+학생회관!I11+멀티미디어관!I11+제2기숙사!I11+선승관!I11+예술디자인대!I11+공학관!I11 -> 2000 | Q11: ='교육용,R&D,삼의원(잇다카페)'!J11+푸른솔!J11+의과대학!J11+중앙도서관!J11+학생회관!J11+멀티미디어관!J11+제2기숙사!J11+선승관!J11+예술디자인대!J11+공학관!J11 -> 2000 | R11: ='교육용,R&D,삼의원(잇다카페)'!K11+푸른솔!K11+의과대학!K11+중앙도서관!K11+학생회관!K11+멀티미디어관!K11+제2기숙사!K11+선승관!K11+예술디자인대!K11+공학관!K11 -> 3000 | S11: ='교육용,R&D,삼의원(잇다카페)'!L11+푸른솔!L11+의과대학!L11+중앙도서관!L11+학생회관!L11+멀티미디어관!L11+제2기숙사!L11+선승관!L11+예술디자인대!L11+공학관!L11 -> 0 | T11: ='교육용,R&D,삼의원(잇다카페)'!M11+푸른솔!M11+의과대학!M11+중앙도서관!M11+학생회관!M11+멀티미디어관!M11+제2기숙사!M11+선승관!M11+예술디자인대!M11+공학관!M11 -> 0 | U11: =P11+Q11+R11+S11+T11 -> 7000 | V11: =E11*U11 -> 129500 | W11: =(H11+N11)-U11 -> 3000 | X11: =E11*W11 -> 55500 | Z11: 0 | AA11: =Z11*E11 -> 0
B12: 아이스컵 돔뚜껑(98Ø) | C12: 1box=1000ea | D12: ea | E12: 20 | F12: 1000 | G12: 20000 | H12: 8000 | I12: 0 | N12: =I12+J12+K12+L12+M12 -> 0 | O12: =E12*N12 -> 0 | P12: ='교육용,R&D,삼의원(잇다카페)'!I12+푸른솔!I12+의과대학!I12+중앙도서관!I12+학생회관!I12+멀티미디어관!I12+제2기숙사!I12+선승관!I12+예술디자인대!I12+공학관!I12 -> 0 | Q12: ='교육용,R&D,삼의원(잇다카페)'!J12+푸른솔!J12+의과대학!J12+중앙도서관!J12+학생회관!J12+멀티미디어관!J12+제2기숙사!J12+선승관!J12+예술디자인대!J12+공학관!J12 -> 1000 | R12: ='교육용,R&D,삼의원(잇다카페)'!K12+푸른솔!K12+의과대학!K12+중앙도서관!K12+학생회관!K12+멀티미디어관!K12+제2기숙사!K12+선승관!K12+예술디자인대!K12+공학관!K12 -> 0 | S12: ='교육용,R&D,삼의원(잇다카페)'!L12+푸른솔!L12+의과대학!L12+중앙도서관!L12+학생회관!L12+멀티미디어관!L12+제2기숙사!L12+선승관!L12+예술디자인대!L12+공학관!L12 -> 0 | T12: ='교육용,R&D,삼의원(잇다카페)'!M12+푸른솔!M12+의과대학!M12+중앙도서관!M12+학생회관!M12+멀티미디어관!M12+제2기숙사!M12+선승관!M12+예술디자인대!M12+공학관!M12 -> 0 | U12: =P12+Q12+R12+S12+T12 -> 1000 | V12: =E12*U12 -> 20000 | W12: =(H12+N12)-U12 -> 7000 | X12: =E12*W12 -> 140000 | Z12: 0 | AA12: =Z12*E12 -> 0
B13: 아이스컵 평뚜껑(98Ø) | C13: 1box=1000ea | D13: ea | E13: 19 | F13: 1000 | G13: 19000 | H13: 1000 | I13: 0 | N13: =I13+J13+K13+L13+M13 -> 0 | O13: =E13*N13 -> 0 | P13: ='교육용,R&D,삼의원(잇다카페)'!I13+푸른솔!I13+의과대학!I13+중앙도서관!I13+학생회관!I13+멀티미디어관!I13+제2기숙사!I13+선승관!I13+예술디자인대!I13+공학관!I13 -> 0 | Q13: ='교육용,R&D,삼의원(잇다카페)'!J13+푸른솔!J13+의과대학!J13+중앙도서관!J13+학생회관!J13+멀티미디어관!J13+제2기숙사!J13+선승관!J13+예술디자인대!J13+공학관!J13 -> 0 | R13: ='교육용,R&D,삼의원(잇다카페)'!K13+푸른솔!K13+의과대학!K13+중앙도서관!K13+학생회관!K13+멀티미디어관!K13+제2기숙사!K13+선승관!K13+예술디자인대!K13+공학관!K13 -> 0 | S13: ='교육용,R&D,삼의원(잇다카페)'!L13+푸른솔!L13+의과대학!L13+중앙도서관!L13+학생회관!L13+멀티미디어관!L13+제2기숙사!L13+선승관!L13+예술디자인대!L13+공학관!L13 -> 0 | T13: ='교육용,R&D,삼의원(잇다카페)'!M13+푸른솔!M13+의과대학!M13+중앙도서관!M13+학생회관!M13+멀티미디어관!M13+제2기숙사!M13+선승관!M13+예술디자인대!M13+공학관!M13 -> 0 | U13: =P13+Q13+R13+S13+T13 -> 0 | V13: =E13*U13 -> 0 | W13: =(H13+N13)-U13 -> 1000 | X13: =E13*W13 -> 19000 | Z13: 0 | AA13: =Z13*E13 -> 0
B14: 10/13홀더 | C14: 1box=1000ea | D14: ea | E14: 17.5 | F14: 1000 | G14: 17500 | H14: 5000 | I14: 0 | N14: =I14+J14+K14+L14+M14 -> 0 | O14: =E14*N14 -> 0 | P14: ='교육용,R&D,삼의원(잇다카페)'!I14+푸른솔!I14+의과대학!I14+중앙도서관!I14+학생회관!I14+멀티미디어관!I14+제2기숙사!I14+선승관!I14+예술디자인대!I14+공학관!I14 -> 0 | Q14: ='교육용,R&D,삼의원(잇다카페)'!J14+푸른솔!J14+의과대학!J14+중앙도서관!J14+학생회관!J14+멀티미디어관!J14+제2기숙사!J14+선승관!J14+예술디자인대!J14+공학관!J14 -> 0 | R14: ='교육용,R&D,삼의원(잇다카페)'!K14+푸른솔!K14+의과대학!K14+중앙도서관!K14+학생회관!K14+멀티미디어관!K14+제2기숙사!K14+선승관!K14+예술디자인대!K14+공학관!K14 -> 0 | S14: ='교육용,R&D,삼의원(잇다카페)'!L14+푸른솔!L14+의과대학!L14+중앙도서관!L14+학생회관!L14+멀티미디어관!L14+제2기숙사!L14+선승관!L14+예술디자인대!L14+공학관!L14 -> 0 | T14: ='교육용,R&D,삼의원(잇다카페)'!M14+푸른솔!M14+의과대학!M14+중앙도서관!M14+학생회관!M14+멀티미디어관!M14+제2기숙사!M14+선승관!M14+예술디자인대!M14+공학관!M14 -> 0 | U14: =P14+Q14+R14+S14+T14 -> 0 | V14: =E14*U14 -> 0 | W14: =(H14+N14)-U14 -> 5000 | X14: =E14*W14 -> 87500 | Z14: 0 | AA14: =Z14*E14 -> 0
B15: 12/16홀더 | C15: 1box=1000ea | D15: ea | E15: 18 | F15: 1000 | G15: 18000 | H15: 3000 | I15: 17000 | N15: =I15+J15+K15+L15+M15 -> 17000 | O15: =E15*N15 -> 306000 | P15: ='교육용,R&D,삼의원(잇다카페)'!I15+푸른솔!I15+의과대학!I15+중앙도서관!I15+학생회관!I15+멀티미디어관!I15+제2기숙사!I15+선승관!I15+예술디자인대!I15+공학관!I15 -> 4000 | Q15: ='교육용,R&D,삼의원(잇다카페)'!J15+푸른솔!J15+의과대학!J15+중앙도서관!J15+학생회관!J15+멀티미디어관!J15+제2기숙사!J15+선승관!J15+예술디자인대!J15+공학관!J15 -> 2000 | R15: ='교육용,R&D,삼의원(잇다카페)'!K15+푸른솔!K15+의과대학!K15+중앙도서관!K15+학생회관!K15+멀티미디어관!K15+제2기숙사!K15+선승관!K15+예술디자인대!K15+공학관!K15 -> 6000 | S15: ='교육용,R&D,삼의원(잇다카페)'!L15+푸른솔!L15+의과대학!L15+중앙도서관!L15+학생회관!L15+멀티미디어관!L15+제2기숙사!L15+선승관!L15+예술디자인대!L15+공학관!L15 -> 0 | T15: ='교육용,R&D,삼의원(잇다카페)'!M15+푸른솔!M15+의과대학!M15+중앙도서관!M15+학생회관!M15+멀티미디어관!M15+제2기숙사!M15+선승관!M15+예술디자인대!M15+공학관!M15 -> 0 | U15: =P15+Q15+R15+S15+T15 -> 12000 | V15: =E15*U15 -> 216000 | W15: =(H15+N15)-U15 -> 8000 | X15: =E15*W15 -> 144000 | Z15: 0 | AA15: =Z15*E15 -> 0
B16: 21cm 일자 스트로우 (투명) | C16: 1box=10000ea | D16: ea | E16: 6.9 | F16: 10000 | G16: 69000 | H16: 1000 | I16: 10000 | N16: =I16+J16+K16+L16+M16 -> 10000 | O16: =E16*N16 -> 69000 | P16: ='교육용,R&D,삼의원(잇다카페)'!I16+푸른솔!I16+의과대학!I16+중앙도서관!I16+학생회관!I16+멀티미디어관!I16+제2기숙사!I16+선승관!I16+예술디자인대!I16+공학관!I16 -> 1000 | Q16: ='교육용,R&D,삼의원(잇다카페)'!J16+푸른솔!J16+의과대학!J16+중앙도서관!J16+학생회관!J16+멀티미디어관!J16+제2기숙사!J16+선승관!J16+예술디자인대!J16+공학관!J16 -> 1500 | R16: ='교육용,R&D,삼의원(잇다카페)'!K16+푸른솔!K16+의과대학!K16+중앙도서관!K16+학생회관!K16+멀티미디어관!K16+제2기숙사!K16+선승관!K16+예술디자인대!K16+공학관!K16 -> 3000 | S16: ='교육용,R&D,삼의원(잇다카페)'!L16+푸른솔!L16+의과대학!L16+중앙도서관!L16+학생회관!L16+멀티미디어관!L16+제2기숙사!L16+선승관!L16+예술디자인대!L16+공학관!L16 -> 0 | T16: ='교육용,R&D,삼의원(잇다카페)'!M16+푸른솔!M16+의과대학!M16+중앙도서관!M16+학생회관!M16+멀티미디어관!M16+제2기숙사!M16+선승관!M16+예술디자인대!M16+공학관!M16 -> 0 | U16: =P16+Q16+R16+S16+T16 -> 5500 | V16: =E16*U16 -> 37950 | W16: =(H16+N16)-U16 -> 5500 | X16: =E16*W16 -> 37950 | Z16: 0 | AA16: =Z16*E16 -> 0
B17: 21cm 버블티 스트로우 | C17: 1box=3200ea | D17: ea | E17: 22.1875 | F17: 3200 | G17: 71000 | H17: 4200 | I17: 0 | N17: =I17+J17+K17+L17+M17 -> 0 | O17: =E17*N17 -> 0 | P17: ='교육용,R&D,삼의원(잇다카페)'!I17+푸른솔!I17+의과대학!I17+중앙도서관!I17+학생회관!I17+멀티미디어관!I17+제2기숙사!I17+선승관!I17+예술디자인대!I17+공학관!I17 -> 0 | Q17: ='교육용,R&D,삼의원(잇다카페)'!J17+푸른솔!J17+의과대학!J17+중앙도서관!J17+학생회관!J17+멀티미디어관!J17+제2기숙사!J17+선승관!J17+예술디자인대!J17+공학관!J17 -> 0 | R17: ='교육용,R&D,삼의원(잇다카페)'!K17+푸른솔!K17+의과대학!K17+중앙도서관!K17+학생회관!K17+멀티미디어관!K17+제2기숙사!K17+선승관!K17+예술디자인대!K17+공학관!K17 -> 0 | S17: ='교육용,R&D,삼의원(잇다카페)'!L17+푸른솔!L17+의과대학!L17+중앙도서관!L17+학생회관!L17+멀티미디어관!L17+제2기숙사!L17+선승관!L17+예술디자인대!L17+공학관!L17 -> 0 | T17: ='교육용,R&D,삼의원(잇다카페)'!M17+푸른솔!M17+의과대학!M17+중앙도서관!M17+학생회관!M17+멀티미디어관!M17+제2기숙사!M17+선승관!M17+예술디자인대!M17+공학관!M17 -> 0 | U17: =P17+Q17+R17+S17+T17 -> 0 | V17: =E17*U17 -> 0 | W17: =(H17+N17)-U17 -> 4200 | X17: =E17*W17 -> 93187.5 | Z17: 0 | AA17: =Z17*E17 -> 0
... B36: 메티에 헤이즐럿시럽(700ml) | C36: 1box=8ea | D36: ea | E36: 6870 | F36: 8 | G36: 54960 | H36: 8 | I36: 24 | N36: =I36+J36+K36+L36+M36 -> 24 | O36: =E36*N36 -> 164880 | P36: ='교육용,R&D,삼의원(잇다카페)'!I36+푸른솔!I36+의과대학!I36+중앙도서관!I36+학생회관!I36+멀티미디어관!I36+제2기숙사!I36+선승관!I36+예술디자인대!I36+공학관!I36 -> 4 | Q36: ='교육용,R&D,삼의원(잇다카페)'!J36+푸른솔!J36+의과대학!J36+중앙도서관!J36+학생회관!J36+멀티미디어관!J36+제2기숙사!J36+선승관!J36+예술디자인대!J36+공학관!J36 -> 4 | R36: ='교육용,R&D,삼의원(잇다카페)'!K36+푸른솔!K36+의과대학!K36+중앙도서관!K36+학생회관!K36+멀티미디어관!K36+제2기숙사!K36+선승관!K36+예술디자인대!K36+공학관!K36 -> 2 | S36: ='교육용,R&D,삼의원(잇다카페)'!L36+푸른솔!L36+의과대학!L36+중앙도서관!L36+학생회관!L36+멀티미디어관!L36+제2기숙사!L36+선승관!L36+예술디자인대!L36+공학관!L36 -> 0 | T36: ='교육용,R&D,삼의원(잇다카페)'!M36+푸른솔!M36+의과대학!M36+중앙도서관!M36+학생회관!M36+멀티미디어관!M36+제2기숙사!M36+선승관!M36+예술디자인대!M36+공학관!M36 -> 0 | U36: =P36+Q36+R36+S36+T36 -> 10 | V36: =E36*U36 -> 68700 | W36: =(H36+N36)-U36 -> 22 | X36: =E36*W36 -> 151140 | Z36: 0 | AA36: =Z36*E36 -> 0
A37: 성원애드피아 | B37: 적립쿠폰 | C37: 1bundle=500ea | D37: ea | E37: 6.4 | F37: 500 | G37: 3200 | H37: 20500 | N37: =I37+J37+K37+L37+M37 -> 0 | O37: =E37*N37 -> 0 | P37: ='교육용,R&D,삼의원(잇다카페)'!I37+푸른솔!I37+의과대학!I37+중앙도서관!I37+학생회관!I37+멀티미디어관!I37+제2기숙사!I37+선승관!I37+예술디자인대!I37+공학관!I37 -> 200 | Q37: ='교육용,R&D,삼의원(잇다카페)'!J37+푸른솔!J37+의과대학!J37+중앙도서관!J37+학생회관!J37+멀티미디어관!J37+제2기숙사!J37+선승관!J37+예술디자인대!J37+공학관!J37 -> 100 | R37: ='교육용,R&D,삼의원(잇다카페)'!K37+푸른솔!K37+의과대학!K37+중앙도서관!K37+학생회관!K37+멀티미디어관!K37+제2기숙사!K37+선승관!K37+예술디자인대!K37+공학관!K37 -> 0 | S37: ='교육용,R&D,삼의원(잇다카페)'!L37+푸른솔!L37+의과대학!L37+중앙도서관!L37+학생회관!L37+멀티미디어관!L37+제2기숙사!L37+선승관!L37+예술디자인대!L37+공학관!L37 -> 0 | T37: ='교육용,R&D,삼의원(잇다카페)'!M37+푸른솔!M37+의과대학!M37+중앙도서관!M37+학생회관!M37+멀티미디어관!M37+제2기숙사!M37+선승관!M37+예술디자인대!M37+공학관!M37 -> 0 | U37: =P37+Q37+R37+S37+T37 -> 300 | V37: =E37*U37 -> 1920 | W37: =(H37+N37)-U37 -> 20200 | X37: =E37*W37 -> 129280 | Z37: 0 | AA37: =Z37*E37 -> 0 | AB37: =SUM(AA37:AA38) -> 0 | AC37: =AB37*1.1 -> 0
B38: 유통기한 스티커 | C38: 1bundle=1000ea | D38: ea | E38: 4.69 | F38: 1000 | G38: 4690 | H38: 3580 | N38: =I38+J38+K38+L38+M38 -> 0 | O38: =E38*N38 -> 0 | P38: ='교육용,R&D,삼의원(잇다카페)'!I38+푸른솔!I38+의과대학!I38+중앙도서관!I38+학생회관!I38+멀티미디어관!I38+제2기숙사!I38+선승관!I38+예술디자인대!I38+공학관!I38 -> 0 | Q38: ='교육용,R&D,삼의원(잇다카페)'!J38+푸른솔!J38+의과대학!J38+중앙도서관!J38+학생회관!J38+멀티미디어관!J38+제2기숙사!J38+선승관!J38+예술디자인대!J38+공학관!J38 -> 0 | R38: ='교육용,R&D,삼의원(잇다카페)'!K38+푸른솔!K38+의과대학!K38+중앙도서관!K38+학생회관!K38+멀티미디어관!K38+제2기숙사!K38+선승관!K38+예술디자인대!K38+공학관!K38 -> 0 | S38: ='교육용,R&D,삼의원(잇다카페)'!L38+푸른솔!L38+의과대학!L38+중앙도서관!L38+학생회관!L38+멀티미디어관!L38+제2기숙사!L38+선승관!L38+예술디자인대!L38+공학관!L38 -> 0 | T38: ='교육용,R&D,삼의원(잇다카페)'!M38+푸른솔!M38+의과대학!M38+중앙도서관!M38+학생회관!M38+멀티미디어관!M38+제2기숙사!M38+선승관!M38+예술디자인대!M38+공학관!M38 -> 0 | U38: =P38+Q38+R38+S38+T38 -> 0 | V38: =E38*U38 -> 0 | W38: =(H38+N38)-U38 -> 3580 | X38: =E38*W38 -> 16790.2 | Z38: 0 | AA38: =Z38*E38 -> 0
A39: 휴럼 | B39: 민트초코파우더 | C39: 1box = 12ea | D39: ea | E39: 7700 | F39: 12 | G39: 92400 | H39: 19 | N39: =I39+J39+K39+L39+M39 -> 0 | O39: =E39*N39 -> 0 | P39: ='교육용,R&D,삼의원(잇다카페)'!I39+푸른솔!I39+의과대학!I39+중앙도서관!I39+학생회관!I39+멀티미디어관!I39+제2기숙사!I39+선승관!I39+예술디자인대!I39+공학관!I39 -> 4 | Q39: ='교육용,R&D,삼의원(잇다카페)'!J39+푸른솔!J39+의과대학!J39+중앙도서관!J39+학생회관!J39+멀티미디어관!J39+제2기숙사!J39+선승관!J39+예술디자인대!J39+공학관!J39 -> 0 | R39: ='교육용,R&D,삼의원(잇다카페)'!K39+푸른솔!K39+의과대학!K39+중앙도서관!K39+학생회관!K39+멀티미디어관!K39+제2기숙사!K39+선승관!K39+예술디자인대!K39+공학관!K39 -> 2 | S39: ='교육용,R&D,삼의원(잇다카페)'!L39+푸른솔!L39+의과대학!L39+중앙도서관!L39+학생회관!L39+멀티미디어관!L39+제2기숙사!L39+선승관!L39+예술디자인대!L39+공학관!L39 -> 0 | T39: ='교육용,R&D,삼의원(잇다카페)'!M39+푸른솔!M39+의과대학!M39+중앙도서관!M39+학생회관!M39+멀티미디어관!M39+제2기숙사!M39+선승관!M39+예술디자인대!M39+공학관!M39 -> 0 | U39: =P39+Q39+R39+S39+T39 -> 6 | V39: =E39*U39 -> 46200 | W39: =(H39+N39)-U39 -> 13 | X39: =E39*W39 -> 100100 | Z39: 0 | AA39: =Z39*E39 -> 0 | AB39: =SUM(AA39:AA48) -> 0 | AC39: =AB39*1.1 -> 0
B40: 다크초코파우더 | C40: 1box = 12ea | D40: ea | E40: 6200 | F40: 12 | G40: 74400 | H40: 33 | N40: =I40+J40+K40+L40+M40 -> 0 | O40: =E40*N40 -> 0 | P40: ='교육용,R&D,삼의원(잇다카페)'!I40+푸른솔!I40+의과대학!I40+중앙도서관!I40+학생회관!I40+멀티미디어관!I40+제2기숙사!I40+선승관!I40+예술디자인대!I40+공학관!I40 -> 11 | Q40: ='교육용,R&D,삼의원(잇다카페)'!J40+푸른솔!J40+의과대학!J40+중앙도서관!J40+학생회관!J40+멀티미디어관!J40+제2기숙사!J40+선승관!J40+예술디자인대!J40+공학관!J40 -> 5 | R40: ='교육용,R&D,삼의원(잇다카페)'!K40+푸른솔!K40+의과대학!K40+중앙도서관!K40+학생회관!K40+멀티미디어관!K40+제2기숙사!K40+선승관!K40+예술디자인대!K40+공학관!K40 -> 8 | S40: ='교육용,R&D,삼의원(잇다카페)'!L40+푸른솔!L40+의과대학!L40+중앙도서관!L40+학생회관!L40+멀티미디어관!L40+제2기숙사!L40+선승관!L40+예술디자인대!L40+공학관!L40 -> 0 | T40: ='교육용,R&D,삼의원(잇다카페)'!M40+푸른솔!M40+의과대학!M40+중앙도서관!M40+학생회관!M40+멀티미디어관!M40+제2기숙사!M40+선승관!M40+예술디자인대!M40+공학관!M40 -> 0 | U40: =P40+Q40+R40+S40+T40 -> 24 | V40: =E40*U40 -> 148800 | W40: =(H40+N40)-U40 -> 9 | X40: =E40*W40 -> 55800 | Z40: 0 | AA40: =Z40*E40 -> 0
B41: 청귤베이스 | C41: 1box = 12ea | D41: ea | E41: 6700 | F41: 12 | G41: 80400 | H41: 39 | N41: =I41+J41+K41+L41+M41 -> 0 | O41: =E41*N41 -> 0 | P41: ='교육용,R&D,삼의원(잇다카페)'!I41+푸른솔!I41+의과대학!I41+중앙도서관!I41+학생회관!I41+멀티미디어관!I41+제2기숙사!I41+선승관!I41+예술디자인대!I41+공학관!I41 -> 4 | Q41: ='교육용,R&D,삼의원(잇다카페)'!J41+푸른솔!J41+의과대학!J41+중앙도서관!J41+학생회관!J41+멀티미디어관!J41+제2기숙사!J41+선승관!J41+예술디자인대!J41+공학관!J41 -> 6 | R41: ='교육용,R&D,삼의원(잇다카페)'!K41+푸른솔!K41+의과대학!K41+중앙도서관!K41+학생회관!K41+멀티미디어관!K41+제2기숙사!K41+선승관!K41+예술디자인대!K41+공학관!K41 -> 7 | S41: ='교육용,R&D,삼의원(잇다카페)'!L41+푸른솔!L41+의과대학!L41+중앙도서관!L41+학생회관!L41+멀티미디어관!L41+제2기숙사!L41+선승관!L41+예술디자인대!L41+공학관!L41 -> 0 | T41: ='교육용,R&D,삼의원(잇다카페)'!M41+푸른솔!M41+의과대학!M41+중앙도서관!M41+학생회관!M41+멀티미디어관!M41+제2기숙사!M41+선승관!M41+예술디자인대!M41+공학관!M41 -> 0 | U41: =P41+Q41+R41+S41+T41 -> 17 | V41: =E41*U41 -> 113900 | W41: =(H41+N41)-U41 -> 22 | X41: =E41*W41 -> 147400 | Z41: 0 | AA41: =Z41*E41 -> 0
B42: 요거에스플레인 | C42: 1box=12ea | D42: ea | E42: 7250 | F42: 12 | G42: 87000 | H42: 50 | N42: =I42+J42+K42+L42+M42 -> 0 | O42: =E42*N42 -> 0 | P42: ='교육용,R&D,삼의원(잇다카페)'!I42+푸른솔!I42+의과대학!I42+중앙도서관!I42+학생회관!I42+멀티미디어관!I42+제2기숙사!I42+선승관!I42+예술디자인대!I42+공학관!I42 -> 3 | Q42: ='교육용,R&D,삼의원(잇다카페)'!J42+푸른솔!J42+의과대학!J42+중앙도서관!J42+학생회관!J42+멀티미디어관!J42+제2기숙사!J42+선승관!J42+예술디자인대!J42+공학관!J42 -> 3 | R42: ='교육용,R&D,삼의원(잇다카페)'!K42+푸른솔!K42+의과대학!K42+중앙도서관!K42+학생회관!K42+멀티미디어관!K42+제2기숙사!K42+선승관!K42+예술디자인대!K42+공학관!K42 -> 5 | S42: ='교육용,R&D,삼의원(잇다카페)'!L42+푸른솔!L42+의과대학!L42+중앙도서관!L42+학생회관!L42+멀티미디어관!L42+제2기숙사!L42+선승관!L42+예술디자인대!L42+공학관!L42 -> 0 | T42: ='교육용,R&D,삼의원(잇다카페)'!M42+푸른솔!M42+의과대학!M42+중앙도서관!M42+학생회관!M42+멀티미디어관!M42+제2기숙사!M42+선승관!M42+예술디자인대!M42+공학관!M42 -> 0 | U42: =P42+Q42+R42+S42+T42 -> 11 | V42: =E42*U42 -> 79750 | W42: =(H42+N42)-U42 -> 39 | X42: =E42*W42 -> 282750 | Z42: 0 | AA42: =Z42*E42 -> 0
B43: 흑당베이스 | C43: 1kg x 12ea | D43: ea | E43: 5300 | F43: 12 | G43: 63600 | H43: 13 | N43: =I43+J43+K43+L43+M43 -> 0 | O43: =E43*N43 -> 0 | P43: ='교육용,R&D,삼의원(잇다카페)'!I43+푸른솔!I43+의과대학!I43+중앙도서관!I43+학생회관!I43+멀티미디어관!I43+제2기숙사!I43+선승관!I43+예술디자인대!I43+공학관!I43 -> 1 | Q43: ='교육용,R&D,삼의원(잇다카페)'!J43+푸른솔!J43+의과대학!J43+중앙도서관!J43+학생회관!J43+멀티미디어관!J43+제2기숙사!J43+선승관!J43+예술디자인대!J43+공학관!J43 -> 2 | R43: ='교육용,R&D,삼의원(잇다카페)'!K43+푸른솔!K43+의과대학!K43+중앙도서관!K43+학생회관!K43+멀티미디어관!K43+제2기숙사!K43+선승관!K43+예술디자인대!K43+공학관!K43 -> 1 | S43: ='교육용,R&D,삼의원(잇다카페)'!L43+푸른솔!L43+의과대학!L43+중앙도서관!L43+학생회관!L43+멀티미디어관!L43+제2기숙사!L43+선승관!L43+예술디자인대!L43+공학관!L43 -> 0 | T43: ='교육용,R&D,삼의원(잇다카페)'!M43+푸른솔!M43+의과대학!M43+중앙도서관!M43+학생회관!M43+멀티미디어관!M43+제2기숙사!M43+선승관!M43+예술디자인대!M43+공학관!M43 -> 0 | U43: =P43+Q43+R43+S43+T43 -> 4 | V43: =E43*U43 -> 21200 | W43: =(H43+N43)-U43 -> 9 | X43: =E43*W43 -> 47700 | Z43: 0 | AA43: =Z43*E43 -> 0
B44: 쿠키앤크림 파우더 | C44: 1kg x 12ea | D44: ea | E44: 6600 | F44: 12 | G44: 79200 | H44: 24 | N44: =I44+J44+K44+L44+M44 -> 0 | O44: =E44*N44 -> 0 | P44: ='교육용,R&D,삼의원(잇다카페)'!I44+푸른솔!I44+의과대학!I44+중앙도서관!I44+학생회관!I44+멀티미디어관!I44+제2기숙사!I44+선승관!I44+예술디자인대!I44+공학관!I44 -> 6 | Q44: ='교육용,R&D,삼의원(잇다카페)'!J44+푸른솔!J44+의과대학!J44+중앙도서관!J44+학생회관!J44+멀티미디어관!J44+제2기숙사!J44+선승관!J44+예술디자인대!J44+공학관!J44 -> 1 | R44: ='교육용,R&D,삼의원(잇다카페)'!K44+푸른솔!K44+의과대학!K44+중앙도서관!K44+학생회관!K44+멀티미디어관!K44+제2기숙사!K44+선승관!K44+예술디자인대!K44+공학관!K44 -> 3 | S44: ='교육용,R&D,삼의원(잇다카페)'!L44+푸른솔!L44+의과대학!L44+중앙도서관!L44+학생회관!L44+멀티미디어관!L44+제2기숙사!L44+선승관!L44+예술디자인대!L44+공학관!L44 -> 0 | T44: ='교육용,R&D,삼의원(잇다카페)'!M44+푸른솔!M44+의과대학!M44+중앙도서관!M44+학생회관!M44+멀티미디어관!M44+제2기숙사!M44+선승관!M44+예술디자인대!M44+공학관!M44 -> 0 | U44: =P44+Q44+R44+S44+T44 -> 10 | V44: =E44*U44 -> 66000 | W44: =(H44+N44)-U44 -> 14 | X44: =E44*W44 -> 92400 | Z44: 0 | AA44: =Z44*E44 -> 0
B45: 자몽 베이스 | C45: 1.8kg x 6ea | D45: ea | E45: 14500 | F45: 6 | G45: 87000 | H45: 12 | N45: =I45+J45+K45+L45+M45 -> 0 | O45: =E45*N45 -> 0 | P45: ='교육용,R&D,삼의원(잇다카페)'!I45+푸른솔!I45+의과대학!I45+중앙도서관!I45+학생회관!I45+멀티미디어관!I45+제2기숙사!I45+선승관!I45+예술디자인대!I45+공학관!I45 -> 6 | Q45: ='교육용,R&D,삼의원(잇다카페)'!J45+푸른솔!J45+의과대학!J45+중앙도서관!J45+학생회관!J45+멀티미디어관!J45+제2기숙사!J45+선승관!J45+예술디자인대!J45+공학관!J45 -> 0 | R45: ='교육용,R&D,삼의원(잇다카페)'!K45+푸른솔!K45+의과대학!K45+중앙도서관!K45+학생회관!K45+멀티미디어관!K45+제2기숙사!K45+선승관!K45+예술디자인대!K45+공학관!K45 -> 6 | S45: ='교육용,R&D,삼의원(잇다카페)'!L45+푸른솔!L45+의과대학!L45+중앙도서관!L45+학생회관!L45+멀티미디어관!L45+제2기숙사!L45+선승관!L45+예술디자인대!L45+공학관!L45 -> 0 | T45: ='교육용,R&D,삼의원(잇다카페)'!M45+푸른솔!M45+의과대학!M45+중앙도서관!M45+학생회관!M45+멀티미디어관!M45+제2기숙사!M45+선승관!M45+예술디자인대!M45+공학관!M45 -> 0 | U45: =P45+Q45+R45+S45+T45 -> 12 | V45: =E45*U45 -> 174000 | W45: =(H45+N45)-U45 -> 0 | X45: =E45*W45 -> 0 | Z45: 0 | AA45: =Z45*E45 -> 0
B46: 수박 베이스 | C46: 1.8kg x 6ea | D46: ea | E46: 11000 | F46: 6 | G46: 66000 | H46: 14 | N46: =I46+J46+K46+L46+M46 -> 0 | O46: =E46*N46 -> 0 | P46: ='교육용,R&D,삼의원(잇다카페)'!I46+푸른솔!I46+의과대학!I46+중앙도서관!I46+학생회관!I46+멀티미디어관!I46+제2기숙사!I46+선승관!I46+예술디자인대!I46+공학관!I46 -> 0 | Q46: ='교육용,R&D,삼의원(잇다카페)'!J46+푸른솔!J46+의과대학!J46+중앙도서관!J46+학생회관!J46+멀티미디어관!J46+제2기숙사!J46+선승관!J46+예술디자인대!J46+공학관!J46 -> 1 | R46: ='교육용,R&D,삼의원(잇다카페)'!K46+푸른솔!K46+의과대학!K46+중앙도서관!K46+학생회관!K46+멀티미디어관!K46+제2기숙사!K46+선승관!K46+예술디자인대!K46+공학관!K46 -> 0 | S46: ='교육용,R&D,삼의원(잇다카페)'!L46+푸른솔!L46+의과대학!L46+중앙도서관!L46+학생회관!L46+멀티미디어관!L46+제2기숙사!L46+선승관!L46+예술디자인대!L46+공학관!L46 -> 0 | T46: ='교육용,R&D,삼의원(잇다카페)'!M46+푸른솔!M46+의과대학!M46+중앙도서관!M46+학생회관!M46+멀티미디어관!M46+제2기숙사!M46+선승관!M46+예술디자인대!M46+공학관!M46 -> 0 | U46: =P46+Q46+R46+S46+T46 -> 1 | V46: =E46*U46 -> 11000 | W46: =(H46+N46)-U46 -> 13 | X46: =E46*W46 -> 143000 | Z46: 0 | AA46: =Z46*E46 -> 0
B47: 17곡 파우더 | C47: 1kg x 12ea | D47: ea | E47: 4500 | F47: 12 | G47: 54000 | H47: 16 | N47: =I47+J47+K47+L47+M47 -> 0 | O47: =E47*N47 -> 0 | P47: ='교육용,R&D,삼의원(잇다카페)'!I47+푸른솔!I47+의과대학!I47+중앙도서관!I47+학생회관!I47+멀티미디어관!I47+제2기숙사!I47+선승관!I47+예술디자인대!I47+공학관!I47 -> 5 | Q47: ='교육용,R&D,삼의원(잇다카페)'!J47+푸른솔!J47+의과대학!J47+중앙도서관!J47+학생회관!J47+멀티미디어관!J47+제2기숙사!J47+선승관!J47+예술디자인대!J47+공학관!J47 -> 1 | R47: ='교육용,R&D,삼의원(잇다카페)'!K47+푸른솔!K47+의과대학!K47+중앙도서관!K47+학생회관!K47+멀티미디어관!K47+제2기숙사!K47+선승관!K47+예술디자인대!K47+공학관!K47 -> 5 | S47: ='교육용,R&D,삼의원(잇다카페)'!L47+푸른솔!L47+의과대학!L47+중앙도서관!L47+학생회관!L47+멀티미디어관!L47+제2기숙사!L47+선승관!L47+예술디자인대!L47+공학관!L47 -> 0 | T47: ='교육용,R&D,삼의원(잇다카페)'!M47+푸른솔!M47+의과대학!M47+중앙도서관!M47+학생회관!M47+멀티미디어관!M47+제2기숙사!M47+선승관!M47+예술디자인대!M47+공학관!M47 -> 0 | U47: =P47+Q47+R47+S47+T47 -> 11 | V47: =E47*U47 -> 49500 | W47: =(H47+N47)-U47 -> 5 | X47: =E47*W47 -> 22500 | Z47: 0 | AA47: =Z47*E47 -> 0
B48: 토피넛파우더 | C48: 1box=12ea | D48: ea | E48: 6700 | F48: 12 | G48: 80400 | H48: 28 | N48: =I48+J48+K48+L48+M48 -> 0 | O48: =E48*N48 -> 0 | P48: ='교육용,R&D,삼의원(잇다카페)'!I48+푸른솔!I48+의과대학!I48+중앙도서관!I48+학생회관!I48+멀티미디어관!I48+제2기숙사!I48+선승관!I48+예술디자인대!I48+공학관!I48 -> 6 | Q48: ='교육용,R&D,삼의원(잇다카페)'!J48+푸른솔!J48+의과대학!J48+중앙도서관!J48+학생회관!J48+멀티미디어관!J48+제2기숙사!J48+선승관!J48+예술디자인대!J48+공학관!J48 -> 3 | R48: ='교육용,R&D,삼의원(잇다카페)'!K48+푸른솔!K48+의과대학!K48+중앙도서관!K48+학생회관!K48+멀티미디어관!K48+제2기숙사!K48+선승관!K48+예술디자인대!K48+공학관!K48 -> 7 | S48: ='교육용,R&D,삼의원(잇다카페)'!L48+푸른솔!L48+의과대학!L48+중앙도서관!L48+학생회관!L48+멀티미디어관!L48+제2기숙사!L48+선승관!L48+예술디자인대!L48+공학관!L48 -> 0 | T48: ='교육용,R&D,삼의원(잇다카페)'!M48+푸른솔!M48+의과대학!M48+중앙도서관!M48+학생회관!M48+멀티미디어관!M48+제2기숙사!M48+선승관!M48+예술디자인대!M48+공학관!M48 -> 0 | U48: =P48+Q48+R48+S48+T48 -> 16 | V48: =E48*U48 -> 107200 | W48: =(H48+N48)-U48 -> 12 | X48: =E48*W48 -> 80400 | Z48: 0 | AA48: =Z48*E48 -> 0
A49: 세미기업 | B49: 딸기스무디 원액 | C49: 1.8kg x 6ea | D49: ea | E49: 6900 | F49: 6 | G49: 41400 | H49: 23 | I49: 0 | N49: =I49+J49+K49+L49+M49 -> 0 | O49: =E49*N49 -> 0 | P49: ='교육용,R&D,삼의원(잇다카페)'!I49+푸른솔!I49+의과대학!I49+중앙도서관!I49+학생회관!I49+멀티미디어관!I49+제2기숙사!I49+선승관!I49+예술디자인대!I49+공학관!I49 -> 5 | Q49: ='교육용,R&D,삼의원(잇다카페)'!J49+푸른솔!J49+의과대학!J49+중앙도서관!J49+학생회관!J49+멀티미디어관!J49+제2기숙사!J49+선승관!J49+예술디자인대!J49+공학관!J49 -> 2 | R49: ='교육용,R&D,삼의원(잇다카페)'!K49+푸른솔!K49+의과대학!K49+중앙도서관!K49+학생회관!K49+멀티미디어관!K49+제2기숙사!K49+선승관!K49+예술디자인대!K49+공학관!K49 -> 2 | S49: ='교육용,R&D,삼의원(잇다카페)'!L49+푸른솔!L49+의과대학!L49+중앙도서관!L49+학생회관!L49+멀티미디어관!L49+제2기숙사!L49+선승관!L49+예술디자인대!L49+공학관!L49 -> 0 | T49: ='교육용,R&D,삼의원(잇다카페)'!M49+푸른솔!M49+의과대학!M49+중앙도서관!M49+학생회관!M49+멀티미디어관!M49+제2기숙사!M49+선승관!M49+예술디자인대!M49+공학관!M49 -> 0 | U49: =P49+Q49+R49+S49+T49 -> 9 | V49: =E49*U49 -> 62100 | W49: =(H49+N49)-U49 -> 14 | X49: =E49*W49 -> 96600 | Z49: 0 | AA49: =Z49*E49 -> 0 | AB49: =SUM(AA49:AA58) -> 0 | AC49: =AB49*1.1 -> 0
B50: 망고스무디 원액 | C50: 1.8kg x 6ea | D50: ea | E50: 6900 | F50: 6 | G50: 41400 | H50: 25 | I50: 0 | N50: =I50+J50+K50+L50+M50 -> 0 | O50: =E50*N50 -> 0 | P50: ='교육용,R&D,삼의원(잇다카페)'!I50+푸른솔!I50+의과대학!I50+중앙도서관!I50+학생회관!I50+멀티미디어관!I50+제2기숙사!I50+선승관!I50+예술디자인대!I50+공학관!I50 -> 2 | Q50: ='교육용,R&D,삼의원(잇다카페)'!J50+푸른솔!J50+의과대학!J50+중앙도서관!J50+학생회관!J50+멀티미디어관!J50+제2기숙사!J50+선승관!J50+예술디자인대!J50+공학관!J50 -> 0 | R50: ='교육용,R&D,삼의원(잇다카페)'!K50+푸른솔!K50+의과대학!K50+중앙도서관!K50+학생회관!K50+멀티미디어관!K50+제2기숙사!K50+선승관!K50+예술디자인대!K50+공학관!K50 -> 2 | S50: ='교육용,R&D,삼의원(잇다카페)'!L50+푸른솔!L50+의과대학!L50+중앙도서관!L50+학생회관!L50+멀티미디어관!L50+제2기숙사!L50+선승관!L50+예술디자인대!L50+공학관!L50 -> 0 | T50: ='교육용,R&D,삼의원(잇다카페)'!M50+푸른솔!M50+의과대학!M50+중앙도서관!M50+학생회관!M50+멀티미디어관!M50+제2기숙사!M50+선승관!M50+예술디자인대!M50+공학관!M50 -> 0 | U50: =P50+Q50+R50+S50+T50 -> 4 | V50: =E50*U50 -> 27600 | W50: =(H50+N50)-U50 -> 21 | X50: =E50*W50 -> 144900 | Z50: 0 | AA50: =Z50*E50 -> 0
B51: 베리믹스스무디 원액 | C51: 1.8kg x 6ea | D51: ea | E51: 6800 | F51: 6 | G51: 40800 | H51: 27 | I51: 0 | N51: =I51+J51+K51+L51+M51 -> 0 | O51: =E51*N51 -> 0 | P51: ='교육용,R&D,삼의원(잇다카페)'!I51+푸른솔!I51+의과대학!I51+중앙도서관!I51+학생회관!I51+멀티미디어관!I51+제2기숙사!I51+선승관!I51+예술디자인대!I51+공학관!I51 -> 3 | Q51: ='교육용,R&D,삼의원(잇다카페)'!J51+푸른솔!J51+의과대학!J51+중앙도서관!J51+학생회관!J51+멀티미디어관!J51+제2기숙사!J51+선승관!J51+예술디자인대!J51+공학관!J51 -> 1 | R51: ='교육용,R&D,삼의원(잇다카페)'!K51+푸른솔!K51+의과대학!K51+중앙도서관!K51+학생회관!K51+멀티미디어관!K51+제2기숙사!K51+선승관!K51+예술디자인대!K51+공학관!K51 -> 2 | S51: ='교육용,R&D,삼의원(잇다카페)'!L51+푸른솔!L51+의과대학!L51+중앙도서관!L51+학생회관!L51+멀티미디어관!L51+제2기숙사!L51+선승관!L51+예술디자인대!L51+공학관!L51 -> 0 | T51: ='교육용,R&D,삼의원(잇다카페)'!M51+푸른솔!M51+의과대학!M51+중앙도서관!M51+학생회관!M51+멀티미디어관!M51+제2기숙사!M51+선승관!M51+예술디자인대!M51+공학관!M51 -> 0 | U51: =P51+Q51+R51+S51+T51 -> 6 | V51: =E51*U51 -> 40800 | W51: =(H51+N51)-U51 -> 21 | X51: =E51*W51 -> 142800 | Z51: 0 | AA51: =Z51*E51 -> 0
B52: 베버시티 레몬에이드 | C52: 1kg x 4ea | D52: ea | E52: 15000 | F52: 4 | G52: 60000 | H52: 18 | I52: 20 | N52: =I52+J52+K52+L52+M52 -> 20 | O52: =E52*N52 -> 300000 | P52: ='교육용,R&D,삼의원(잇다카페)'!I52+푸른솔!I52+의과대학!I52+중앙도서관!I52+학생회관!I52+멀티미디어관!I52+제2기숙사!I52+선승관!I52+예술디자인대!I52+공학관!I52 -> 4 | Q52: ='교육용,R&D,삼의원(잇다카페)'!J52+푸른솔!J52+의과대학!J52+중앙도서관!J52+학생회관!J52+멀티미디어관!J52+제2기숙사!J52+선승관!J52+예술디자인대!J52+공학관!J52 -> 5 | R52: ='교육용,R&D,삼의원(잇다카페)'!K52+푸른솔!K52+의과대학!K52+중앙도서관!K52+학생회관!K52+멀티미디어관!K52+제2기숙사!K52+선승관!K52+예술디자인대!K52+공학관!K52 -> 9 | S52: ='교육용,R&D,삼의원(잇다카페)'!L52+푸른솔!L52+의과대학!L52+중앙도서관!L52+학생회관!L52+멀티미디어관!L52+제2기숙사!L52+선승관!L52+예술디자인대!L52+공학관!L52 -> 0 | T52: ='교육용,R&D,삼의원(잇다카페)'!M52+푸른솔!M52+의과대학!M52+중앙도서관!M52+학생회관!M52+멀티미디어관!M52+제2기숙사!M52+선승관!M52+예술디자인대!M52+공학관!M52 -> 0 | U52: =P52+Q52+R52+S52+T52 -> 18 | V52: =E52*U52 -> 270000 | W52: =(H52+N52)-U52 -> 20 | X52: =E52*W52 -> 300000 | Z52: 0 | AA52: =Z52*E52 -> 0
B53: 녹차라떼 | C53: 500g x 6ea | D53: ea | E53: 5300 | F53: 6 | G53: 31800 | H53: 8 | I53: 30 | N53: =I53+J53+K53+L53+M53 -> 30 | O53: =E53*N53 -> 159000 | P53: ='교육용,R&D,삼의원(잇다카페)'!I53+푸른솔!I53+의과대학!I53+중앙도서관!I53+학생회관!I53+멀티미디어관!I53+제2기숙사!I53+선승관!I53+예술디자인대!I53+공학관!I53 -> 13 | Q53: ='교육용,R&D,삼의원(잇다카페)'!J53+푸른솔!J53+의과대학!J53+중앙도서관!J53+학생회관!J53+멀티미디어관!J53+제2기숙사!J53+선승관!J53+예술디자인대!J53+공학관!J53 -> 7 | R53: ='교육용,R&D,삼의원(잇다카페)'!K53+푸른솔!K53+의과대학!K53+중앙도서관!K53+학생회관!K53+멀티미디어관!K53+제2기숙사!K53+선승관!K53+예술디자인대!K53+공학관!K53 -> 14 | S53: ='교육용,R&D,삼의원(잇다카페)'!L53+푸른솔!L53+의과대학!L53+중앙도서관!L53+학생회관!L53+멀티미디어관!L53+제2기숙사!L53+선승관!L53+예술디자인대!L53+공학관!L53 -> 0 | T53: ='교육용,R&D,삼의원(잇다카페)'!M53+푸른솔!M53+의과대학!M53+중앙도서관!M53+학생회관!M53+멀티미디어관!M53+제2기숙사!M53+선승관!M53+예술디자인대!M53+공학관!M53 -> 0 | U53: =P53+Q53+R53+S53+T53 -> 34 | V53: =E53*U53 -> 180200 | W53: =(H53+N53)-U53 -> 4 | X53: =E53*W53 -> 21200 | Z53: 0 | AA53: =Z53*E53 -> 0
B54: 홍차라떼 | C54: 500g x 6ea | D54: ea | E54: 6600 | F54: 6 | G54: 39600 | H54: 20 | I54: 12 | N54: =I54+J54+K54+L54+M54 -> 12 | O54: =E54*N54 -> 79200 | P54: ='교육용,R&D,삼의원(잇다카페)'!I54+푸른솔!I54+의과대학!I54+중앙도서관!I54+학생회관!I54+멀티미디어관!I54+제2기숙사!I54+선승관!I54+예술디자인대!I54+공학관!I54 -> 6 | Q54: ='교육용,R&D,삼의원(잇다카페)'!J54+푸른솔!J54+의과대학!J54+중앙도서관!J54+학생회관!J54+멀티미디어관!J54+제2기숙사!J54+선승관!J54+예술디자인대!J54+공학관!J54 -> 4 | R54: ='교육용,R&D,삼의원(잇다카페)'!K54+푸른솔!K54+의과대학!K54+중앙도서관!K54+학생회관!K54+멀티미디어관!K54+제2기숙사!K54+선승관!K54+예술디자인대!K54+공학관!K54 -> 11 | S54: ='교육용,R&D,삼의원(잇다카페)'!L54+푸른솔!L54+의과대학!L54+중앙도서관!L54+학생회관!L54+멀티미디어관!L54+제2기숙사!L54+선승관!L54+예술디자인대!L54+공학관!L54 -> 0 | T54: ='교육용,R&D,삼의원(잇다카페)'!M54+푸른솔!M54+의과대학!M54+중앙도서관!M54+학생회관!M54+멀티미디어관!M54+제2기숙사!M54+선승관!M54+예술디자인대!M54+공학관!M54 -> 0 | U54: =P54+Q54+R54+S54+T54 -> 21 | V54: =E54*U54 -> 138600 | W54: =(H54+N54)-U54 -> 11 | X54: =E54*W54 -> 72600 | Z54: 0 | AA54: =Z54*E54 -> 0
B55: 고구마페이스트 | C55: 1kg x 10ea | D55: ea | E55: 5600 | F55: 10 | G55: 56000 | H55: 12 | I55: 20 | N55: =I55+J55+K55+L55+M55 -> 20 | O55: =E55*N55 -> 112000 | P55: ='교육용,R&D,삼의원(잇다카페)'!I55+푸른솔!I55+의과대학!I55+중앙도서관!I55+학생회관!I55+멀티미디어관!I55+제2기숙사!I55+선승관!I55+예술디자인대!I55+공학관!I55 -> 7 | Q55: ='교육용,R&D,삼의원(잇다카페)'!J55+푸른솔!J55+의과대학!J55+중앙도서관!J55+학생회관!J55+멀티미디어관!J55+제2기숙사!J55+선승관!J55+예술디자인대!J55+공학관!J55 -> 6 | R55: ='교육용,R&D,삼의원(잇다카페)'!K55+푸른솔!K55+의과대학!K55+중앙도서관!K55+학생회관!K55+멀티미디어관!K55+제2기숙사!K55+선승관!K55+예술디자인대!K55+공학관!K55 -> 11 | S55: ='교육용,R&D,삼의원(잇다카페)'!L55+푸른솔!L55+의과대학!L55+중앙도서관!L55+학생회관!L55+멀티미디어관!L55+제2기숙사!L55+선승관!L55+예술디자인대!L55+공학관!L55 -> 0 | T55: ='교육용,R&D,삼의원(잇다카페)'!M55+푸른솔!M55+의과대학!M55+중앙도서관!M55+학생회관!M55+멀티미디어관!M55+제2기숙사!M55+선승관!M55+예술디자인대!M55+공학관!M55 -> 0 | U55: =P55+Q55+R55+S55+T55 -> 24 | V55: =E55*U55 -> 134400 | W55: =(H55+N55)-U55 -> 8 | X55: =E55*W55 -> 44800 | Z55: 0 | AA55: =Z55*E55 -> 0
B56: 토라니 초코소스 | C56: 1.89L x 4ea | D56: ea | E56: 14100 | F56: 4 | G56: 56400 | H56: 18 | I56: 8 | N56: =I56+J56+K56+L56+M56 -> 8 | O56: =E56*N56 -> 112800 | P56: ='교육용,R&D,삼의원(잇다카페)'!I56+푸른솔!I56+의과대학!I56+중앙도서관!I56+학생회관!I56+멀티미디어관!I56+제2기숙사!I56+선승관!I56+예술디자인대!I56+공학관!I56 -> 2 | Q56: ='교육용,R&D,삼의원(잇다카페)'!J56+푸른솔!J56+의과대학!J56+중앙도서관!J56+학생회관!J56+멀티미디어관!J56+제2기숙사!J56+선승관!J56+예술디자인대!J56+공학관!J56 -> 2 | R56: ='교육용,R&D,삼의원(잇다카페)'!K56+푸른솔!K56+의과대학!K56+중앙도서관!K56+학생회관!K56+멀티미디어관!K56+제2기숙사!K56+선승관!K56+예술디자인대!K56+공학관!K56 -> 5 | S56: ='교육용,R&D,삼의원(잇다카페)'!L56+푸른솔!L56+의과대학!L56+중앙도서관!L56+학생회관!L56+멀티미디어관!L56+제2기숙사!L56+선승관!L56+예술디자인대!L56+공학관!L56 -> 0 | T56: ='교육용,R&D,삼의원(잇다카페)'!M56+푸른솔!M56+의과대학!M56+중앙도서관!M56+학생회관!M56+멀티미디어관!M56+제2기숙사!M56+선승관!M56+예술디자인대!M56+공학관!M56 -> 0 | U56: =P56+Q56+R56+S56+T56 -> 9 | V56: =E56*U56 -> 126900 | W56: =(H56+N56)-U56 -> 17 | X56: =E56*W56 -> 239700 | Z56: 0 | AA56: =Z56*E56 -> 0
B57: 토라니 카라멜소스 | C57: 1.89L x 4ea | D57: ea | E57: 15100 | F57: 4 | G57: 60400 | H57: 0 | I57: 12 | N57: =I57+J57+K57+L57+M57 -> 12 | O57: =E57*N57 -> 181200 | P57: ='교육용,R&D,삼의원(잇다카페)'!I57+푸른솔!I57+의과대학!I57+중앙도서관!I57+학생회관!I57+멀티미디어관!I57+제2기숙사!I57+선승관!I57+예술디자인대!I57+공학관!I57 -> 2 | Q57: ='교육용,R&D,삼의원(잇다카페)'!J57+푸른솔!J57+의과대학!J57+중앙도서관!J57+학생회관!J57+멀티미디어관!J57+제2기숙사!J57+선승관!J57+예술디자인대!J57+공학관!J57 -> 2 | R57: ='교육용,R&D,삼의원(잇다카페)'!K57+푸른솔!K57+의과대학!K57+중앙도서관!K57+학생회관!K57+멀티미디어관!K57+제2기숙사!K57+선승관!K57+예술디자인대!K57+공학관!K57 -> 3 | S57: ='교육용,R&D,삼의원(잇다카페)'!L57+푸른솔!L57+의과대학!L57+중앙도서관!L57+학생회관!L57+멀티미디어관!L57+제2기숙사!L57+선승관!L57+예술디자인대!L57+공학관!L57 -> 0 | T57: ='교육용,R&D,삼의원(잇다카페)'!M57+푸른솔!M57+의과대학!M57+중앙도서관!M57+학생회관!M57+멀티미디어관!M57+제2기숙사!M57+선승관!M57+예술디자인대!M57+공학관!M57 -> 0 | U57: =P57+Q57+R57+S57+T57 -> 7 | V57: =E57*U57 -> 105700 | W57: =(H57+N57)-U57 -> 5 | X57: =E57*W57 -> 75500 | Z57: 0 | AA57: =Z57*E57 -> 0
B58: 베버시티 청포도에이드 | C58: 1kg x 4ea | D58: ea | E58: 15300 | F58: 4 | G58: 61200 | H58: 23 | I58: 0 | N58: =I58+J58+K58+L58+M58 -> 0 | O58: =E58*N58 -> 0 | P58: ='교육용,R&D,삼의원(잇다카페)'!I58+푸른솔!I58+의과대학!I58+중앙도서관!I58+학생회관!I58+멀티미디어관!I58+제2기숙사!I58+선승관!I58+예술디자인대!I58+공학관!I58 -> 2 | Q58: ='교육용,R&D,삼의원(잇다카페)'!J58+푸른솔!J58+의과대학!J58+중앙도서관!J58+학생회관!J58+멀티미디어관!J58+제2기숙사!J58+선승관!J58+예술디자인대!J58+공학관!J58 -> 2 | R58: ='교육용,R&D,삼의원(잇다카페)'!K58+푸른솔!K58+의과대학!K58+중앙도서관!K58+학생회관!K58+멀티미디어관!K58+제2기숙사!K58+선승관!K58+예술디자인대!K58+공학관!K58 -> 6 | S58: ='교육용,R&D,삼의원(잇다카페)'!L58+푸른솔!L58+의과대학!L58+중앙도서관!L58+학생회관!L58+멀티미디어관!L58+제2기숙사!L58+선승관!L58+예술디자인대!L58+공학관!L58 -> 0 | T58: ='교육용,R&D,삼의원(잇다카페)'!M58+푸른솔!M58+의과대학!M58+중앙도서관!M58+학생회관!M58+멀티미디어관!M58+제2기숙사!M58+선승관!M58+예술디자인대!M58+공학관!M58 -> 0 | U58: =P58+Q58+R58+S58+T58 -> 10 | V58: =E58*U58 -> 153000 | W58: =(H58+N58)-U58 -> 13 | X58: =E58*W58 -> 198900 | Z58: 0 | AA58: =Z58*E58 -> 0
A59: 손맛커피 | B59: 신규 원두 | C59: 1box=10kg | D59: ea | E59: 11000 | F59: 10 | G59: 110000 | H59: 75 | I59: 300 | N59: =I59+J59+K59+L59+M59 -> 300 | O59: =E59*N59 -> 3300000 | P59: ='교육용,R&D,삼의원(잇다카페)'!I59+푸른솔!I59+의과대학!I59+중앙도서관!I59+학생회관!I59+멀티미디어관!I59+제2기숙사!I59+선승관!I59+예술디자인대!I59+공학관!I59 -> 64 | Q59: ='교육용,R&D,삼의원(잇다카페)'!J59+푸른솔!J59+의과대학!J59+중앙도서관!J59+학생회관!J59+멀티미디어관!J59+제2기숙사!J59+선승관!J59+예술디자인대!J59+공학관!J59 -> 54 | R59: ='교육용,R&D,삼의원(잇다카페)'!K59+푸른솔!K59+의과대학!K59+중앙도서관!K59+학생회관!K59+멀티미디어관!K59+제2기숙사!K59+선승관!K59+예술디자인대!K59+공학관!K59 -> 82 | S59: ='교육용,R&D,삼의원(잇다카페)'!L59+푸른솔!L59+의과대학!L59+중앙도서관!L59+학생회관!L59+멀티미디어관!L59+제2기숙사!L59+선승관!L59+예술디자인대!L59+공학관!L59 -> 0 | T59: ='교육용,R&D,삼의원(잇다카페)'!M59+푸른솔!M59+의과대학!M59+중앙도서관!M59+학생회관!M59+멀티미디어관!M59+제2기숙사!M59+선승관!M59+예술디자인대!M59+공학관!M59 -> 0 | U59: =P59+Q59+R59+S59+T59 -> 200 | V59: =E59*U59 -> 2200000 | W59: =(H59+N59)-U59 -> 175 | X59: =E59*W59 -> 1925000 | Z59: 0 | AA59: =Z59*E59 -> 0 | AB59: =SUM(AA59) -> 0 | AC59: =AB59*1.1 -> 0
B60: 디카페인 원두 | C60: 1box=10kg | D60: ea | E60: 19000 | F60: 10 | G60: 190000 | H60: 20 | N60: =I60+J60+K60+L60+M60 -> 0 | O60: =E60*N60 -> 0 | P60: ='교육용,R&D,삼의원(잇다카페)'!I60+푸른솔!I60+의과대학!I60+중앙도서관!I60+학생회관!I60+멀티미디어관!I60+제2기숙사!I60+선승관!I60+예술디자인대!I60+공학관!I60 -> 6 | Q60: ='교육용,R&D,삼의원(잇다카페)'!J60+푸른솔!J60+의과대학!J60+중앙도서관!J60+학생회관!J60+멀티미디어관!J60+제2기숙사!J60+선승관!J60+예술디자인대!J60+공학관!J60 -> 1 | R60: ='교육용,R&D,삼의원(잇다카페)'!K60+푸른솔!K60+의과대학!K60+중앙도서관!K60+학생회관!K60+멀티미디어관!K60+제2기숙사!K60+선승관!K60+예술디자인대!K60+공학관!K60 -> 2 | S60: ='교육용,R&D,삼의원(잇다카페)'!L60+푸른솔!L60+의과대학!L60+중앙도서관!L60+학생회관!L60+멀티미디어관!L60+제2기숙사!L60+선승관!L60+예술디자인대!L60+공학관!L60 -> 0 | T60: ='교육용,R&D,삼의원(잇다카페)'!M60+푸른솔!M60+의과대학!M60+중앙도서관!M60+학생회관!M60+멀티미디어관!M60+제2기숙사!M60+선승관!M60+예술디자인대!M60+공학관!M60 -> 0 | U60: =P60+Q60+R60+S60+T60 -> 9 | V60: =E60*U60 -> 171000 | W60: =(H60+N60)-U60 -> 11 | X60: =E60*W60 -> 209000 | Z60: 0 | AA60: =Z60*E60 -> 0 | AB60: =SUM(AA60) -> 0 | AC60: =AB60*1.1 -> 0
...

Sheet 교육용,R&D,삼의원(잇다카페)
A1: 카페 쿠피 12월 발주 관리 대장 (교육용,R&D,삼의원(잇다카페))
A4: 협력사 | B4: 품목명 | C4: 규격 | D4: 단위 | E4: 입고단가 | F4: 입고단위 | G4: 입고단위단가 | H4: 전월 재고 | I4: 1주차 발주 | J4: 2주차 발주 | K4: 3주차 발주 | L4: 4주차 발주 | M4: 5주차 발주 | N4: 월 발주량 | O4: 월 발주 금액
A5: 비스토리코리아 | B5: 종이컵(-12oz) | C5: 1box=1000ea | D5: ea | E5: 37 | F5: 1000 | G5: 37000 | N5: =I5+J5+K5+L5+M5 -> 0 | O5: =E5*N5 -> 0
B6: 종이컵-16oz | C6: 1box=1000ea | D6: ea | E6: 43 | F6: 1000 | G6: 43000 | N6: =I6+J6+K6+L6+M6 -> 0 | O6: =E6*N6 -> 0
B7: 종이컵뚜껑 (12,16oz) | C7: 1box=1000ea | D7: ea | E7: 20 | F7: 1000 | G7: 20000 | N7: =I7+J7+K7+L7+M7 -> 0 | O7: =E7*N7 -> 0
B8: 아이스(페트)컵(14oz) | C8: 1box=1000ea | D8: ea | E8: 42 | F8: 1000 | G8: 42000 | N8: =I8+J8+K8+L8+M8 -> 0 | O8: =E8*N8 -> 0
B9: 아이스컵(16oz) | C9: 1box=1000ea | D9: ea | E9: 53 | F9: 1000 | G9: 53000 | N9: =I9+J9+K9+L9+M9 -> 0 | O9: =E9*N9 -> 0
B10: 아이스컵(24oz) | C10: 1box=1000ea | D10: ea | E10: 65 | F10: 1000 | G10: 65000 | N10: =I10+J10+K10+L10+M10 -> 0 | O10: =E10*N10 -> 0
B11: 아이스컵 돔뚜껑(93Ø) | C11: 1box=1000ea | D11: ea | E11: 18.5 | F11: 1000 | G11: 18500 | N11: =I11+J11+K11+L11+M11 -> 0 | O11: =E11*N11 -> 0
B12: 아이스컵 돔뚜껑(98Ø) | C12: 1box=1000ea | D12: ea | E12: 20 | F12: 1000 | G12: 20000 | N12: =I12+J12+K12+L12+M12 -> 0 | O12: =E12*N12 -> 0
B13: 아이스컵 평뚜껑(98Ø) | C13: 1box=1000ea | D13: ea | E13: 19 | F13: 1000 | G13: 19000 | N13: =I13+J13+K13+L13+M13 -> 0 | O13: =E13*N13 -> 0
B14: 10/13홀더 (1도인쇄) | C14: 1box=1000ea | D14: ea | E14: 17.5 | F14: 1000 | G14: 17500 | N14: =I14+J14+K14+L14+M14 -> 0 | O14: =E14*N14 -> 0
B15: 12/16홀더(1도인쇄) | C15: 1box=1000ea | D15: ea | E15: 18 | F15: 1000 | G15: 18000 | N15: =I15+J15+K15+L15+M15 -> 0 | O15: =E15*N15 -> 0
B16: 21cm 일자 스트로우 (투명) | C16: 1box=10000ea | D16: ea | E16: 6.9 | F16: 10000 | G16: 69000 | N16: =I16+J16+K16+L16+M16 -> 0 | O16: =E16*N16 -> 0
B17: 21cm 버블티 스트로우 | C17: 1box=3200ea | D17: ea | E17: 22.1875 | F17: 3200 | G17: 71000 | N17: =I17+J17+K17+L17+M17 -> 0 | O17: =E17*N17 -> 0
... B36: 메티에 헤이즐럿시럽(700ml) | C36: 1box=8ea | D36: ea | E36: 6870 | F36: 8 | G36: 54960 | N36: =I36+J36+K36+L36+M36 -> 0 | O36: =E36*N36 -> 0
A37: 성원애드피아 | B37: 적립쿠폰 | C37: 1bundle=500ea | D37: ea | E37: 6.4 | F37: 500 | G37: 3200 | N37: =I37+J37+K37+L37+M37 -> 0 | O37: =E37*N37 -> 0
B38: 유통기한 스티커 | C38: 1bundle=1000ea | D38: ea | E38: 4.69 | F38: 1000 | G38: 4690 | N38: =I38+J38+K38+L38+M38 -> 0 | O38: =E38*N38 -> 0
A39: 휴럼 | B39: 민트초코파우더 | C39: 1box = 12ea | D39: ea | E39: 7700 | F39: 12 | G39: 92400 | N39: =I39+J39+K39+L39+M39 -> 0 | O39: =E39*N39 -> 0
B40: 다크초코파우더 | C40: 1box = 12ea | D40: ea | E40: 6200 | F40: 12 | G40: 74400 | N40: =I40+J40+K40+L40+M40 -> 0 | O40: =E40*N40 -> 0
B41: 청귤베이스 | C41: 1box = 12ea | D41: ea | E41: 6700 | F41: 12 | G41: 80400 | N41: =I41+J41+K41+L41+M41 -> 0 | O41: =E41*N41 -> 0
B42: 요거에스플레인 | C42: 1box=12ea | D42: ea | E42: 7250 | F42: 12 | G42: 87000 | N42: =I42+J42+K42+L42+M42 -> 0 | O42: =E42*N42 -> 0
B43: 흑당베이스 | C43: 1kg x 12ea | D43: ea | E43: 5300 | F43: 12 | G43: 63600 | N43: =I43+J43+K43+L43+M43 -> 0 | O43: =E43*N43 -> 0
B44: 쿠키앤크림 파우더 | C44: 1kg x 12ea | D44: ea | E44: 6600 | F44: 12 | G44: 79200 | N44: =I44+J44+K44+L44+M44 -> 0 | O44: =E44*N44 -> 0
B45: 자몽 베이스 | C45: 1.8kg x 6ea | D45: ea | E45: 14500 | F45: 6 | G45: 87000 | N45: =I45+J45+K45+L45+M45 -> 0 | O45: =E45*N45 -> 0
B46: 수박 베이스 | C46: 1.8kg x 6ea | D46: ea | E46: 11000 | F46: 6 | G46: 66000 | N46: =I46+J46+K46+L46+M46 -> 0 | O46: =E46*N46 -> 0
B47: 17곡 파우더 | C47: 1kg x 12ea | D47: ea | E47: 4500 | F47: 12 | G47: 54000 | N47: =I47+J47+K47+L47+M47 -> 0 | O47: =E47*N47 -> 0
B48: 토피넛파우더 | C48: 1box=12ea | D48: ea | E48: 6700 | F48: 12 | G48: 80400 | N48: =I48+J48+K48+L48+M48 -> 0 | O48: =E48*N48 -> 0
A49: 세미기업 | B49: 딸기스무디 원액 | C49: 1.8kg x 6ea | D49: ea | E49: 6900 | F49: 6 | G49: 41400 | N49: =I49+J49+K49+L49+M49 -> 0 | O49: =E49*N49 -> 0
B50: 망고스무디 원액 | C50: 1.8kg x 6ea | D50: ea | E50: 6900 | F50: 6 | G50: 41400 | N50: =I50+J50+K50+L50+M50 -> 0 | O50: =E50*N50 -> 0
B51: 베리믹스스무디 원액 | C51: 1.8kg x 6ea | D51: ea | E51: 6800 | F51: 6 | G51: 40800 | N51: =I51+J51+K51+L51+M51 -> 0 | O51: =E51*N51 -> 0
B52: 베버시티 레몬에이드 | C52: 1kg x 4ea | D52: ea | E52: 15000 | F52: 4 | G52: 60000 | N52: =I52+J52+K52+L52+M52 -> 0 | O52: =E52*N52 -> 0
B53: 녹차라떼 | C53: 500g x 6ea | D53: ea | E53: 5300 | F53: 6 | G53: 31800 | N53: =I53+J53+K53+L53+M53 -> 0 | O53: =E53*N53 -> 0
B54: 홍차라떼 | C54: 500g x 6ea | D54: ea | E54: 6600 | F54: 6 | G54: 39600 | N54: =I54+J54+K54+L54+M54 -> 0 | O54: =E54*N54 -> 0
B55: 고구마페이스트 | C55: 1kg x 10ea | D55: ea | E55: 5600 | F55: 10 | G55: 56000 | N55: =I55+J55+K55+L55+M55 -> 0 | O55: =E55*N55 -> 0
B56: 토라니 초코소스 | C56: 1.89L x 4ea | D56: ea | E56: 14100 | F56: 4 | G56: 56400 | N56: =I56+J56+K56+L56+M56 -> 0 | O56: =E56*N56 -> 0
B57: 토라니 카라멜소스 | C57: 1.89L x 4ea | D57: ea | E57: 15100 | F57: 4 | G57: 60400 | N57: =I57+J57+K57+L57+M57 -> 0 | O57: =E57*N57 -> 0
B58: 베버시티 청포도에이드 | C58: 1kg x 4ea | D58: ea | E58: 15300 | F58: 4 | G58: 61200 | N58: =I58+J58+K58+L58+M58 -> 0 | O58: =E58*N58 -> 0
A59: 손맛커피 | B59: 신규 원두 | C59: 1box=10kg | D59: ea | E59: 11000 | F59: 10 | G59: 110000 | N59: =I59+J59+K59+L59+M59 -> 0 | O59: =E59*N59 -> 0
B60: 디카페인 원두 | C60: 1box=10kg | D60: ea | E60: 19000 | F60: 10 | G60: 190000 | N60: =I60+J60+K60+L60+M60 -> 0 | O60: =E60*N60 -> 0
...

Sheet 푸른솔
A1: 카페 쿠피 12월 발주 관리 대장 (푸른솔)
A4: 협력사 | B4: 품목명 | C4: 규격 | D4: 단위 | E4: 입고단가 | F4: 입고단위 | G4: 입고단위단가 | H4: 전월 재고 | I4: 1주차 발주 | J4: 2주차 발주 | K4: 3주차 발주 | L4: 4주차 발주 | M4: 5주차 발주 | N4: 월 발주량 | O4: 월 발주 금액
A5: 비스토리코리아 | B5: 종이컵(-12oz) | C5: 1box=1000ea | D5: ea | E5: 37 | F5: 1000 | G5: 37000 | N5: =I5+J5+K5+L5+M5 -> 0 | O5: =E5*N5 -> 0
B6: 종이컵-16oz | C6: 1box=1000ea | D6: ea | E6: 43 | F6: 1000 | G6: 43000 | H6: =26*50 -> 1300 | I6: 1000 | N6: =I6+J6+K6+L6+M6 -> 1000 | O6: =E6*N6 -> 43000
B7: 종이컵뚜껑 (12,16oz) | C7: 1box=1000ea | D7: ea | E7: 20 | F7: 1000 | G7: 20000 | H7: =50*26 -> 1300 | I7: 1000 | N7: =I7+J7+K7+L7+M7 -> 1000 | O7: =E7*N7 -> 20000
B8: 아이스(페트)컵(14oz) | C8: 1box=1000ea | D8: ea | E8: 42 | F8: 1000 | G8: 42000 | N8: =I8+J8+K8+L8+M8 -> 0 | O8: =E8*N8 -> 0
B9: 아이스컵(16oz) | C9: 1box=1000ea | D9: ea | E9: 53 | F9: 1000 | G9: 53000 | I9: 1000 | N9: =I9+J9+K9+L9+M9 -> 1000 | O9: =E9*N9 -> 53000
B10: 아이스컵(24oz) | C10: 1box=1000ea | D10: ea | E10: 65 | F10: 1000 | G10: 65000 | N10: =I10+J10+K10+L10+M10 -> 0 | O10: =E10*N10 -> 0
B11: 아이스컵 돔뚜껑(93Ø) | C11: 1box=1000ea | D11: ea | E11: 18.5 | F11: 1000 | G11: 18500 | I11: 1000 | N11: =I11+J11+K11+L11+M11 -> 1000 | O11: =E11*N11 -> 18500
B12: 아이스컵 돔뚜껑(98Ø) | C12: 1box=1000ea | D12: ea | E12: 20 | F12: 1000 | G12: 20000 | H12: =50*8 -> 400 | N12: =I12+J12+K12+L12+M12 -> 0 | O12: =E12*N12 -> 0
B13: 아이스컵 평뚜껑(98Ø) | C13: 1box=1000ea | D13: ea | E13: 19 | F13: 1000 | G13: 19000 | N13: =I13+J13+K13+L13+M13 -> 0 | O13: =E13*N13 -> 0
B14: 10/13홀더 | C14: 1box=1000ea | D14: ea | E14: 17.5 | F14: 1000 | G14: 17500 | N14: =I14+J14+K14+L14+M14 -> 0 | O14: =E14*N14 -> 0
B15: 12/16홀더 | C15: 1box=1000ea | D15: ea | E15: 18 | F15: 1000 | G15: 18000 | I15: 1000 | N15: =I15+J15+K15+L15+M15 -> 1000 | O15: =E15*N15 -> 18000
B16: 21cm 일자 스트로우 (투명) | C16: 1box=10000ea | D16: ea | E16: 6.9 | F16: 10000 | G16: 69000 | I16: 500 | N16: =I16+J16+K16+L16+M16 -> 500 | O16: =E16*N16 -> 3450
B17: 21cm 버블티 스트로우 | C17: 1box=3200ea | D17: ea | E17: 22.1875 | F17: 3200 | G17: 71000 | H17: 200 | N17: =I17+J17+K17+L17+M17 -> 0 | O17: =E17*N17 -> 0
B18: 25cm 일자 스트로우 (블랙) | C18: 1box=10000ea | D18: ea | E18: 7.2 | F18: 10000 | G18: 72000 | H18: 500 | N18: =I18+J18+K18+L18+M18 -> 0 | O18: =E18*N18 -> 0
B19: 21cm 종이 스트로우 | C19: 1box=5000ea | D19: ea | E19: 18 | F19: 5000 | G19: 90000 | K19: 250 | N19: =I19+J19+K19+L19+M19 -> 250 | O19: =E19*N19 -> 4500
B20: 21cm 종이 버블 스트로우 | C20: 1box=4000ea | D20: ea | E20: 26.7 | F20: 4000 | G20: 106800 | H20: 200 | N20: =I20+J20+K20+L20+M20 -> 0 | O20: =E20*N20 -> 0
B21: 25cm 버블티 스트로우 | C21: 1box=3200ea | D21: ea | E21: 22.8125 | F21: 3200 | G21: 73000 | H21: 200 | N21: =I21+J21+K21+L21+M21 -> 0 | O21: =E21*N21 -> 0
B22: 캐리어 무지(크라프트지) | C22: 1box=200ea | D22: ea | E22: 112.5 | F22: 200 | G22: 22500 | H22: 200 | N22: =I22+J22+K22+L22+M22 -> 0 | O22: =E22*N22 -> 0
B23: 갈색무지냅킨 | C23: 1box=8000ea | D23: ea | E23: 3.625 | F23: 8000 | G23: 29000 | H23: =400*24 -> 9600 | N23: =I23+J23+K23+L23+M23 -> 0 | O23: =E23*N23 -> 0
B24: 커피머신세정제 | C24: 1ea | D24: kg | E24: 12000 | F24: 1 | G24: 12000 | N24: =I24+J24+K24+L24+M24 -> 0 | O24: =E24*N24 -> 0
B25: 15cm 개별포장커피스틱 | C25: 1box=10000ea | D25: ea | E25: 6.4 | F25: 10000 | G25: 64000 | H25: 2000 | N25: =I25+J25+K25+L25+M25 -> 0 | O25: =E25*N25 -> 0
B26: 18cm 개별포장커피스틱 | C26: 1box=10000ea | D26: ea | E26: 6.8 | F26: 10000 | G26: 68000 | N26: =I26+J26+K26+L26+M26 -> 0 | O26: =E26*N26 -> 0
B27: opp 비닐봉투 18*25 | C27: 1pack=200ea | D27: ea | E27: 25 | F27: 200 | G27: 5000 | N27: =I27+J27+K27+L27+M27 -> 0 | O27: =E27*N27 -> 0
B28: 콤부차오리지날 | C28: 1box=12ea | D28: ea | E28: 2100 | F28: 12 | G28: 25200 | H28: 4 | N28: =I28+J28+K28+L28+M28 -> 0 | O28: =E28*N28 -> 0
B29: 콤부차진저레몬 | C29: 1box=12ea | D29: ea | E29: 2100 | F29: 12 | G29: 25200 | H29: 4 | N29: =I29+J29+K29+L29+M29 -> 0 | O29: =E29*N29 -> 0
B30: 콤부차석류 | C30: 1box=12ea | D30: ea | E30: 2100 | F30: 12 | G30: 25200 | H30: 8 | I30: 18 | N30: =I30+J30+K30+L30+M30 -> 18 | O30: =E30*N30 -> 37800
B31: 슈가시럽 | C31: 1box=6ea | D31: ea | E31: 2800 | F31: 6 | G31: 16800 | H31: 5 | N31: =I31+J31+K31+L31+M31 -> 0 | O31: =E31*N31 -> 0
B32: 삼다수 | C32: 1box=20ea | D32: ea | E32: 410 | F32: 20 | G32: 8200 | N32: =I32+J32+K32+L32+M32 -> 0 | O32: =E32*N32 -> 0
B33: 립톤 복숭아파우더(907g) | C33: 1box=12ea | D33: ea | E33: 7200 | F33: 12 | G33: 86400 | H33: 13 | N33: =I33+J33+K33+L33+M33 -> 0 | O33: =E33*N33 -> 0
B34: 초정탄산수(1.5L) | C34: 1box=12ea | D34: ea | E34: 1350 | F34: 12 | G34: 16200 | I34: 3 | J34: 3 | K34: 2 | N34: =I34+J34+K34+L34+M34 -> 8 | O34: =E34*N34 -> 10800
B35: 메티에 바닐라시럽(700ml) | C35: 1box=8ea | D35: ea | E35: 6870 | F35: 8 | G35: 54960 | H35: 1 | J35: 2 | K35: 3 | N35: =I35+J35+K35+L35+M35 -> 5 | O35: =E35*N35 -> 34350
B36: 메티에 헤이즐럿시럽(700ml) | C36: 1box=8ea | D36: ea | E36: 6870 | F36: 8 | G36: 54960 | H36: 1 | I36: 1 | J36: 2 | N36: =I36+J36+K36+L36+M36 -> 3 | O36: =E36*N36 -> 20610
A37: 성원애드피아 | B37: 적립쿠폰 | C37: 1bundle=500ea | D37: ea | E37: 6.4 | F37: 500 | G37: 3200 | N37: =I37+J37+K37+L37+M37 -> 0 | O37: =E37*N37 -> 0
B38: 유통기한 스티커 | C38: 1bundle=1000ea | D38: ea | E38: 4.69 | F38: 1000 | G38: 4690 | N38: =I38+J38+K38+L38+M38 -> 0 | O38: =E38*N38 -> 0
A39: 휴럼 | B39: 민트초코파우더 | C39: 1box = 12ea | D39: ea | E39: 7700 | F39: 12 | G39: 92400 | H39: 2 | N39: =I39+J39+K39+L39+M39 -> 0 | O39: =E39*N39 -> 0
B40: 다크초코파우더 | C40: 1box = 12ea | D40: ea | E40: 6200 | F40: 12 | G40: 74400 | H40: 4 | K40: 1 | N40: =I40+J40+K40+L40+M40 -> 1 | O40: =E40*N40 -> 6200
B41: 청귤베이스 | C41: 1box = 12ea | D41: ea | E41: 6700 | F41: 12 | G41: 80400 | H41: 4 | I41: 2 | J41: 2 | K41: 1 | N41: =I41+J41+K41+L41+M41 -> 5 | O41: =E41*N41 -> 33500
B42: 요거에스플레인 | C42: 1box=12ea | D42: ea | E42: 7250 | F42: 12 | G42: 87000 | H42: 6 | N42: =I42+J42+K42+L42+M42 -> 0 | O42: =E42*N42 -> 0
...

Sheet 의과대학
A1: 카페 쿠피 12월 발주 관리 대장 (의과대학)
A4: 협력사 | B4: 품목명 | C4: 규격 | D4: 단위 | E4: 입고단가 | F4: 입고단위 | G4: 입고단위단가 | H4: 전월 재고 | I4: 1주차 발주 | J4: 2주차 발주 | K4: 3주차 발주 | L4: 4주차 발주 | M4: 5주차 발주 | N4: 월 발주량 | O4: 월 발주 금액
A5: 비스토리코리아 | B5: 종이컵(-12oz) | C5: 1box=1000ea | D5: ea | E5: 37 | F5: 1000 | G5: 37000 | H5: =50*6 -> 300 | N5: =I5+J5+K5+L5+M5 -> 0 | O5: =E5*N5 -> 0
B6: 종이컵-16oz | C6: 1box=1000ea | D6: ea | E6: 43 | F6: 1000 | G6: 43000 | H6: =50*11 -> 550 | N6: =I6+J6+K6+L6+M6 -> 0 | O6: =E6*N6 -> 0
B7: 종이컵뚜껑 (12,16oz) | C7: 1box=1000ea | D7: ea | E7: 20 | F7: 1000 | G7: 20000 | H7: =50*6 -> 300 | I7: 1000 | N7: =I7+J7+K7+L7+M7 -> 1000 | O7: =E7*N7 -> 20000
B8: 아이스(페트)컵(14oz) | C8: 1box=1000ea | D8: ea | E8: 42 | F8: 1000 | G8: 42000 | N8: =I8+J8+K8+L8+M8 -> 0 | O8: =E8*N8 -> 0
B9: 아이스컵(16oz) | C9: 1box=1000ea | D9: ea | E9: 53 | F9: 1000 | G9: 53000 | H9: =50*2 -> 100 | I9: 1000 | N9: =I9+J9+K9+L9+M9 -> 1000 | O9: =E9*N9 -> 53000
B10: 아이스컵(24oz) | C10: 1box=1000ea | D10: ea | E10: 65 | F10: 1000 | G10: 65000 | H10: =50*11 -> 550 | N10: =I10+J10+K10+L10+M10 -> 0 | O10: =E10*N10 -> 0
B11: 아이스컵 돔뚜껑(93Ø) | C11: 1box=1000ea | D11: ea | E11: 18.5 | F11: 1000 | G11: 18500 | H11: =50*14 -> 700 | N11: =I11+J11+K11+L11+M11 -> 0 | O11: =E11*N11 -> 0
B12: 아이스컵 돔뚜껑(98Ø) | C12: 1box=1000ea | D12: ea | E12: 20 | F12: 1000 | G12: 20000 | H12: =50*13 -> 650 | N12: =I12+J12+K12+L12+M12 -> 0 | O12: =E12*N12 -> 0
B13: 아이스컵 평뚜껑(98Ø) | C13: 1box=1000ea | D13: ea | E13: 19 | F13: 1000 | G13: 19000 | N13: =I13+J13+K13+L13+M13 -> 0 | O13: =E13*N13 -> 0
B14: 10/13홀더 | C14: 1box=1000ea | D14: ea | E14: 17.5 | F14: 1000 | G14: 17500 | N14: =I14+J14+K14+L14+M14 -> 0 | O14: =E14*N14 -> 0
B15: 12/16홀더 | C15: 1box=1000ea | D15: ea | E15: 18 | F15: 1000 | G15: 18000 | N15: =I15+J15+K15+L15+M15 -> 0 | O15: =E15*N15 -> 0
B16: 21cm 일자 스트로우 (투명) | C16: 1box=10000ea | D16: ea | E16: 6.9 | F16: 10000 | G16: 69000 | I16: 500 | K16: 500 | N16: =I16+J16+K16+L16+M16 -> 1000 | O16: =E16*N16 -> 6900
B17: 21cm 버블티 스트로우 | C17: 1box=3200ea | D17: ea | E17: 22.1875 | F17: 3200 | G17: 71000 | H17: 200 | N17: =I17+J17+K17+L17+M17 -> 0 | O17: =E17*N17 -> 0
B18: 25cm 일자 스트로우 (블랙) | C18: 1box=10000ea | D18: ea | E18: 7.2 | F18: 10000 | G18: 72000 | K18: 500 | N18: =I18+J18+K18+L18+M18 -> 500 | O18: =E18*N18 -> 3600
B19: 21cm 종이 스트로우 | C19: 1box=5000ea | D19: ea | E19: 18 | F19: 5000 | G19: 90000 | N19: =I19+J19+K19+L19+M19 -> 0 | O19: =E19*N19 -> 0
B20: 21cm 종이 버블 스트로우 | C20: 1box=4000ea | D20: ea | E20: 26.7 | F20: 4000 | G20: 106800 | N20: =I20+J20+K20+L20+M20 -> 0 | O20: =E20*N20 -> 0
B21: 25cm 버블티 스트로우 | C21: 1box=3200ea | D21: ea | E21: 22.8125 | F21: 3200 | G21: 73000 | H21: 200 | N21: =I21+J21+K21+L21+M21 -> 0 | O21: =E21*N21 -> 0
B22: 캐리어 무지(크라프트지) | C22: 1box=200ea | D22: ea | E22: 112.5 | F22: 200 | G22: 22500 | H22: =25*8 -> 200 | N22: =I22+J22+K22+L22+M22 -> 0 | O22: =E22*N22 -> 0
B23: 갈색무지냅킨 | C23: 1box=8000ea | D23: ea | E23: 3.625 | F23: 8000 | G23: 29000 | H23: 400 | N23: =I23+J23+K23+L23+M23 -> 0 | O23: =E23*N23 -> 0
B24: 커피머신세정제 | C24: 1ea | D24: kg | E24: 12000 | F24: 1 | G24: 12000 | N24: =I24+J24+K24+L24+M24 -> 0 | O24: =E24*N24 -> 0
B25: 15cm 개별포장커피스틱 | C25: 1box=10000ea | D25: ea | E25: 6.4 | F25: 10000 | G25: 64000 | H25: 3000 | N25: =I25+J25+K25+L25+M25 -> 0 | O25: =E25*N25 -> 0
B26: 18cm 개별포장커피스틱 | C26: 1box=10000ea | D26: ea | E26: 6.8 | F26: 10000 | G26: 68000 | N26: =I26+J26+K26+L26+M26 -> 0 | O26: =E26*N26 -> 0
B27: opp 비닐봉투 18*25 | C27: 1pack=200ea | D27: ea | E27: 25 | F27: 200 | G27: 5000 | N27: =I27+J27+K27+L27+M27 -> 0 | O27: =E27*N27 -> 0
B28: 콤부차오리지날 | C28: 1box=12ea | D28: ea | E28: 2100 | F28: 12 | G28: 25200 | N28: =I28+J28+K28+L28+M28 -> 0 | O28: =E28*N28 -> 0
B29: 콤부차진저레몬 | C29: 1box=12ea | D29: ea | E29: 2100 | F29: 12 | G29: 25200 | N29: =I29+J29+K29+L29+M29 -> 0 | O29: =E29*N29 -> 0
B30: 콤부차석류 | C30: 1box=12ea | D30: ea | E30: 2100 | F30: 12 | G30: 25200 | N30: =I30+J30+K30+L30+M30 -> 0 | O30: =E30*N30 -> 0
B31: 슈가시럽 | C31: 1box=6ea | D31: ea | E31: 2800 | F31: 6 | G31: 16800 | H31: 1 | N31: =I31+J31+K31+L31+M31 -> 0 | O31: =E31*N31 -> 0
B32: 삼다수 | C32: 1box=20ea | D32: ea | E32: 410 | F32: 20 | G32: 8200 | H32: 2 | N32: =I32+J32+K32+L32+M32 -> 0 | O32: =E32*N32 -> 0
B33: 립톤 복숭아파우더(907g) | C33: 1box=12ea | D33: ea | E33: 7200 | F33: 12 | G33: 86400 | H33: 2 | N33: =I33+J33+K33+L33+M33 -> 0 | O33: =E33*N33 -> 0
B34: 초정탄산수(1.5L) | C34: 1box=12ea | D34: ea | E34: 1350 | F34: 12 | G34: 16200 | H34: 3 | I34: 2 | N34: =I34+J34+K34+L34+M34 -> 2 | O34: =E34*N34 -> 2700
B35: 메티에 바닐라시럽(700ml) | C35: 1box=8ea | D35: ea | E35: 6870 | F35: 8 | G35: 54960 | I35: 1 | N35: =I35+J35+K35+L35+M35 -> 1 | O35: =E35*N35 -> 6870
B36: 메티에 헤이즐럿시럽(700ml) | C36: 1box=8ea | D36: ea | E36: 6870 | F36: 8 | G36: 54960 | H36: 2 | N36: =I36+J36+K36+L36+M36 -> 0 | O36: =E36*N36 -> 0
A37: 성원애드피아 | B37: 적립쿠폰 | C37: 1bundle=500ea | D37: ea | E37: 6.4 | F37: 500 | G37: 3200 | N37: =I37+J37+K37+L37+M37 -> 0 | O37: =E37*N37 -> 0
B38: 유통기한 스티커 | C38: 1bundle=1000ea | D38: ea | E38: 4.69 | F38: 1000 | G38: 4690 | N38: =I38+J38+K38+L38+M38 -> 0 | O38: =E38*N38 -> 0
A39: 휴럼 | B39: 민트초코파우더 | C39: 1box = 12ea | D39: ea | E39: 7700 | F39: 12 | G39: 92400 | H39: 1 | N39: =I39+J39+K39+L39+M39 -> 0 | O39: =E39*N39 -> 0
B40: 다크초코파우더 | C40: 1box = 12ea | D40: ea | E40: 6200 | F40: 12 | G40: 74400 | H40: 1 | K40: 1 | N40: =I40+J40+K40+L40+M40 -> 1 | O40: =E40*N40 -> 6200
B41: 청귤베이스 | C41: 1box = 12ea | D41: ea | E41: 6700 | F41: 12 | G41: 80400 | H41: 1 | K41: 1 | N41: =I41+J41+K41+L41+M41 -> 1 | O41: =E41*N41 -> 6700
B42: 요거에스플레인 | C42: 1box=12ea | D42: ea | E42: 7250 | F42: 12 | G42: 87000 | H42: 1 | N42: =I42+J42+K42+L42+M42 -> 0 | O42: =E42*N42 -> 0
...

Sheet 중앙도서관
A1: 카페 쿠피 12월 발주 관리 대장 (중앙도서관)
A4: 협력사 | B4: 품목명 | C4: 규격 | D4: 단위 | E4: 입고단가 | F4: 입고단위 | G4: 입고단위단가 | H4: 전월 재고 | I4: 1주차 발주 | J4: 2주차 발주 | K4: 3주차 발주 | L4: 4주차 발주 | M4: 5주차 발주 | N4: 월 발주량 | O4: 월 발주 금액
A5: 비스토리코리아 | B5: 종이컵(-12oz) | C5: 1box=1000ea | D5: ea | E5: 37 | F5: 1000 | G5: 37000 | N5: =I5+J5+K5+L5+M5 -> 0 | O5: =E5*N5 -> 0
B6: 종이컵-16oz | C6: 1box=1000ea | D6: ea | E6: 43 | F6: 1000 | G6: 43000 | H6: 350 | J6: 1000 | N6: =I6+J6+K6+L6+M6 -> 1000 | O6: =E6*N6 -> 43000
B7: 종이컵뚜껑 (12,16oz) | C7: 1box=1000ea | D7: ea | E7: 20 | F7: 1000 | G7: 20000 | H7: 1000 | N7: =I7+J7+K7+L7+M7 -> 0 | O7: =E7*N7 -> 0
B8: 아이스(페트)컵(14oz) | C8: 1box=1000ea | D8: ea | E8: 42 | F8: 1000 | G8: 42000 | N8: =I8+J8+K8+L8+M8 -> 0 | O8: =E8*N8 -> 0
B9: 아이스컵(16oz) | C9: 1box=1000ea | D9: ea | E9: 53 | F9: 1000 | G9: 53000 | H9: 1200 | N9: =I9+J9+K9+L9+M9 -> 0 | O9: =E9*N9 -> 0
B10: 아이스컵(24oz) | C10: 1box=1000ea | D10: ea | E10: 65 | F10: 1000 | G10: 65000 | H10: 850 | N10: =I10+J10+K10+L10+M10 -> 0 | O10: =E10*N10 -> 0
B11: 아이스컵 돔뚜껑(93Ø) | C11: 1box=1000ea | D11: ea | E11: 18.5 | F11: 1000 | G11: 18500 | H11: 950 | K11: 1000 | N11: =I11+J11+K11+L11+M11 -> 1000 | O11: =E11*N11 -> 18500
B12: 아이스컵 돔뚜껑(98Ø) | C12: 1box=1000ea | D12: ea | E12: 20 | F12: 1000 | G12: 20000 | H12: 450 | N12: =I12+J12+K12+L12+M12 -> 0 | O12: =E12*N12 -> 0
B13: 아이스컵 평뚜껑(98Ø) | C13: 1box=1000ea | D13: ea | E13: 19 | F13: 1000 | G13: 19000 | H13: 250 | N13: =I13+J13+K13+L13+M13 -> 0 | O13: =E13*N13 -> 0
B14: 10/13홀더 | C14: 1box=1000ea | D14: ea | E14: 17.5 | F14: 1000 | G14: 17500 | N14: =I14+J14+K14+L14+M14 -> 0 | O14: =E14*N14 -> 0
B15: 12/16홀더 | C15: 1box=1000ea | D15: ea | E15: 18 | F15: 1000 | G15: 18000 | I15: 1000 | K15: 1000 | N15: =I15+J15+K15+L15+M15 -> 2000 | O15: =E15*N15 -> 36000
B16: 21cm 일자 스트로우 (투명) | C16: 1box=10000ea | D16: ea | E16: 6.9 | F16: 10000 | G16: 69000 | H16: 500 | J16: 500 | N16: =I16+J16+K16+L16+M16 -> 500 | O16: =E16*N16 -> 3450
B17: 21cm 버블티 스트로우 | C17: 1box=3200ea | D17: ea | E17: 22.1875 | F17: 3200 | G17: 71000 | N17: =I17+J17+K17+L17+M17 -> 0 | O17: =E17*N17 -> 0
B18: 25cm 일자 스트로우 (블랙) | C18: 1box=10000ea | D18: ea | E18: 7.2 | F18: 10000 | G18: 72000 | H18: 1000 | N18: =I18+J18+K18+L18+M18 -> 0 | O18: =E18*N18 -> 0
B19: 21cm 종이 스트로우 | C19: 1box=5000ea | D19: ea | E19: 18 | F19: 5000 | G19: 90000 | J19: 250 | N19: =I19+J19+K19+L19+M19 -> 250 | O19: =E19*N19 -> 4500
B20: 21cm 종이 버블 스트로우 | C20: 1box=4000ea | D20: ea | E20: 26.7 | F20: 4000 | G20: 106800 | N20: =I20+J20+K20+L20+M20 -> 0 | O20: =E20*N20 -> 0
B21: 25cm 버블티 스트로우 | C21: 1box=3200ea | D21: ea | E21: 22.8125 | F21: 3200 | G21: 73000 | N21: =I21+J21+K21+L21+M21 -> 0 | O21: =E21*N21 -> 0
B22: 캐리어 무지(크라프트지) | C22: 1box=200ea | D22: ea | E22: 112.5 | F22: 200 | G22: 22500 | H22: 100 | N22: =I22+J22+K22+L22+M22 -> 0 | O22: =E22*N22 -> 0
B23: 갈색무지냅킨 | C23: 1box=8000ea | D23: ea | E23: 3.625 | F23: 8000 | G23: 29000 | H23: 6800 | N23: =I23+J23+K23+L23+M23 -> 0 | O23: =E23*N23 -> 0
B24: 커피머신세정제 | C24: 1ea | D24: kg | E24: 12000 | F24: 1 | G24: 12000 | N24: =I24+J24+K24+L24+M24 -> 0 | O24: =E24*N24 -> 0
B25: 15cm 개별포장커피스틱 | C25: 1box=10000ea | D25: ea | E25: 6.4 | F25: 10000 | G25: 64000 | N25: =I25+J25+K25+L25+M25 -> 0 | O25: =E25*N25 -> 0
B26: 18cm 개별포장커피스틱 | C26: 1box=10000ea | D26: ea | E26: 6.8 | F26: 10000 | G26: 68000 | H26: 7000 | N26: =I26+J26+K26+L26+M26 -> 0 | O26: =E26*N26 -> 0
B27: opp 비닐봉투 18*25 | C27: 1pack=200ea | D27: ea | E27: 25 | F27: 200 | G27: 5000 | N27: =I27+J27+K27+L27+M27 -> 0 | O27: =E27*N27 -> 0
B28: 콤부차오리지날 | C28: 1box=12ea | D28: ea | E28: 2100 | F28: 12 | G28: 25200 | H28: 6 | N28: =I28+J28+K28+L28+M28 -> 0 | O28: =E28*N28 -> 0
B29: 콤부차진저레몬 | C29: 1box=12ea | D29: ea | E29: 2100 | F29: 12 | G29: 25200 | H29: 4 | J29: 4 | N29: =I29+J29+K29+L29+M29 -> 4 | O29: =E29*N29 -> 8400
B30: 콤부차석류 | C30: 1box=12ea | D30: ea | E30: 2100 | F30: 12 | G30: 25200 | N30: =I30+J30+K30+L30+M30 -> 0 | O30: =E30*N30 -> 0
B31: 슈가시럽 | C31: 1box=6ea | D31: ea | E31: 2800 | F31: 6 | G31: 16800 | H31: 1 | K31: 2 | N31: =I31+J31+K31+L31+M31 -> 2 | O31: =E31*N31 -> 5600
B32: 삼다수 | C32: 1box=20ea | D32: ea | E32: 410 | F32: 20 | G32: 8200 | H32: 16 | N32: =I32+J32+K32+L32+M32 -> 0 | O32: =E32*N32 -> 0
B33: 립톤 복숭아파우더(907g) | C33: 1box=12ea | D33: ea | E33: 7200 | F33: 12 | G33: 86400 | H33: 6 | J33: 4 | K33: 4 | N33: =I33+J33+K33+L33+M33 -> 8 | O33: =E33*N33 -> 57600
B34: 초정탄산수(1.5L) | C34: 1box=12ea | D34: ea | E34: 1350 | F34: 12 | G34: 16200 | H34: 4 | J34: 2 | N34: =I34+J34+K34+L34+M34 -> 2 | O34: =E34*N34 -> 2700
B35: 메티에 바닐라시럽(700ml) | C35: 1box=8ea | D35: ea | E35: 6870 | F35: 8 | G35: 54960 | H35: 3 | I35: 2 | J35: 2 | K35: 2 | N35: =I35+J35+K35+L35+M35 -> 6 | O35: =E35*N35 -> 41220
B36: 메티에 헤이즐럿시럽(700ml) | C36: 1box=8ea | D36: ea | E36: 6870 | F36: 8 | G36: 54960 | H36: 3 | K36: 1 | N36: =I36+J36+K36+L36+M36 -> 1 | O36: =E36*N36 -> 6870
A37: 성원애드피아 | B37: 적립쿠폰 | C37: 1bundle=500ea | D37: ea | E37: 6.4 | F37: 500 | G37: 3200 | J37: 100 | N37: =I37+J37+K37+L37+M37 -> 100 | O37: =E37*N37 -> 640
B38: 유통기한 스티커 | C38: 1bundle=1000ea | D38: ea | E38: 4.69 | F38: 1000 | G38: 4690 | N38: =I38+J38+K38+L38+M38 -> 0 | O38: =E38*N38 -> 0
A39: 휴럼 | B39: 민트초코파우더 | C39: 1box = 12ea | D39: ea | E39: 7700 | F39: 12 | G39: 92400 | H39: 1 | N39: =I39+J39+K39+L39+M39 -> 0 | O39: =E39*N39 -> 0
B40: 다크초코파우더 | C40: 1box = 12ea | D40: ea | E40: 6200 | F40: 12 | G40: 74400 | H40: 1 | J40: 2 | K40: 1 | N40: =I40+J40+K40+L40+M40 -> 3 | O40: =E40*N40 -> 18600
B41: 청귤베이스 | C41: 1box = 12ea | D41: ea | E41: 6700 | F41: 12 | G41: 80400 | H41: 1 | I41: 1 | J41: 1 | K41: 1 | N41: =I41+J41+K41+L41+M41 -> 3 | O41: =E41*N41 -> 20100
B42: 요거에스플레인 | C42: 1box=12ea | D42: ea | E42: 7250 | F42: 12 | G42: 87000 | H42: 1 | J42: 1 | K42: 1 | N42: =I42+J42+K42+L42+M42 -> 2 | O42: =E42*N42 -> 14500
...

Sheet 학생회관
A1: 카페 쿠피 12월 발주 관리 대장 (학생회관)
A4: 협력사 | B4: 품목명 | C4: 규격 | D4: 단위 | E4: 입고단가 | F4: 입고단위 | G4: 입고단위단가 | H4: 전월 재고 | I4: 1주차 발주 | J4: 2주차 발주 | K4: 3주차 발주 | L4: 4주차 발주 | M4: 5주차 발주 | N4: 월 발주량 | O4: 월 발주 금액
A5: 비스토리코리아 | B5: 종이컵(-12oz) | C5: 1box=1000ea | D5: ea | E5: 37 | F5: 1000 | G5: 37000 | H5: 350 | N5: =I5+J5+K5+L5+M5 -> 0 | O5: =E5*N5 -> 0
B6: 종이컵-16oz | C6: 1box=1000ea | D6: ea | E6: 43 | F6: 1000 | G6: 43000 | H6: 600 | N6: =I6+J6+K6+L6+M6 -> 0 | O6: =E6*N6 -> 0
B7: 종이컵뚜껑 (12,16oz) | C7: 1box=1000ea | D7: ea | E7: 20 | F7: 1000 | G7: 20000 | H7: 400 | I7: 1000 | N7: =I7+J7+K7+L7+M7 -> 1000 | O7: =E7*N7 -> 20000
B8: 아이스(페트)컵(14oz) | C8: 1box=1000ea | D8: ea | E8: 42 | F8: 1000 | G8: 42000 | N8: =I8+J8+K8+L8+M8 -> 0 | O8: =E8*N8 -> 0
B9: 아이스컵(16oz) | C9: 1box=1000ea | D9: ea | E9: 53 | F9: 1000 | G9: 53000 | H9: 600 | K9: 1000 | N9: =I9+J9+K9+L9+M9 -> 1000 | O9: =E9*N9 -> 53000
B10: 아이스컵(24oz) | C10: 1box=1000ea | D10: ea | E10: 65 | F10: 1000 | G10: 65000 | H10: 700 | N10: =I10+J10+K10+L10+M10 -> 0 | O10: =E10*N10 -> 0
B11: 아이스컵 돔뚜껑(93Ø) | C11: 1box=1000ea | D11: ea | E11: 18.5 | F11: 1000 | G11: 18500 | H11: 450 | J11: 1000 | N11: =I11+J11+K11+L11+M11 -> 1000 | O11: =E11*N11 -> 18500
B12: 아이스컵 돔뚜껑(98Ø) | C12: 1box=1000ea | D12: ea | E12: 20 | F12: 1000 | G12: 20000 | H12: 350 | N12: =I12+J12+K12+L12+M12 -> 0 | O12: =E12*N12 -> 0
B13: 아이스컵 평뚜껑(98Ø) | C13: 1box=1000ea | D13: ea | E13: 19 | F13: 1000 | G13: 19000 | N13: =I13+J13+K13+L13+M13 -> 0 | O13: =E13*N13 -> 0
B14: 10/13홀더 | C14: 1box=1000ea | D14: ea | E14: 17.5 | F14: 1000 | G14: 17500 | N14: =I14+J14+K14+L14+M14 -> 0 | O14: =E14*N14 -> 0
B15: 12/16홀더 | C15: 1box=1000ea | D15: ea | E15: 18 | F15: 1000 | G15: 18000 | K15: 1000 | N15: =I15+J15+K15+L15+M15 -> 1000 | O15: =E15*N15 -> 18000
B16: 21cm 일자 스트로우 (투명) | C16: 1box=10000ea | D16: ea | E16: 6.9 | F16: 10000 | G16: 69000 | H16: 500 | J16: 500 | N16: =I16+J16+K16+L16+M16 -> 500 | O16: =E16*N16 -> 3450
B17: 21cm 버블티 스트로우 | C17: 1box=3200ea | D17: ea | E17: 22.1875 | F17: 3200 | G17: 71000 | H17: 200 | N17: =I17+J17+K17+L17+M17 -> 0 | O17: =E17*N17 -> 0
B18: 25cm 일자 스트로우 (블랙) | C18: 1box=10000ea | D18: ea | E18: 7.2 | F18: 10000 | G18: 72000 | N18: =I18+J18+K18+L18+M18 -> 0 | O18: =E18*N18 -> 0
B19: 21cm 종이 스트로우 | C19: 1box=5000ea | D19: ea | E19: 18 | F19: 5000 | G19: 90000 | H19: 250 | N19: =I19+J19+K19+L19+M19 -> 0 | O19: =E19*N19 -> 0
B20: 21cm 종이 버블 스트로우 | C20: 1box=4000ea | D20: ea | E20: 26.7 | F20: 4000 | G20: 106800 | N20: =I20+J20+K20+L20+M20 -> 0 | O20: =E20*N20 -> 0
B21: 25cm 버블티 스트로우 | C21: 1box=3200ea | D21: ea | E21: 22.8125 | F21: 3200 | G21: 73000 | H21: 200 | N21: =I21+J21+K21+L21+M21 -> 0 | O21: =E21*N21 -> 0
