Workbook

Sheet 본사창고
A1: 카페 쿠피 3월 입출고 관리 대장 (본사창고)
A4: 협력사 | B4: 품목명 | C4: 규격 | D4: 단위 | E4: 입고단가 | F4: 입고단위 | G4: 입고단위단가 | H4: 전월 재고 | I4: 1주차 입고 | J4: 2주차 입고 | K4: 3주차 입고 | L4: 4주차 입고 | M4: 5주차 입고 | N4: 월 입고량 | O4: 월 입고 금액 | P4: 1주차 출고량 | Q4: 2주차 출고량 | R4: 3주차 출고량 | S4: 4주차 출고량 | T4: 5주차 출고량 | U4: 월 출고량 | V4: 월 출고 금액 | W4: 현재고 | X4: 현재고 금액 | Y4: 비고 | Z4: 발주량 | AA4: 발주금액 | AB4: 발주합계 (부가세 별도) | AC4: 발주합계 (부가세 포함)
A5: 비스토리코리아 | B5: 종이컵(-12oz) | C5: 1box=1000ea | D5: ea | E5: 37 | F5: 1000 | G5: 37000 | H5: 4000 | K5: 0 | L5: 0 | N5: =I5+J5+K5+L5+M5 -> 0 | O5: =E5*N5 -> 0 | P5: =캠퍼스타운_외부원두영업!I5+잇다카페_외부원두영업!I5+푸른솔!I5+의과대학!I5+중앙도서관!I5+학생회관!I5+멀티미디어관!I5+제2기숙사!I5+선승관!I5+예술디자인대!I5+공학관!I5 -> 0 | Q5: =캠퍼스타운_외부원두영업!J5+잇다카페_외부원두영업!J5+푸른솔!J5+의과대학!J5+중앙도서관!J5+학생회관!J5+멀티미디어관!J5+제2기숙사!J5+선승관!J5+예술디자인대!J5+공학관!J5 -> 0 | R5: =캠퍼스타운_외부원두영업!K5+잇다카페_외부원두영업!K5+푸른솔!K5+의과대학!K5+중앙도서관!K5+학생회관!K5+멀티미디어관!K5+제2기숙사!K5+선승관!K5+예술디자인대!K5+공학관!K5 -> 0 | S5: =캠퍼스타운_외부원두영업!L5+잇다카페_외부원두영업!L5+푸른솔!L5+의과대학!L5+중앙도서관!L5+학생회관!L5+멀티미디어관!L5+제2기숙사!L5+선승관!L5+예술디자인대!L5+공학관!L5 -> 0 | T5: =캠퍼스타운_외부원두영업!M5+잇다카페_외부원두영업!M5+푸른솔!M5+의과대학!M5+중앙도서관!M5+학생회관!M5+멀티미디어관!M5+제2기숙사!M5+선승관!M5+예술디자인대!M5+공학관!M5 -> 0 | U5: =P5+Q5+R5+S5+T5 -> 0 | V5: =E5*U5 -> 0 | W5: =(H5+N5)-U5 -> 4000 | X5: =E5*W5 -> 148000 | Z5: 0 | AA5: =Z5*E5 -> 0 | AB5: =SUM(AA5:AA39) -> 0 | AC5: =AB5*1.1 -> 0
B6: 종이컵-16oz | C6: 1box=1000ea | D6: ea | E6: 43 | F6: 1000 | G6: 43000 | H6: 2000 | K6: 6000 | L6: 0 | N6: =I6+J6+K6+L6+M6 -> 6000 | O6: =E6*N6 -> 258000 | P6: =캠퍼스타운_외부원두영업!I6+잇다카페_외부원두영업!I6+푸른솔!I6+의과대학!I6+중앙도서관!I6+학생회관!I6+멀티미디어관!I6+제2기숙사!I6+선승관!I6+예술디자인대!I6+공학관!I6 -> 0 | Q6: =캠퍼스타운_외부원두영업!J6+잇다카페_외부원두영업!J6+푸른솔!J6+의과대학!J6+중앙도서관!J6+학생회관!J6+멀티미디어관!J6+제2기숙사!J6+선승관!J6+예술디자인대!J6+공학관!J6 -> 1000 | R6: =캠퍼스타운_외부원두영업!K6+잇다카페_외부원두영업!K6+푸른솔!K6+의과대학!K6+중앙도서관!K6+학생회관!K6+멀티미디어관!K6+제2기숙사!K6+선승관!K6+예술디자인대!K6+공학관!K6 -> 1000 | S6: =캠퍼스타운_외부원두영업!L6+잇다카페_외부원두영업!L6+푸른솔!L6+의과대학!L6+중앙도서관!L6+학생회관!L6+멀티미디어관!L6+제2기숙사!L6+선승관!L6+예술디자인대!L6+공학관!L6 -> 2000 | T6: =캠퍼스타운_외부원두영업!M6+잇다카페_외부원두영업!M6+푸른솔!M6+의과대학!M6+중앙도서관!M6+학생회관!M6+멀티미디어관!M6+제2기숙사!M6+선승관!M6+예술디자인대!M6+공학관!M6 -> 0 | U6: =P6+Q6+R6+S6+T6 -> 4000 | V6: =E6*U6 -> 172000 | W6: =(H6+N6)-U6 -> 4000 | X6: =E6*W6 -> 172000 | Z6: 0 | AA6: =Z6*E6 -> 0
B7: 종이컵뚜껑 (12,16oz) | C7: 1box=1000ea | D7: ea | E7: 20 | F7: 1000 | G7: 20000 | H7: 7000 | K7: 0 | L7: 0 | N7: =I7+J7+K7+L7+M7 -> 0 | O7: =E7*N7 -> 0 | P7: =캠퍼스타운_외부원두영업!I7+잇다카페_외부원두영업!I7+푸른솔!I7+의과대학!I7+중앙도서관!I7+학생회관!I7+멀티미디어관!I7+제2기숙사!I7+선승관!I7+예술디자인대!I7+공학관!I7 -> 0 | Q7: =캠퍼스타운_외부원두영업!J7+잇다카페_외부원두영업!J7+푸른솔!J7+의과대학!J7+중앙도서관!J7+학생회관!J7+멀티미디어관!J7+제2기숙사!J7+선승관!J7+예술디자인대!J7+공학관!J7 -> 0 | R7: =캠퍼스타운_외부원두영업!K7+잇다카페_외부원두영업!K7+푸른솔!K7+의과대학!K7+중앙도서관!K7+학생회관!K7+멀티미디어관!K7+제2기숙사!K7+선승관!K7+예술디자인대!K7+공학관!K7 -> 1000 | S7: =캠퍼스타운_외부원두영업!L7+잇다카페_외부원두영업!L7+푸른솔!L7+의과대학!L7+중앙도서관!L7+학생회관!L7+멀티미디어관!L7+제2기숙사!L7+선승관!L7+예술디자인대!L7+공학관!L7 -> 2000 | T7: =캠퍼스타운_외부원두영업!M7+잇다카페_외부원두영업!M7+푸른솔!M7+의과대학!M7+중앙도서관!M7+학생회관!M7+멀티미디어관!M7+제2기숙사!M7+선승관!M7+예술디자인대!M7+공학관!M7 -> 0 | U7: =P7+Q7+R7+S7+T7 -> 3000 | V7: =E7*U7 -> 60000 | W7: =(H7+N7)-U7 -> 4000 | X7: =E7*W7 -> 80000 | Z7: 0 | AA7: =Z7*E7 -> 0
B8: 아이스(페트)컵(14oz) | C8: 1box=1000ea | D8: ea | E8: 42 | F8: 1000 | G8: 42000 | H8: 0 | K8: 0 | L8: 0 | N8: =I8+J8+K8+L8+M8 -> 0 | O8: =E8*N8 -> 0 | P8: =캠퍼스타운_외부원두영업!I8+잇다카페_외부원두영업!I8+푸른솔!I8+의과대학!I8+중앙도서관!I8+학생회관!I8+멀티미디어관!I8+제2기숙사!I8+선승관!I8+예술디자인대!I8+공학관!I8 -> 0 | Q8: =캠퍼스타운_외부원두영업!J8+잇다카페_외부원두영업!J8+푸른솔!J8+의과대학!J8+중앙도서관!J8+학생회관!J8+멀티미디어관!J8+제2기숙사!J8+선승관!J8+예술디자인대!J8+공학관!J8 -> 0 | R8: =캠퍼스타운_외부원두영업!K8+잇다카페_외부원두영업!K8+푸른솔!K8+의과대학!K8+중앙도서관!K8+학생회관!K8+멀티미디어관!K8+제2기숙사!K8+선승관!K8+예술디자인대!K8+공학관!K8 -> 0 | S8: =캠퍼스타운_외부원두영업!L8+잇다카페_외부원두영업!L8+푸른솔!L8+의과대학!L8+중앙도서관!L8+학생회관!L8+멀티미디어관!L8+제2기숙사!L8+선승관!L8+예술디자인대!L8+공학관!L8 -> 0 | T8: =캠퍼스타운_외부원두영업!M8+잇다카페_외부원두영업!M8+푸른솔!M8+의과대학!M8+중앙도서관!M8+학생회관!M8+멀티미디어관!M8+제2기숙사!M8+선승관!M8+예술디자인대!M8+공학관!M8 -> 0 | U8: =P8+Q8+R8+S8+T8 -> 0 | V8: =E8*U8 -> 0 | W8: =(H8+N8)-U8 -> 0 | X8: =E8*W8 -> 0 | Z8: 0 | AA8: =Z8*E8 -> 0
B9: 아이스컵(16oz) | C9: 1box=1000ea | D9: ea | E9: 53 | F9: 1000 | G9: 53000 | H9: 17000 | K9: 5000 | L9: 7000 | N9: =I9+J9+K9+L9+M9 -> 12000 | O9: =E9*N9 -> 636000 | P9: =캠퍼스타운_외부원두영업!I9+잇다카페_외부원두영업!I9+푸른솔!I9+의과대학!I9+중앙도서관!I9+학생회관!I9+멀티미디어관!I9+제2기숙사!I9+선승관!I9+예술디자인대!I9+공학관!I9 -> 1000 | Q9: =캠퍼스타운_외부원두영업!J9+잇다카페_외부원두영업!J9+푸른솔!J9+의과대학!J9+중앙도서관!J9+학생회관!J9+멀티미디어관!J9+제2기숙사!J9+선승관!J9+예술디자인대!J9+공학관!J9 -> 6000 | R9: =캠퍼스타운_외부원두영업!K9+잇다카페_외부원두영업!K9+푸른솔!K9+의과대학!K9+중앙도서관!K9+학생회관!K9+멀티미디어관!K9+제2기숙사!K9+선승관!K9+예술디자인대!K9+공학관!K9 -> 4000 | S9: =캠퍼스타운_외부원두영업!L9+잇다카페_외부원두영업!L9+푸른솔!L9+의과대학!L9+중앙도서관!L9+학생회관!L9+멀티미디어관!L9+제2기숙사!L9+선승관!L9+예술디자인대!L9+공학관!L9 -> 3000 | T9: =캠퍼스타운_외부원두영업!M9+잇다카페_외부원두영업!M9+푸른솔!M9+의과대학!M9+중앙도서관!M9+학생회관!M9+멀티미디어관!M9+제2기숙사!M9+선승관!M9+예술디자인대!M9+공학관!M9 -> 0 | U9: =P9+Q9+R9+S9+T9 -> 14000 | V9: =E9*U9 -> 742000 | W9: =(H9+N9)-U9 -> 15000 | X9: =E9*W9 -> 795000 | Z9: 0 | AA9: =Z9*E9 -> 0
B10: 아이스컵(24oz) | C10: 1box=1000ea | D10: ea | E10: 65 | F10: 1000 | G10: 65000 | H10: 7000 | K10: 0 | L10: 0 | N10: =I10+J10+K10+L10+M10 -> 0 | O10: =E10*N10 -> 0 | P10: =캠퍼스타운_외부원두영업!I10+잇다카페_외부원두영업!I10+푸른솔!I10+의과대학!I10+중앙도서관!I10+학생회관!I10+멀티미디어관!I10+제2기숙사!I10+선승관!I10+예술디자인대!I10+공학관!I10 -> 0 | Q10: =캠퍼스타운_외부원두영업!J10+잇다카페_외부원두영업!J10+푸른솔!J10+의과대학!J10+중앙도서관!J10+학생회관!J10+멀티미디어관!J10+제2기숙사!J10+선승관!J10+예술디자인대!J10+공학관!J10 -> 0 | R10: =캠퍼스타운_외부원두영업!K10+잇다카페_외부원두영업!K10+푸른솔!K10+의과대학!K10+중앙도서관!K10+학생회관!K10+멀티미디어관!K10+제2기숙사!K10+선승관!K10+예술디자인대!K10+공학관!K10 -> 1000 | S10: =캠퍼스타운_외부원두영업!L10+잇다카페_외부원두영업!L10+푸른솔!L10+의과대학!L10+중앙도서관!L10+학생회관!L10+멀티미디어관!L10+제2기숙사!L10+선승관!L10+예술디자인대!L10+공학관!L10 -> 0 | T10: =캠퍼스타운_외부원두영업!M10+잇다카페_외부원두영업!M10+푸른솔!M10+의과대학!M10+중앙도서관!M10+학생회관!M10+멀티미디어관!M10+제2기숙사!M10+선승관!M10+예술디자인대!M10+공학관!M10 -> 0 | U10: =P10+Q10+R10+S10+T10 -> 1000 | V10: =E10*U10 -> 65000 | W10: =(H10+N10)-U10 -> 6000 | X10: =E10*W10 -> 390000 | Z10: 0 | AA10: =Z10*E10 -> 0
B11: 아이스컵 돔뚜껑(93Ø) | C11: 1box=1000ea | D11: ea | E11: 18.5 | F11: 1000 | G11: 18500 | H11: 16000 | K11: 6000 | L11: 8000 | N11: =I11+J11+K11+L11+M11 -> 14000 | O11: =E11*N11 -> 259000 | P11: =캠퍼스타운_외부원두영업!I11+잇다카페_외부원두영업!I11+푸른솔!I11+의과대학!I11+중앙도서관!I11+학생회관!I11+멀티미디어관!I11+제2기숙사!I11+선승관!I11+예술디자인대!I11+공학관!I11 -> 1000 | Q11: =캠퍼스타운_외부원두영업!J11+잇다카페_외부원두영업!J11+푸른솔!J11+의과대학!J11+중앙도서관!J11+학생회관!J11+멀티미디어관!J11+제2기숙사!J11+선승관!J11+예술디자인대!J11+공학관!J11 -> 6000 | R11: =캠퍼스타운_외부원두영업!K11+잇다카페_외부원두영업!K11+푸른솔!K11+의과대학!K11+중앙도서관!K11+학생회관!K11+멀티미디어관!K11+제2기숙사!K11+선승관!K11+예술디자인대!K11+공학관!K11 -> 4000 | S11: =캠퍼스타운_외부원두영업!L11+잇다카페_외부원두영업!L11+푸른솔!L11+의과대학!L11+중앙도서관!L11+학생회관!L11+멀티미디어관!L11+제2기숙사!L11+선승관!L11+예술디자인대!L11+공학관!L11 -> 4000 | T11: =캠퍼스타운_외부원두영업!M11+잇다카페_외부원두영업!M11+푸른솔!M11+의과대학!M11+중앙도서관!M11+학생회관!M11+멀티미디어관!M11+제2기숙사!M11+선승관!M11+예술디자인대!M11+공학관!M11 -> 0 | U11: =P11+Q11+R11+S11+T11 -> 15000 | V11: =E11*U11 -> 277500 | W11: =(H11+N11)-U11 -> 15000 | X11: =E11*W11 -> 277500 | Z11: 0 | AA11: =Z11*E11 -> 0
B12: 아이스컵 돔뚜껑(98Ø) | C12: 1box=1000ea | D12: ea | E12: 20 | F12: 1000 | G12: 20000 | H12: 8000 | K12: 0 | L12: 0 | N12: =I12+J12+K12+L12+M12 -> 0 | O12: =E12*N12 -> 0 | P12: =캠퍼스타운_외부원두영업!I12+잇다카페_외부원두영업!I12+푸른솔!I12+의과대학!I12+중앙도서관!I12+학생회관!I12+멀티미디어관!I12+제2기숙사!I12+선승관!I12+예술디자인대!I12+공학관!I12 -> 0 | Q12: =캠퍼스타운_외부원두영업!J12+잇다카페_외부원두영업!J12+푸른솔!J12+의과대학!J12+중앙도서관!J12+학생회관!J12+멀티미디어관!J12+제2기숙사!J12+선승관!J12+예술디자인대!J12+공학관!J12 -> 0 | R12: =캠퍼스타운_외부원두영업!K12+잇다카페_외부원두영업!K12+푸른솔!K12+의과대학!K12+중앙도서관!K12+학생회관!K12+멀티미디어관!K12+제2기숙사!K12+선승관!K12+예술디자인대!K12+공학관!K12 -> 0 | S12: =캠퍼스타운_외부원두영업!L12+잇다카페_외부원두영업!L12+푸른솔!L12+의과대학!L12+중앙도서관!L12+학생회관!L12+멀티미디어관!L12+제2기숙사!L12+선승관!L12+예술디자인대!L12+공학관!L12 -> 1000 | T12: =캠퍼스타운_외부원두영업!M12+잇다카페_외부원두영업!M12+푸른솔!M12+의과대학!M12+중앙도서관!M12+학생회관!M12+멀티미디어관!M12+제2기숙사!M12+선승관!M12+예술디자인대!M12+공학관!M12 -> 0 | U12: =P12+Q12+R12+S12+T12 -> 1000 | V12: =E12*U12 -> 20000 | W12: =(H12+N12)-U12 -> 7000 | X12: =E12*W12 -> 140000 | Z12: 0 | AA12: =Z12*E12 -> 0
B13: 아이스컵 평뚜껑(98Ø) | C13: 1box=1000ea | D13: ea | E13: 19 | F13: 1000 | G13: 19000 | H13: 0 | K13: 0 | L13: 0 | N13: =I13+J13+K13+L13+M13 -> 0 | O13: =E13*N13 -> 0 | P13: =캠퍼스타운_외부원두영업!I13+잇다카페_외부원두영업!I13+푸른솔!I13+의과대학!I13+중앙도서관!I13+학생회관!I13+멀티미디어관!I13+제2기숙사!I13+선승관!I13+예술디자인대!I13+공학관!I13 -> 0 | Q13: =캠퍼스타운_외부원두영업!J13+잇다카페_외부원두영업!J13+푸른솔!J13+의과대학!J13+중앙도서관!J13+학생회관!J13+멀티미디어관!J13+제2기숙사!J13+선승관!J13+예술디자인대!J13+공학관!J13 -> 0 | R13: =캠퍼스타운_외부원두영업!K13+잇다카페_외부원두영업!K13+푸른솔!K13+의과대학!K13+중앙도서관!K13+학생회관!K13+멀티미디어관!K13+제2기숙사!K13+선승관!K13+예술디자인대!K13+공학관!K13 -> 0 | S13: =캠퍼스타운_외부원두영업!L13+잇다카페_외부원두영업!L13+푸른솔!L13+의과대학!L13+중앙도서관!L13+학생회관!L13+멀티미디어관!L13+제2기숙사!L13+선승관!L13+예술디자인대!L13+공학관!L13 -> 0 | T13: =캠퍼스타운_외부원두영업!M13+잇다카페_외부원두영업!M13+푸른솔!M13+의과대학!M13+중앙도서관!M13+학생회관!M13+멀티미디어관!M13+제2기숙사!M13+선승관!M13+예술디자인대!M13+공학관!M13 -> 0 | U13: =P13+Q13+R13+S13+T13 -> 0 | V13: =E13*U13 -> 0 | W13: =(H13+N13)-U13 -> 0 | X13: =E13*W13 -> 0 | Z13: 0 | AA13: =Z13*E13 -> 0
B14: 10/13홀더 | C14: 1box=1000ea | D14: ea | E14: 17.5 | F14: 1000 | G14: 17500 | H14: 4000 | K14: 0 | L14: 0 | N14: =I14+J14+K14+L14+M14 -> 0 | O14: =E14*N14 -> 0 | P14: =캠퍼스타운_외부원두영업!I14+잇다카페_외부원두영업!I14+푸른솔!I14+의과대학!I14+중앙도서관!I14+학생회관!I14+멀티미디어관!I14+제2기숙사!I14+선승관!I14+예술디자인대!I14+공학관!I14 -> 0 | Q14: =캠퍼스타운_외부원두영업!J14+잇다카페_외부원두영업!J14+푸른솔!J14+의과대학!J14+중앙도서관!J14+학생회관!J14+멀티미디어관!J14+제2기숙사!J14+선승관!J14+예술디자인대!J14+공학관!J14 -> 0 | R14: =캠퍼스타운_외부원두영업!K14+잇다카페_외부원두영업!K14+푸른솔!K14+의과대학!K14+중앙도서관!K14+학생회관!K14+멀티미디어관!K14+제2기숙사!K14+선승관!K14+예술디자인대!K14+공학관!K14 -> 0 | S14: =캠퍼스타운_외부원두영업!L14+잇다카페_외부원두영업!L14+푸른솔!L14+의과대학!L14+중앙도서관!L14+학생회관!L14+멀티미디어관!L14+제2기숙사!L14+선승관!L14+예술디자인대!L14+공학관!L14 -> 0 | T14: =캠퍼스타운_외부원두영업!M14+잇다카페_외부원두영업!M14+푸른솔!M14+의과대학!M14+중앙도서관!M14+학생회관!M14+멀티미디어관!M14+제2기숙사!M14+선승관!M14+예술디자인대!M14+공학관!M14 -> 0 | U14: =P14+Q14+R14+S14+T14 -> 0 | V14: =E14*U14 -> 0 | W14: =(H14+N14)-U14 -> 4000 | X14: =E14*W14 -> 70000 | Z14: 0 | AA14: =Z14*E14 -> 0
B15: 12/16홀더 | C15: 1box=1000ea | D15: ea | E15: 18 | F15: 1000 | G15: 18000 | H15: 20000 | K15: 7000 | L15: 15000 | N15: =I15+J15+K15+L15+M15 -> 22000 | O15: =E15*N15 -> 396000 | P15: =캠퍼스타운_외부원두영업!I15+잇다카페_외부원두영업!I15+푸른솔!I15+의과대학!I15+중앙도서관!I15+학생회관!I15+멀티미디어관!I15+제2기숙사!I15+선승관!I15+예술디자인대!I15+공학관!I15 -> 2000 | Q15: =캠퍼스타운_외부원두영업!J15+잇다카페_외부원두영업!J15+푸른솔!J15+의과대학!J15+중앙도서관!J15+학생회관!J15+멀티미디어관!J15+제2기숙사!J15+선승관!J15+예술디자인대!J15+공학관!J15 -> 5000 | R15: =캠퍼스타운_외부원두영업!K15+잇다카페_외부원두영업!K15+푸른솔!K15+의과대학!K15+중앙도서관!K15+학생회관!K15+멀티미디어관!K15+제2기숙사!K15+선승관!K15+예술디자인대!K15+공학관!K15 -> 5000 | S15: =캠퍼스타운_외부원두영업!L15+잇다카페_외부원두영업!L15+푸른솔!L15+의과대학!L15+중앙도서관!L15+학생회관!L15+멀티미디어관!L15+제2기숙사!L15+선승관!L15+예술디자인대!L15+공학관!L15 -> 6000 | T15: =캠퍼스타운_외부원두영업!M15+잇다카페_외부원두영업!M15+푸른솔!M15+의과대학!M15+중앙도서관!M15+학생회관!M15+멀티미디어관!M15+제2기숙사!M15+선승관!M15+예술디자인대!M15+공학관!M15 -> 0 | U15: =P15+Q15+R15+S15+T15 -> 18000 | V15: =E15*U15 -> 324000 | W15: =(H15+N15)-U15 -> 24000 | X15: =E15*W15 -> 432000 | Z15: 0 | AA15: =Z15*E15 -> 0
B16: 21cm 일자 스트로우 (투명) | C16: 1box=10000ea | D16: ea | E16: 6.9 | F16: 10000 | G16: 69000 | H16: 18500 | K16: 0 | L16: 0 | N16: =I16+J16+K16+L16+M16 -> 0 | O16: =E16*N16 -> 0 | P16: =캠퍼스타운_외부원두영업!I16+잇다카페_외부원두영업!I16+푸른솔!I16+의과대학!I16+중앙도서관!I16+학생회관!I16+멀티미디어관!I16+제2기숙사!I16+선승관!I16+예술디자인대!I16+공학관!I16 -> 500 | Q16: =캠퍼스타운_외부원두영업!J16+잇다카페_외부원두영업!J16+푸른솔!J16+의과대학!J16+중앙도서관!J16+학생회관!J16+멀티미디어관!J16+제2기숙사!J16+선승관!J16+예술디자인대!J16+공학관!J16 -> 2500 | R16: =캠퍼스타운_외부원두영업!K16+잇다카페_외부원두영업!K16+푸른솔!K16+의과대학!K16+중앙도서관!K16+학생회관!K16+멀티미디어관!K16+제2기숙사!K16+선승관!K16+예술디자인대!K16+공학관!K16 -> 2000 | S16: =캠퍼스타운_외부원두영업!L16+잇다카페_외부원두영업!L16+푸른솔!L16+의과대학!L16+중앙도서관!L16+학생회관!L16+멀티미디어관!L16+제2기숙사!L16+선승관!L16+예술디자인대!L16+공학관!L16 -> 2500 | T16: =캠퍼스타운_외부원두영업!M16+잇다카페_외부원두영업!M16+푸른솔!M16+의과대학!M16+중앙도서관!M16+학생회관!M16+멀티미디어관!M16+제2기숙사!M16+선승관!M16+예술디자인대!M16+공학관!M16 -> 0 | U16: =P16+Q16+R16+S16+T16 -> 7500 | V16: =E16*U16 -> 51750 | W16: =(H16+N16)-U16 -> 11000 | X16: =E16*W16 -> 75900 | Z16: 0 | AA16: =Z16*E16 -> 0
B17: 21cm 버블티 스트로우 | C17: 1box=3200ea | D17: ea | E17: 22.1875 | F17: 3200 | G17: 71000 | H17: 3600 | K17: 0 | L17: 0 | N17: =I17+J17+K17+L17+M17 -> 0 | O17: =E17*N17 -> 0 | P17: =캠퍼스타운_외부원두영업!I17+잇다카페_외부원두영업!I17+푸른솔!I17+의과대학!I17+중앙도서관!I17+학생회관!I17+멀티미디어관!I17+제2기숙사!I17+선승관!I17+예술디자인대!I17+공학관!I17 -> 0 | Q17: =캠퍼스타운_외부원두영업!J17+잇다카페_외부원두영업!J17+푸른솔!J17+의과대학!J17+중앙도서관!J17+학생회관!J17+멀티미디어관!J17+제2기숙사!J17+선승관!J17+예술디자인대!J17+공학관!J17 -> 200 | R17: =캠퍼스타운_외부원두영업!K17+잇다카페_외부원두영업!K17+푸른솔!K17+의과대학!K17+중앙도서관!K17+학생회관!K17+멀티미디어관!K17+제2기숙사!K17+선승관!K17+예술디자인대!K17+공학관!K17 -> 200 | S17: =캠퍼스타운_외부원두영업!L17+잇다카페_외부원두영업!L17+푸른솔!L17+의과대학!L17+중앙도서관!L17+학생회관!L17+멀티미디어관!L17+제2기숙사!L17+선승관!L17+예술디자인대!L17+공학관!L17 -> 200 | T17: =캠퍼스타운_외부원두영업!M17+잇다카페_외부원두영업!M17+푸른솔!M17+의과대학!M17+중앙도서관!M17+학생회관!M17+멀티미디어관!M17+제2기숙사!M17+선승관!M17+예술디자인대!M17+공학관!M17 -> 0 | U17: =P17+Q17+R17+S17+T17 -> 600 | V17: =E17*U17 -> 13312.5 | W17: =(H17+N17)-U17 -> 3000 | X17: =E17*W17 -> 66562.5 | Z17: 0 | AA17: =Z17*E17 -> 0
... B27: opp 비닐봉투 18*25 | C27: 1pack=200ea | D27: ea | E27: 25 | F27: 200 | G27: 5000 | H27: 600 | K27: 0 | L27: 0 | N27: =I27+J27+K27+L27+M27 -> 0 | O27: =E27*N27 -> 0 | P27: =캠퍼스타운_외부원두영업!I27+잇다카페_외부원두영업!I27+푸른솔!I27+의과대학!I27+중앙도서관!I27+학생회관!I27+멀티미디어관!I27+제2기숙사!I27+선승관!I27+예술디자인대!I27+공학관!I27 -> 0 | Q27: =캠퍼스타운_외부원두영업!J27+잇다카페_외부원두영업!J27+푸른솔!J27+의과대학!J27+중앙도서관!J27+학생회관!J27+멀티미디어관!J27+제2기숙사!J27+선승관!J27+예술디자인대!J27+공학관!J27 -> 0 | R27: =캠퍼스타운_외부원두영업!K27+잇다카페_외부원두영업!K27+푸른솔!K27+의과대학!K27+중앙도서관!K27+학생회관!K27+멀티미디어관!K27+제2기숙사!K27+선승관!K27+예술디자인대!K27+공학관!K27 -> 0 | S27: =캠퍼스타운_외부원두영업!L27+잇다카페_외부원두영업!L27+푸른솔!L27+의과대학!L27+중앙도서관!L27+학생회관!L27+멀티미디어관!L27+제2기숙사!L27+선승관!L27+예술디자인대!L27+공학관!L27 -> 0 | T27: =캠퍼스타운_외부원두영업!M27+잇다카페_외부원두영업!M27+푸른솔!M27+의과대학!M27+중앙도서관!M27+학생회관!M27+멀티미디어관!M27+제2기숙사!M27+선승관!M27+예술디자인대!M27+공학관!M27 -> 0 | U27: =P27+Q27+R27+S27+T27 -> 0 | V27: =E27*U27 -> 0 | W27: =(H27+N27)-U27 -> 600 | X27: =E27*W27 -> 15000 | Z27: 0 | AA27: =Z27*E27 -> 0
B28: 콤부차오리지날 | C28: 1box=12ea | D28: ea | E28: 2100 | F28: 12 | G28: 25200 | H28: 20 | L28: 24 | N28: =I28+J28+K28+L28+M28 -> 24 | O28: =E28*N28 -> 50400 | P28: =캠퍼스타운_외부원두영업!I28+잇다카페_외부원두영업!I28+푸른솔!I28+의과대학!I28+중앙도서관!I28+학생회관!I28+멀티미디어관!I28+제2기숙사!I28+선승관!I28+예술디자인대!I28+공학관!I28 -> 0 | Q28: =캠퍼스타운_외부원두영업!J28+잇다카페_외부원두영업!J28+푸른솔!J28+의과대학!J28+중앙도서관!J28+학생회관!J28+멀티미디어관!J28+제2기숙사!J28+선승관!J28+예술디자인대!J28+공학관!J28 -> 0 | R28: =캠퍼스타운_외부원두영업!K28+잇다카페_외부원두영업!K28+푸른솔!K28+의과대학!K28+중앙도서관!K28+학생회관!K28+멀티미디어관!K28+제2기숙사!K28+선승관!K28+예술디자인대!K28+공학관!K28 -> 0 | S28: =캠퍼스타운_외부원두영업!L28+잇다카페_외부원두영업!L28+푸른솔!L28+의과대학!L28+중앙도서관!L28+학생회관!L28+멀티미디어관!L28+제2기숙사!L28+선승관!L28+예술디자인대!L28+공학관!L28 -> 0 | T28: =캠퍼스타운_외부원두영업!M28+잇다카페_외부원두영업!M28+푸른솔!M28+의과대학!M28+중앙도서관!M28+학생회관!M28+멀티미디어관!M28+제2기숙사!M28+선승관!M28+예술디자인대!M28+공학관!M28 -> 0 | U28: =P28+Q28+R28+S28+T28 -> 0 | V28: =E28*U28 -> 0 | W28: =(H28+N28)-U28 -> 44 | X28: =E28*W28 -> 92400 | Z28: 0 | AA28: =Z28*E28 -> 0
B29: 콤부차진저레몬 | C29: 1box=12ea | D29: ea | E29: 2100 | F29: 12 | G29: 25200 | H29: 14 | K29: 36 | L29: 24 | N29: =I29+J29+K29+L29+M29 -> 60 | O29: =E29*N29 -> 126000 | P29: =캠퍼스타운_외부원두영업!I29+잇다카페_외부원두영업!I29+푸른솔!I29+의과대학!I29+중앙도서관!I29+학생회관!I29+멀티미디어관!I29+제2기숙사!I29+선승관!I29+예술디자인대!I29+공학관!I29 -> 14 | Q29: =캠퍼스타운_외부원두영업!J29+잇다카페_외부원두영업!J29+푸른솔!J29+의과대학!J29+중앙도서관!J29+학생회관!J29+멀티미디어관!J29+제2기숙사!J29+선승관!J29+예술디자인대!J29+공학관!J29 -> 0 | R29: =캠퍼스타운_외부원두영업!K29+잇다카페_외부원두영업!K29+푸른솔!K29+의과대학!K29+중앙도서관!K29+학생회관!K29+멀티미디어관!K29+제2기숙사!K29+선승관!K29+예술디자인대!K29+공학관!K29 -> 6 | S29: =캠퍼스타운_외부원두영업!L29+잇다카페_외부원두영업!L29+푸른솔!L29+의과대학!L29+중앙도서관!L29+학생회관!L29+멀티미디어관!L29+제2기숙사!L29+선승관!L29+예술디자인대!L29+공학관!L29 -> 0 | T29: =캠퍼스타운_외부원두영업!M29+잇다카페_외부원두영업!M29+푸른솔!M29+의과대학!M29+중앙도서관!M29+학생회관!M29+멀티미디어관!M29+제2기숙사!M29+선승관!M29+예술디자인대!M29+공학관!M29 -> 0 | U29: =P29+Q29+R29+S29+T29 -> 20 | V29: =E29*U29 -> 42000 | W29: =(H29+N29)-U29 -> 54 | X29: =E29*W29 -> 113400 | Z29: 0 | AA29: =Z29*E29 -> 0
B30: 콤부차석류 | C30: 1box=12ea | D30: ea | E30: 2100 | F30: 12 | G30: 25200 | H30: 48 | L30: 24 | N30: =I30+J30+K30+L30+M30 -> 24 | O30: =E30*N30 -> 50400 | P30: =캠퍼스타운_외부원두영업!I30+잇다카페_외부원두영업!I30+푸른솔!I30+의과대학!I30+중앙도서관!I30+학생회관!I30+멀티미디어관!I30+제2기숙사!I30+선승관!I30+예술디자인대!I30+공학관!I30 -> 0 | Q30: =캠퍼스타운_외부원두영업!J30+잇다카페_외부원두영업!J30+푸른솔!J30+의과대학!J30+중앙도서관!J30+학생회관!J30+멀티미디어관!J30+제2기숙사!J30+선승관!J30+예술디자인대!J30+공학관!J30 -> 6 | R30: =캠퍼스타운_외부원두영업!K30+잇다카페_외부원두영업!K30+푸른솔!K30+의과대학!K30+중앙도서관!K30+학생회관!K30+멀티미디어관!K30+제2기숙사!K30+선승관!K30+예술디자인대!K30+공학관!K30 -> 0 | S30: =캠퍼스타운_외부원두영업!L30+잇다카페_외부원두영업!L30+푸른솔!L30+의과대학!L30+중앙도서관!L30+학생회관!L30+멀티미디어관!L30+제2기숙사!L30+선승관!L30+예술디자인대!L30+공학관!L30 -> 12 | T30: =캠퍼스타운_외부원두영업!M30+잇다카페_외부원두영업!M30+푸른솔!M30+의과대학!M30+중앙도서관!M30+학생회관!M30+멀티미디어관!M30+제2기숙사!M30+선승관!M30+예술디자인대!M30+공학관!M30 -> 0 | U30: =P30+Q30+R30+S30+T30 -> 18 | V30: =E30*U30 -> 37800 | W30: =(H30+N30)-U30 -> 54 | X30: =E30*W30 -> 113400 | Z30: 0 | AA30: =Z30*E30 -> 0
B31: 슈가시럽 | C31: 1box=6ea | D31: ea | E31: 2800 | F31: 6 | G31: 16800 | H31: 0 | L31: 0 | N31: =I31+J31+K31+L31+M31 -> 0 | O31: =E31*N31 -> 0 | P31: =캠퍼스타운_외부원두영업!I31+잇다카페_외부원두영업!I31+푸른솔!I31+의과대학!I31+중앙도서관!I31+학생회관!I31+멀티미디어관!I31+제2기숙사!I31+선승관!I31+예술디자인대!I31+공학관!I31 -> 0 | Q31: =캠퍼스타운_외부원두영업!J31+잇다카페_외부원두영업!J31+푸른솔!J31+의과대학!J31+중앙도서관!J31+학생회관!J31+멀티미디어관!J31+제2기숙사!J31+선승관!J31+예술디자인대!J31+공학관!J31 -> 0 | R31: =캠퍼스타운_외부원두영업!K31+잇다카페_외부원두영업!K31+푸른솔!K31+의과대학!K31+중앙도서관!K31+학생회관!K31+멀티미디어관!K31+제2기숙사!K31+선승관!K31+예술디자인대!K31+공학관!K31 -> 0 | S31: =캠퍼스타운_외부원두영업!L31+잇다카페_외부원두영업!L31+푸른솔!L31+의과대학!L31+중앙도서관!L31+학생회관!L31+멀티미디어관!L31+제2기숙사!L31+선승관!L31+예술디자인대!L31+공학관!L31 -> 0 | T31: =캠퍼스타운_외부원두영업!M31+잇다카페_외부원두영업!M31+푸른솔!M31+의과대학!M31+중앙도서관!M31+학생회관!M31+멀티미디어관!M31+제2기숙사!M31+선승관!M31+예술디자인대!M31+공학관!M31 -> 0 | U31: =P31+Q31+R31+S31+T31 -> 0 | V31: =E31*U31 -> 0 | W31: =(H31+N31)-U31 -> 0 | X31: =E31*W31 -> 0 | Z31: 0 | AA31: =Z31*E31 -> 0
B32: 슈가시럽(24년인상) | C32: 1box=6ea | D32: ea | E32: 3200 | F32: 6 | G32: 19200 | H32: 30 | L32: 18 | N32: =I32+J32+K32+L32+M32 -> 18 | O32: =E32*N32 -> 57600 | P32: =캠퍼스타운_외부원두영업!I32+잇다카페_외부원두영업!I32+푸른솔!I32+의과대학!I32+중앙도서관!I32+학생회관!I32+멀티미디어관!I32+제2기숙사!I32+선승관!I32+예술디자인대!I32+공학관!I32 -> 2 | Q32: =캠퍼스타운_외부원두영업!J32+잇다카페_외부원두영업!J32+푸른솔!J32+의과대학!J32+중앙도서관!J32+학생회관!J32+멀티미디어관!J32+제2기숙사!J32+선승관!J32+예술디자인대!J32+공학관!J32 -> 4 | R32: =캠퍼스타운_외부원두영업!K32+잇다카페_외부원두영업!K32+푸른솔!K32+의과대학!K32+중앙도서관!K32+학생회관!K32+멀티미디어관!K32+제2기숙사!K32+선승관!K32+예술디자인대!K32+공학관!K32 -> 6 | S32: =캠퍼스타운_외부원두영업!L32+잇다카페_외부원두영업!L32+푸른솔!L32+의과대학!L32+중앙도서관!L32+학생회관!L32+멀티미디어관!L32+제2기숙사!L32+선승관!L32+예술디자인대!L32+공학관!L32 -> 6 | T32: =캠퍼스타운_외부원두영업!M32+잇다카페_외부원두영업!M32+푸른솔!M32+의과대학!M32+중앙도서관!M32+학생회관!M32+멀티미디어관!M32+제2기숙사!M32+선승관!M32+예술디자인대!M32+공학관!M32 -> 0 | U32: =P32+Q32+R32+S32+T32 -> 18 | V32: =E32*U32 -> 57600 | W32: =(H32+N32)-U32 -> 30 | X32: =E32*W32 -> 96000 | Z32: 0 | AA32: =Z32*E32 -> 0
B33: 삼다수 | C33: 1box=20ea | D33: ea | E33: 410 | F33: 20 | G33: 8200 | H33: 220 | L33: 0 | N33: =I33+J33+K33+L33+M33 -> 0 | O33: =E33*N33 -> 0 | P33: =캠퍼스타운_외부원두영업!I33+잇다카페_외부원두영업!I33+푸른솔!I33+의과대학!I33+중앙도서관!I33+학생회관!I33+멀티미디어관!I33+제2기숙사!I33+선승관!I33+예술디자인대!I33+공학관!I33 -> 20 | Q33: =캠퍼스타운_외부원두영업!J33+잇다카페_외부원두영업!J33+푸른솔!J33+의과대학!J33+중앙도서관!J33+학생회관!J33+멀티미디어관!J33+제2기숙사!J33+선승관!J33+예술디자인대!J33+공학관!J33 -> 60 | R33: =캠퍼스타운_외부원두영업!K33+잇다카페_외부원두영업!K33+푸른솔!K33+의과대학!K33+중앙도서관!K33+학생회관!K33+멀티미디어관!K33+제2기숙사!K33+선승관!K33+예술디자인대!K33+공학관!K33 -> 0 | S33: =캠퍼스타운_외부원두영업!L33+잇다카페_외부원두영업!L33+푸른솔!L33+의과대학!L33+중앙도서관!L33+학생회관!L33+멀티미디어관!L33+제2기숙사!L33+선승관!L33+예술디자인대!L33+공학관!L33 -> 20 | T33: =캠퍼스타운_외부원두영업!M33+잇다카페_외부원두영업!M33+푸른솔!M33+의과대학!M33+중앙도서관!M33+학생회관!M33+멀티미디어관!M33+제2기숙사!M33+선승관!M33+예술디자인대!M33+공학관!M33 -> 0 | U33: =P33+Q33+R33+S33+T33 -> 100 | V33: =E33*U33 -> 41000 | W33: =(H33+N33)-U33 -> 120 | X33: =E33*W33 -> 49200 | Z33: 0 | AA33: =Z33*E33 -> 0
B34: 립톤 복숭아파우더(907g) | C34: 1box=12ea | D34: ea | E34: 7200 | F34: 12 | G34: 86400 | H34: 184 | L34: 204 | N34: =I34+J34+K34+L34+M34 -> 204 | O34: =E34*N34 -> 1468800 | P34: =캠퍼스타운_외부원두영업!I34+잇다카페_외부원두영업!I34+푸른솔!I34+의과대학!I34+중앙도서관!I34+학생회관!I34+멀티미디어관!I34+제2기숙사!I34+선승관!I34+예술디자인대!I34+공학관!I34 -> 16 | Q34: =캠퍼스타운_외부원두영업!J34+잇다카페_외부원두영업!J34+푸른솔!J34+의과대학!J34+중앙도서관!J34+학생회관!J34+멀티미디어관!J34+제2기숙사!J34+선승관!J34+예술디자인대!J34+공학관!J34 -> 37 | R34: =캠퍼스타운_외부원두영업!K34+잇다카페_외부원두영업!K34+푸른솔!K34+의과대학!K34+중앙도서관!K34+학생회관!K34+멀티미디어관!K34+제2기숙사!K34+선승관!K34+예술디자인대!K34+공학관!K34 -> 78 | S34: =캠퍼스타운_외부원두영업!L34+잇다카페_외부원두영업!L34+푸른솔!L34+의과대학!L34+중앙도서관!L34+학생회관!L34+멀티미디어관!L34+제2기숙사!L34+선승관!L34+예술디자인대!L34+공학관!L34 -> 47 | T34: =캠퍼스타운_외부원두영업!M34+잇다카페_외부원두영업!M34+푸른솔!M34+의과대학!M34+중앙도서관!M34+학생회관!M34+멀티미디어관!M34+제2기숙사!M34+선승관!M34+예술디자인대!M34+공학관!M34 -> 0 | U34: =P34+Q34+R34+S34+T34 -> 178 | V34: =E34*U34 -> 1281600 | W34: =(H34+N34)-U34 -> 210 | X34: =E34*W34 -> 1512000 | Z34: 0 | AA34: =Z34*E34 -> 0
B35: 초정탄산수(1.5L) | C35: 1box=12ea | D35: ea | E35: 1350 | F35: 12 | G35: 16200 | H35: 136 | L35: 120 | N35: =I35+J35+K35+L35+M35 -> 120 | O35: =E35*N35 -> 162000 | P35: =캠퍼스타운_외부원두영업!I35+잇다카페_외부원두영업!I35+푸른솔!I35+의과대학!I35+중앙도서관!I35+학생회관!I35+멀티미디어관!I35+제2기숙사!I35+선승관!I35+예술디자인대!I35+공학관!I35 -> 6 | Q35: =캠퍼스타운_외부원두영업!J35+잇다카페_외부원두영업!J35+푸른솔!J35+의과대학!J35+중앙도서관!J35+학생회관!J35+멀티미디어관!J35+제2기숙사!J35+선승관!J35+예술디자인대!J35+공학관!J35 -> 24 | R35: =캠퍼스타운_외부원두영업!K35+잇다카페_외부원두영업!K35+푸른솔!K35+의과대학!K35+중앙도서관!K35+학생회관!K35+멀티미디어관!K35+제2기숙사!K35+선승관!K35+예술디자인대!K35+공학관!K35 -> 22 | S35: =캠퍼스타운_외부원두영업!L35+잇다카페_외부원두영업!L35+푸른솔!L35+의과대학!L35+중앙도서관!L35+학생회관!L35+멀티미디어관!L35+제2기숙사!L35+선승관!L35+예술디자인대!L35+공학관!L35 -> 25 | T35: =캠퍼스타운_외부원두영업!M35+잇다카페_외부원두영업!M35+푸른솔!M35+의과대학!M35+중앙도서관!M35+학생회관!M35+멀티미디어관!M35+제2기숙사!M35+선승관!M35+예술디자인대!M35+공학관!M35 -> 0 | U35: =P35+Q35+R35+S35+T35 -> 77 | V35: =E35*U35 -> 103950 | W35: =(H35+N35)-U35 -> 179 | X35: =E35*W35 -> 241650 | Z35: 0 | AA35: =Z35*E35 -> 0
B36: 메티에 바닐라시럽(700ml) | C36: 1box=8ea | D36: ea | E36: 6870 | F36: 8 | G36: 54960 | H36: 62 | K36: 16 | L36: 0 | N36: =I36+J36+K36+L36+M36 -> 16 | O36: =E36*N36 -> 109920 | P36: =캠퍼스타운_외부원두영업!I36+잇다카페_외부원두영업!I36+푸른솔!I36+의과대학!I36+중앙도서관!I36+학생회관!I36+멀티미디어관!I36+제2기숙사!I36+선승관!I36+예술디자인대!I36+공학관!I36 -> 4 | Q36: =캠퍼스타운_외부원두영업!J36+잇다카페_외부원두영업!J36+푸른솔!J36+의과대학!J36+중앙도서관!J36+학생회관!J36+멀티미디어관!J36+제2기숙사!J36+선승관!J36+예술디자인대!J36+공학관!J36 -> 22 | R36: =캠퍼스타운_외부원두영업!K36+잇다카페_외부원두영업!K36+푸른솔!K36+의과대학!K36+중앙도서관!K36+학생회관!K36+멀티미디어관!K36+제2기숙사!K36+선승관!K36+예술디자인대!K36+공학관!K36 -> 20 | S36: =캠퍼스타운_외부원두영업!L36+잇다카페_외부원두영업!L36+푸른솔!L36+의과대학!L36+중앙도서관!L36+학생회관!L36+멀티미디어관!L36+제2기숙사!L36+선승관!L36+예술디자인대!L36+공학관!L36 -> 25 | T36: =캠퍼스타운_외부원두영업!M36+잇다카페_외부원두영업!M36+푸른솔!M36+의과대학!M36+중앙도서관!M36+학생회관!M36+멀티미디어관!M36+제2기숙사!M36+선승관!M36+예술디자인대!M36+공학관!M36 -> 0 | U36: =P36+Q36+R36+S36+T36 -> 71 | V36: =E36*U36 -> 487770 | W36: =(H36+N36)-U36 -> 7 | X36: =E36*W36 -> 48090 | Z36: 0 | AA36: =Z36*E36 -> 0
B37: 메티에 헤이즐럿시럽(700ml) | C37: 1box=8ea | D37: ea | E37: 6870 | F37: 8 | G37: 54960 | H37: 21 | K37: 16 | L37: 0 | N37: =I37+J37+K37+L37+M37 -> 16 | O37: =E37*N37 -> 109920 | P37: =캠퍼스타운_외부원두영업!I37+잇다카페_외부원두영업!I37+푸른솔!I37+의과대학!I37+중앙도서관!I37+학생회관!I37+멀티미디어관!I37+제2기숙사!I37+선승관!I37+예술디자인대!I37+공학관!I37 -> 0 | Q37: =캠퍼스타운_외부원두영업!J37+잇다카페_외부원두영업!J37+푸른솔!J37+의과대학!J37+중앙도서관!J37+학생회관!J37+멀티미디어관!J37+제2기숙사!J37+선승관!J37+예술디자인대!J37+공학관!J37 -> 2 | R37: =캠퍼스타운_외부원두영업!K37+잇다카페_외부원두영업!K37+푸른솔!K37+의과대학!K37+중앙도서관!K37+학생회관!K37+멀티미디어관!K37+제2기숙사!K37+선승관!K37+예술디자인대!K37+공학관!K37 -> 3 | S37: =캠퍼스타운_외부원두영업!L37+잇다카페_외부원두영업!L37+푸른솔!L37+의과대학!L37+중앙도서관!L37+학생회관!L37+멀티미디어관!L37+제2기숙사!L37+선승관!L37+예술디자인대!L37+공학관!L37 -> 7 | T37: =캠퍼스타운_외부원두영업!M37+잇다카페_외부원두영업!M37+푸른솔!M37+의과대학!M37+중앙도서관!M37+학생회관!M37+멀티미디어관!M37+제2기숙사!M37+선승관!M37+예술디자인대!M37+공학관!M37 -> 0 | U37: =P37+Q37+R37+S37+T37 -> 12 | V37: =E37*U37 -> 82440 | W37: =(H37+N37)-U37 -> 25 | X37: =E37*W37 -> 171750 | Z37: 0 | AA37: =Z37*E37 -> 0
B38: 메티에 바닐라시럽(750ml) | C38: 1box=8ea | D38: ea | E38: 7360 | F38: 8 | G38: =E38*F38 -> 58880 | H38: 0 | L38: 40 | N38: =I38+J38+K38+L38+M38 -> 40 | O38: =E38*N38 -> 294400 | P38: =캠퍼스타운_외부원두영업!I38+잇다카페_외부원두영업!I38+푸른솔!I38+의과대학!I38+중앙도서관!I38+학생회관!I38+멀티미디어관!I38+제2기숙사!I38+선승관!I38+예술디자인대!I38+공학관!I38 -> 0 | Q38: =캠퍼스타운_외부원두영업!J38+잇다카페_외부원두영업!J38+푸른솔!J38+의과대학!J38+중앙도서관!J38+학생회관!J38+멀티미디어관!J38+제2기숙사!J38+선승관!J38+예술디자인대!J38+공학관!J38 -> 0 | R38: =캠퍼스타운_외부원두영업!K38+잇다카페_외부원두영업!K38+푸른솔!K38+의과대학!K38+중앙도서관!K38+학생회관!K38+멀티미디어관!K38+제2기숙사!K38+선승관!K38+예술디자인대!K38+공학관!K38 -> 0 | S38: =캠퍼스타운_외부원두영업!L38+잇다카페_외부원두영업!L38+푸른솔!L38+의과대학!L38+중앙도서관!L38+학생회관!L38+멀티미디어관!L38+제2기숙사!L38+선승관!L38+예술디자인대!L38+공학관!L38 -> 0 | T38: =캠퍼스타운_외부원두영업!M40+잇다카페_외부원두영업!M40+푸른솔!M40+의과대학!M40+중앙도서관!M40+학생회관!M40+멀티미디어관!M40+제2기숙사!M40+선승관!M40+예술디자인대!M40+공학관!M40 -> 0 | U38: =P38+Q38+R38+S38+T38 -> 0 | V38: =E38*U38 -> 0 | W38: =(H38+N38)-U38 -> 40 | X38: =E38*W38 -> 294400 | Z38: 0 | AA38: =Z38*E38 -> 0
B39: 메티에 헤이즐럿시럽(750ml) | C39: 1box=8ea | D39: ea | E39: 7360 | F39: 8 | G39: =E39*F39 -> 58880 | H39: 0 | L39: 0 | N39: =I39+J39+K39+L39+M39 -> 0 | O39: =E39*N39 -> 0 | P39: =캠퍼스타운_외부원두영업!I39+잇다카페_외부원두영업!I39+푸른솔!I39+의과대학!I39+중앙도서관!I39+학생회관!I39+멀티미디어관!I39+제2기숙사!I39+선승관!I39+예술디자인대!I39+공학관!I39 -> 0 | Q39: =캠퍼스타운_외부원두영업!J39+잇다카페_외부원두영업!J39+푸른솔!J39+의과대학!J39+중앙도서관!J39+학생회관!J39+멀티미디어관!J39+제2기숙사!J39+선승관!J39+예술디자인대!J39+공학관!J39 -> 0 | R39: =캠퍼스타운_외부원두영업!K39+잇다카페_외부원두영업!K39+푸른솔!K39+의과대학!K39+중앙도서관!K39+학생회관!K39+멀티미디어관!K39+제2기숙사!K39+선승관!K39+예술디자인대!K39+공학관!K39 -> 0 | S39: =캠퍼스타운_외부원두영업!L39+잇다카페_외부원두영업!L39+푸른솔!L39+의과대학!L39+중앙도서관!L39+학생회관!L39+멀티미디어관!L39+제2기숙사!L39+선승관!L39+예술디자인대!L39+공학관!L39 -> 0 | T39: =캠퍼스타운_외부원두영업!M41+잇다카페_외부원두영업!M41+푸른솔!M41+의과대학!M41+중앙도서관!M41+학생회관!M41+멀티미디어관!M41+제2기숙사!M41+선승관!M41+예술디자인대!M41+공학관!M41 -> 0 | U39: =P39+Q39+R39+S39+T39 -> 0 | V39: =E39*U39 -> 0 | W39: =(H39+N39)-U39 -> 0 | X39: =E39*W39 -> 0 | Z39: 0 | AA39: =Z39*E39 -> 0
A40: 성원애드피아 | B40: 적립쿠폰 | C40: 1bundle=500ea | D40: ea | E40: 6.4 | F40: 500 | G40: 3200 | H40: 17800 | L40: 0 | N40: =I40+J40+K40+L40+M40 -> 0 | O40: =E40*N40 -> 0 | P40: =캠퍼스타운_외부원두영업!I40+잇다카페_외부원두영업!I40+푸른솔!I40+의과대학!I40+중앙도서관!I40+학생회관!I40+멀티미디어관!I40+제2기숙사!I40+선승관!I40+예술디자인대!I40+공학관!I40 -> 300 | Q40: =캠퍼스타운_외부원두영업!J40+잇다카페_외부원두영업!J40+푸른솔!J40+의과대학!J40+중앙도서관!J40+학생회관!J40+멀티미디어관!J40+제2기숙사!J40+선승관!J40+예술디자인대!J40+공학관!J40 -> 1200 | R40: =캠퍼스타운_외부원두영업!K40+잇다카페_외부원두영업!K40+푸른솔!K40+의과대학!K40+중앙도서관!K40+학생회관!K40+멀티미디어관!K40+제2기숙사!K40+선승관!K40+예술디자인대!K40+공학관!K40 -> 1100 | S40: =캠퍼스타운_외부원두영업!L40+잇다카페_외부원두영업!L40+푸른솔!L40+의과대학!L40+중앙도서관!L40+학생회관!L40+멀티미디어관!L40+제2기숙사!L40+선승관!L40+예술디자인대!L40+공학관!L40 -> 600 | T40: =캠퍼스타운_외부원두영업!M40+잇다카페_외부원두영업!M40+푸른솔!M40+의과대학!M40+중앙도서관!M40+학생회관!M40+멀티미디어관!M40+제2기숙사!M40+선승관!M40+예술디자인대!M40+공학관!M40 -> 0 | U40: =P40+Q40+R40+S40+T40 -> 3200 | V40: =E40*U40 -> 20480 | W40: =(H40+N40)-U40 -> 14600 | X40: =E40*W40 -> 93440 | Z40: 0 | AA40: =Z40*E40 -> 0 | AB40: =SUM(AA40:AA41) -> 0 | AC40: =AB40*1.1 -> 0
B41: 유통기한 스티커 | C41: 1bundle=1000ea | D41: ea | E41: 4.69 | F41: 1000 | G41: 4690 | H41: 3500 | L41: 0 | N41: =I41+J41+K41+L41+M41 -> 0 | O41: =E41*N41 -> 0 | P41: =캠퍼스타운_외부원두영업!I41+잇다카페_외부원두영업!I41+푸른솔!I41+의과대학!I41+중앙도서관!I41+학생회관!I41+멀티미디어관!I41+제2기숙사!I41+선승관!I41+예술디자인대!I41+공학관!I41 -> 0 | Q41: =캠퍼스타운_외부원두영업!J41+잇다카페_외부원두영업!J41+푸른솔!J41+의과대학!J41+중앙도서관!J41+학생회관!J41+멀티미디어관!J41+제2기숙사!J41+선승관!J41+예술디자인대!J41+공학관!J41 -> 0 | R41: =캠퍼스타운_외부원두영업!K41+잇다카페_외부원두영업!K41+푸른솔!K41+의과대학!K41+중앙도서관!K41+학생회관!K41+멀티미디어관!K41+제2기숙사!K41+선승관!K41+예술디자인대!K41+공학관!K41 -> 0 | S41: =캠퍼스타운_외부원두영업!L41+잇다카페_외부원두영업!L41+푸른솔!L41+의과대학!L41+중앙도서관!L41+학생회관!L41+멀티미디어관!L41+제2기숙사!L41+선승관!L41+예술디자인대!L41+공학관!L41 -> 0 | T41: =캠퍼스타운_외부원두영업!M41+잇다카페_외부원두영업!M41+푸른솔!M41+의과대학!M41+중앙도서관!M41+학생회관!M41+멀티미디어관!M41+제2기숙사!M41+선승관!M41+예술디자인대!M41+공학관!M41 -> 0 | U41: =P41+Q41+R41+S41+T41 -> 0 | V41: =E41*U41 -> 0 | W41: =(H41+N41)-U41 -> 3500 | X41: =E41*W41 -> 16415 | Z41: 0 | AA41: =Z41*E41 -> 0
A42: 휴럼 | B42: 민트초코파우더 | C42: 1box = 12ea | D42: ea | E42: 7700 | F42: 12 | G42: 92400 | H42: 18 | L42: 0 | N42: =I42+J42+K42+L42+M42 -> 0 | O42: =E42*N42 -> 0 | P42: =캠퍼스타운_외부원두영업!I42+잇다카페_외부원두영업!I42+푸른솔!I42+의과대학!I42+중앙도서관!I42+학생회관!I42+멀티미디어관!I42+제2기숙사!I42+선승관!I42+예술디자인대!I42+공학관!I42 -> 0 | Q42: =캠퍼스타운_외부원두영업!J42+잇다카페_외부원두영업!J42+푸른솔!J42+의과대학!J42+중앙도서관!J42+학생회관!J42+멀티미디어관!J42+제2기숙사!J42+선승관!J42+예술디자인대!J42+공학관!J42 -> 1 | R42: =캠퍼스타운_외부원두영업!K42+잇다카페_외부원두영업!K42+푸른솔!K42+의과대학!K42+중앙도서관!K42+학생회관!K42+멀티미디어관!K42+제2기숙사!K42+선승관!K42+예술디자인대!K42+공학관!K42 -> 2 | S42: =캠퍼스타운_외부원두영업!L42+잇다카페_외부원두영업!L42+푸른솔!L42+의과대학!L42+중앙도서관!L42+학생회관!L42+멀티미디어관!L42+제2기숙사!L42+선승관!L42+예술디자인대!L42+공학관!L42 -> 2 | T42: =캠퍼스타운_외부원두영업!M42+잇다카페_외부원두영업!M42+푸른솔!M42+의과대학!M42+중앙도서관!M42+학생회관!M42+멀티미디어관!M42+제2기숙사!M42+선승관!M42+예술디자인대!M42+공학관!M42 -> 0 | U42: =P42+Q42+R42+S42+T42 -> 5 | V42: =E42*U42 -> 38500 | W42: =(H42+N42)-U42 -> 13 | X42: =E42*W42 -> 100100 | Z42: 0 | AA42: =Z42*E42 -> 0 | AB42: =SUM(AA42:AA51) -> 0 | AC42: =AB42*1.1 -> 0
B43: 다크초코파우더 | C43: 1box = 12ea | D43: ea | E43: 6200 | F43: 12 | G43: 74400 | H43: 44 | L43: 24 | N43: =I43+J43+K43+L43+M43 -> 24 | O43: =E43*N43 -> 148800 | P43: =캠퍼스타운_외부원두영업!I43+잇다카페_외부원두영업!I43+푸른솔!I43+의과대학!I43+중앙도서관!I43+학생회관!I43+멀티미디어관!I43+제2기숙사!I43+선승관!I43+예술디자인대!I43+공학관!I43 -> 5 | Q43: =캠퍼스타운_외부원두영업!J43+잇다카페_외부원두영업!J43+푸른솔!J43+의과대학!J43+중앙도서관!J43+학생회관!J43+멀티미디어관!J43+제2기숙사!J43+선승관!J43+예술디자인대!J43+공학관!J43 -> 9 | R43: =캠퍼스타운_외부원두영업!K43+잇다카페_외부원두영업!K43+푸른솔!K43+의과대학!K43+중앙도서관!K43+학생회관!K43+멀티미디어관!K43+제2기숙사!K43+선승관!K43+예술디자인대!K43+공학관!K43 -> 4 | S43: =캠퍼스타운_외부원두영업!L43+잇다카페_외부원두영업!L43+푸른솔!L43+의과대학!L43+중앙도서관!L43+학생회관!L43+멀티미디어관!L43+제2기숙사!L43+선승관!L43+예술디자인대!L43+공학관!L43 -> 9 | T43: =캠퍼스타운_외부원두영업!M43+잇다카페_외부원두영업!M43+푸른솔!M43+의과대학!M43+중앙도서관!M43+학생회관!M43+멀티미디어관!M43+제2기숙사!M43+선승관!M43+예술디자인대!M43+공학관!M43 -> 0 | U43: =P43+Q43+R43+S43+T43 -> 27 | V43: =E43*U43 -> 167400 | W43: =(H43+N43)-U43 -> 41 | X43: =E43*W43 -> 254200 | Z43: 0 | AA43: =Z43*E43 -> 0
B44: 청귤베이스 | C44: 1box = 12ea | D44: ea | E44: 6700 | F44: 12 | G44: 80400 | H44: 33 | L44: 12 | N44: =I44+J44+K44+L44+M44 -> 12 | O44: =E44*N44 -> 80400 | P44: =캠퍼스타운_외부원두영업!I44+잇다카페_외부원두영업!I44+푸른솔!I44+의과대학!I44+중앙도서관!I44+학생회관!I44+멀티미디어관!I44+제2기숙사!I44+선승관!I44+예술디자인대!I44+공학관!I44 -> 1 | Q44: =캠퍼스타운_외부원두영업!J44+잇다카페_외부원두영업!J44+푸른솔!J44+의과대학!J44+중앙도서관!J44+학생회관!J44+멀티미디어관!J44+제2기숙사!J44+선승관!J44+예술디자인대!J44+공학관!J44 -> 1 | R44: =캠퍼스타운_외부원두영업!K44+잇다카페_외부원두영업!K44+푸른솔!K44+의과대학!K44+중앙도서관!K44+학생회관!K44+멀티미디어관!K44+제2기숙사!K44+선승관!K44+예술디자인대!K44+공학관!K44 -> 6 | S44: =캠퍼스타운_외부원두영업!L44+잇다카페_외부원두영업!L44+푸른솔!L44+의과대학!L44+중앙도서관!L44+학생회관!L44+멀티미디어관!L44+제2기숙사!L44+선승관!L44+예술디자인대!L44+공학관!L44 -> 5 | T44: =캠퍼스타운_외부원두영업!M44+잇다카페_외부원두영업!M44+푸른솔!M44+의과대학!M44+중앙도서관!M44+학생회관!M44+멀티미디어관!M44+제2기숙사!M44+선승관!M44+예술디자인대!M44+공학관!M44 -> 0 | U44: =P44+Q44+R44+S44+T44 -> 13 | V44: =E44*U44 -> 87100 | W44: =(H44+N44)-U44 -> 32 | X44: =E44*W44 -> 214400 | Z44: 0 | AA44: =Z44*E44 -> 0
B45: 요거에스플레인 | C45: 1box=12ea | D45: ea | E45: 7250 | F45: 12 | G45: 87000 | H45: 51 | L45: 24 | N45: =I45+J45+K45+L45+M45 -> 24 | O45: =E45*N45 -> 174000 | P45: =캠퍼스타운_외부원두영업!I45+잇다카페_외부원두영업!I45+푸른솔!I45+의과대학!I45+중앙도서관!I45+학생회관!I45+멀티미디어관!I45+제2기숙사!I45+선승관!I45+예술디자인대!I45+공학관!I45 -> 4 | Q45: =캠퍼스타운_외부원두영업!J45+잇다카페_외부원두영업!J45+푸른솔!J45+의과대학!J45+중앙도서관!J45+학생회관!J45+멀티미디어관!J45+제2기숙사!J45+선승관!J45+예술디자인대!J45+공학관!J45 -> 5 | R45: =캠퍼스타운_외부원두영업!K45+잇다카페_외부원두영업!K45+푸른솔!K45+의과대학!K45+중앙도서관!K45+학생회관!K45+멀티미디어관!K45+제2기숙사!K45+선승관!K45+예술디자인대!K45+공학관!K45 -> 4 | S45: =캠퍼스타운_외부원두영업!L45+잇다카페_외부원두영업!L45+푸른솔!L45+의과대학!L45+중앙도서관!L45+학생회관!L45+멀티미디어관!L45+제2기숙사!L45+선승관!L45+예술디자인대!L45+공학관!L45 -> 9 | T45: =캠퍼스타운_외부원두영업!M45+잇다카페_외부원두영업!M45+푸른솔!M45+의과대학!M45+중앙도서관!M45+학생회관!M45+멀티미디어관!M45+제2기숙사!M45+선승관!M45+예술디자인대!M45+공학관!M45 -> 0 | U45: =P45+Q45+R45+S45+T45 -> 22 | V45: =E45*U45 -> 159500 | W45: =(H45+N45)-U45 -> 53 | X45: =E45*W45 -> 384250 | Z45: 0 | AA45: =Z45*E45 -> 0
B46: 흑당베이스 | C46: 1kg x 12ea | D46: ea | E46: 5300 | F46: 12 | G46: 63600 | H46: 16 | L46: 0 | N46: =I46+J46+K46+L46+M46 -> 0 | O46: =E46*N46 -> 0 | P46: =캠퍼스타운_외부원두영업!I46+잇다카페_외부원두영업!I46+푸른솔!I46+의과대학!I46+중앙도서관!I46+학생회관!I46+멀티미디어관!I46+제2기숙사!I46+선승관!I46+예술디자인대!I46+공학관!I46 -> 1 | Q46: =캠퍼스타운_외부원두영업!J46+잇다카페_외부원두영업!J46+푸른솔!J46+의과대학!J46+중앙도서관!J46+학생회관!J46+멀티미디어관!J46+제2기숙사!J46+선승관!J46+예술디자인대!J46+공학관!J46 -> 1 | R46: =캠퍼스타운_외부원두영업!K46+잇다카페_외부원두영업!K46+푸른솔!K46+의과대학!K46+중앙도서관!K46+학생회관!K46+멀티미디어관!K46+제2기숙사!K46+선승관!K46+예술디자인대!K46+공학관!K46 -> 1 | S46: =캠퍼스타운_외부원두영업!L46+잇다카페_외부원두영업!L46+푸른솔!L46+의과대학!L46+중앙도서관!L46+학생회관!L46+멀티미디어관!L46+제2기숙사!L46+선승관!L46+예술디자인대!L46+공학관!L46 -> 2 | T46: =캠퍼스타운_외부원두영업!M46+잇다카페_외부원두영업!M46+푸른솔!M46+의과대학!M46+중앙도서관!M46+학생회관!M46+멀티미디어관!M46+제2기숙사!M46+선승관!M46+예술디자인대!M46+공학관!M46 -> 0 | U46: =P46+Q46+R46+S46+T46 -> 5 | V46: =E46*U46 -> 26500 | W46: =(H46+N46)-U46 -> 11 | X46: =E46*W46 -> 58300 | Z46: 0 | AA46: =Z46*E46 -> 0
B47: 쿠키앤크림 파우더 | C47: 1kg x 12ea | D47: ea | E47: 6600 | F47: 12 | G47: 79200 | H47: 17 | L47: 0 | N47: =I47+J47+K47+L47+M47 -> 0 | O47: =E47*N47 -> 0 | P47: =캠퍼스타운_외부원두영업!I47+잇다카페_외부원두영업!I47+푸른솔!I47+의과대학!I47+중앙도서관!I47+학생회관!I47+멀티미디어관!I47+제2기숙사!I47+선승관!I47+예술디자인대!I47+공학관!I47 -> 1 | Q47: =캠퍼스타운_외부원두영업!J47+잇다카페_외부원두영업!J47+푸른솔!J47+의과대학!J47+중앙도서관!J47+학생회관!J47+멀티미디어관!J47+제2기숙사!J47+선승관!J47+예술디자인대!J47+공학관!J47 -> 3 | R47: =캠퍼스타운_외부원두영업!K47+잇다카페_외부원두영업!K47+푸른솔!K47+의과대학!K47+중앙도서관!K47+학생회관!K47+멀티미디어관!K47+제2기숙사!K47+선승관!K47+예술디자인대!K47+공학관!K47 -> 1 | S47: =캠퍼스타운_외부원두영업!L47+잇다카페_외부원두영업!L47+푸른솔!L47+의과대학!L47+중앙도서관!L47+학생회관!L47+멀티미디어관!L47+제2기숙사!L47+선승관!L47+예술디자인대!L47+공학관!L47 -> 6 | T47: =캠퍼스타운_외부원두영업!M47+잇다카페_외부원두영업!M47+푸른솔!M47+의과대학!M47+중앙도서관!M47+학생회관!M47+멀티미디어관!M47+제2기숙사!M47+선승관!M47+예술디자인대!M47+공학관!M47 -> 0 | U47: =P47+Q47+R47+S47+T47 -> 11 | V47: =E47*U47 -> 72600 | W47: =(H47+N47)-U47 -> 6 | X47: =E47*W47 -> 39600 | Z47: 0 | AA47: =Z47*E47 -> 0
B48: 자몽 베이스 | C48: 1.8kg x 6ea | D48: ea | E48: 14500 | F48: 6 | G48: 87000 | H48: 13 | L48: 24 | N48: =I48+J48+K48+L48+M48 -> 24 | O48: =E48*N48 -> 348000 | P48: =캠퍼스타운_외부원두영업!I48+잇다카페_외부원두영업!I48+푸른솔!I48+의과대학!I48+중앙도서관!I48+학생회관!I48+멀티미디어관!I48+제2기숙사!I48+선승관!I48+예술디자인대!I48+공학관!I48 -> 0 | Q48: =캠퍼스타운_외부원두영업!J48+잇다카페_외부원두영업!J48+푸른솔!J48+의과대학!J48+중앙도서관!J48+학생회관!J48+멀티미디어관!J48+제2기숙사!J48+선승관!J48+예술디자인대!J48+공학관!J48 -> 3 | R48: =캠퍼스타운_외부원두영업!K48+잇다카페_외부원두영업!K48+푸른솔!K48+의과대학!K48+중앙도서관!K48+학생회관!K48+멀티미디어관!K48+제2기숙사!K48+선승관!K48+예술디자인대!K48+공학관!K48 -> 3 | S48: =캠퍼스타운_외부원두영업!L48+잇다카페_외부원두영업!L48+푸른솔!L48+의과대학!L48+중앙도서관!L48+학생회관!L48+멀티미디어관!L48+제2기숙사!L48+선승관!L48+예술디자인대!L48+공학관!L48 -> 5 | T48: =캠퍼스타운_외부원두영업!M48+잇다카페_외부원두영업!M48+푸른솔!M48+의과대학!M48+중앙도서관!M48+학생회관!M48+멀티미디어관!M48+제2기숙사!M48+선승관!M48+예술디자인대!M48+공학관!M48 -> 0 | U48: =P48+Q48+R48+S48+T48 -> 11 | V48: =E48*U48 -> 159500 | W48: =(H48+N48)-U48 -> 26 | X48: =E48*W48 -> 377000 | Z48: 0 | AA48: =Z48*E48 -> 0
B49: 수박 베이스 | C49: 1.8kg x 6ea | D49: ea | E49: 11000 | F49: 6 | G49: 66000 | H49: 24 | L49: 0 | N49: =I49+J49+K49+L49+M49 -> 0 | O49: =E49*N49 -> 0 | P49: =캠퍼스타운_외부원두영업!I49+잇다카페_외부원두영업!I49+푸른솔!I49+의과대학!I49+중앙도서관!I49+학생회관!I49+멀티미디어관!I49+제2기숙사!I49+선승관!I49+예술디자인대!I49+공학관!I49 -> 1 | Q49: =캠퍼스타운_외부원두영업!J49+잇다카페_외부원두영업!J49+푸른솔!J49+의과대학!J49+중앙도서관!J49+학생회관!J49+멀티미디어관!J49+제2기숙사!J49+선승관!J49+예술디자인대!J49+공학관!J49 -> 0 | R49: =캠퍼스타운_외부원두영업!K49+잇다카페_외부원두영업!K49+푸른솔!K49+의과대학!K49+중앙도서관!K49+학생회관!K49+멀티미디어관!K49+제2기숙사!K49+선승관!K49+예술디자인대!K49+공학관!K49 -> 1 | S49: =캠퍼스타운_외부원두영업!L49+잇다카페_외부원두영업!L49+푸른솔!L49+의과대학!L49+중앙도서관!L49+학생회관!L49+멀티미디어관!L49+제2기숙사!L49+선승관!L49+예술디자인대!L49+공학관!L49 -> 1 | T49: =캠퍼스타운_외부원두영업!M49+잇다카페_외부원두영업!M49+푸른솔!M49+의과대학!M49+중앙도서관!M49+학생회관!M49+멀티미디어관!M49+제2기숙사!M49+선승관!M49+예술디자인대!M49+공학관!M49 -> 0 | U49: =P49+Q49+R49+S49+T49 -> 3 | V49: =E49*U49 -> 33000 | W49: =(H49+N49)-U49 -> 21 | X49: =E49*W49 -> 231000 | Z49: 0 | AA49: =Z49*E49 -> 0
B50: 17곡 파우더 | C50: 1kg x 12ea | D50: ea | E50: 4500 | F50: 12 | G50: 54000 | H50: 33 | L50: 0 | N50: =I50+J50+K50+L50+M50 -> 0 | O50: =E50*N50 -> 0 | P50: =캠퍼스타운_외부원두영업!I50+잇다카페_외부원두영업!I50+푸른솔!I50+의과대학!I50+중앙도서관!I50+학생회관!I50+멀티미디어관!I50+제2기숙사!I50+선승관!I50+예술디자인대!I50+공학관!I50 -> 0 | Q50: =캠퍼스타운_외부원두영업!J50+잇다카페_외부원두영업!J50+푸른솔!J50+의과대학!J50+중앙도서관!J50+학생회관!J50+멀티미디어관!J50+제2기숙사!J50+선승관!J50+예술디자인대!J50+공학관!J50 -> 3 | R50: =캠퍼스타운_외부원두영업!K50+잇다카페_외부원두영업!K50+푸른솔!K50+의과대학!K50+중앙도서관!K50+학생회관!K50+멀티미디어관!K50+제2기숙사!K50+선승관!K50+예술디자인대!K50+공학관!K50 -> 2 | S50: =캠퍼스타운_외부원두영업!L50+잇다카페_외부원두영업!L50+푸른솔!L50+의과대학!L50+중앙도서관!L50+학생회관!L50+멀티미디어관!L50+제2기숙사!L50+선승관!L50+예술디자인대!L50+공학관!L50 -> 4 | T50: =캠퍼스타운_외부원두영업!M50+잇다카페_외부원두영업!M50+푸른솔!M50+의과대학!M50+중앙도서관!M50+학생회관!M50+멀티미디어관!M50+제2기숙사!M50+선승관!M50+예술디자인대!M50+공학관!M50 -> 0 | U50: =P50+Q50+R50+S50+T50 -> 9 | V50: =E50*U50 -> 40500 | W50: =(H50+N50)-U50 -> 24 | X50: =E50*W50 -> 108000 | Z50: 0 | AA50: =Z50*E50 -> 0
B51: 토피넛파우더 | C51: 1box=12ea | D51: ea | E51: 6700 | F51: 12 | G51: 80400 | H51: 28 | L51: 12 | N51: =I51+J51+K51+L51+M51 -> 12 | O51: =E51*N51 -> 80400 | P51: =캠퍼스타운_외부원두영업!I51+잇다카페_외부원두영업!I51+푸른솔!I51+의과대학!I51+중앙도서관!I51+학생회관!I51+멀티미디어관!I51+제2기숙사!I51+선승관!I51+예술디자인대!I51+공학관!I51 -> 0 | Q51: =캠퍼스타운_외부원두영업!J51+잇다카페_외부원두영업!J51+푸른솔!J51+의과대학!J51+중앙도서관!J51+학생회관!J51+멀티미디어관!J51+제2기숙사!J51+선승관!J51+예술디자인대!J51+공학관!J51 -> 2 | R51: =캠퍼스타운_외부원두영업!K51+잇다카페_외부원두영업!K51+푸른솔!K51+의과대학!K51+중앙도서관!K51+학생회관!K51+멀티미디어관!K51+제2기숙사!K51+선승관!K51+예술디자인대!K51+공학관!K51 -> 3 | S51: =캠퍼스타운_외부원두영업!L51+잇다카페_외부원두영업!L51+푸른솔!L51+의과대학!L51+중앙도서관!L51+학생회관!L51+멀티미디어관!L51+제2기숙사!L51+선승관!L51+예술디자인대!L51+공학관!L51 -> 6 | T51: =캠퍼스타운_외부원두영업!M51+잇다카페_외부원두영업!M51+푸른솔!M51+의과대학!M51+중앙도서관!M51+학생회관!M51+멀티미디어관!M51+제2기숙사!M51+선승관!M51+예술디자인대!M51+공학관!M51 -> 0 | U51: =P51+Q51+R51+S51+T51 -> 11 | V51: =E51*U51 -> 73700 | W51: =(H51+N51)-U51 -> 29 | X51: =E51*W51 -> 194300 | Z51: 0 | AA51: =Z51*E51 -> 0
...

Sheet 캠퍼스타운_외부원두영업
A1: 카페 쿠피 3월 발주 관리 대장 (교육용,R&D,삼의원(잇다카페))
A4: 협력사 | B4: 품목명 | C4: 규격 | D4: 단위 | E4: 입고단가 | F4: 입고단위 | G4: 입고단위단가 | H4: 전월 재고 | I4: 1주차 발주 | J4: 2주차 발주 | K4: 3주차 발주 | L4: 4주차 발주 | M4: 5주차 발주 | N4: 월 발주량 | O4: 월 발주 금액
A5: 비스토리코리아 | B5: 종이컵(-12oz) | C5: 1box=1000ea | D5: ea | E5: 37 | F5: 1000 | G5: 37000 | N5: =I5+J5+K5+L5+M5 -> 0 | O5: =E5*N5 -> 0
B6: 종이컵-16oz | C6: 1box=1000ea | D6: ea | E6: 43 | F6: 1000 | G6: 43000 | N6: =I6+J6+K6+L6+M6 -> 0 | O6: =E6*N6 -> 0
B7: 종이컵뚜껑 (12,16oz) | C7: 1box=1000ea | D7: ea | E7: 20 | F7: 1000 | G7: 20000 | N7: =I7+J7+K7+L7+M7 -> 0 | O7: =E7*N7 -> 0
B8: 아이스(페트)컵(14oz) | C8: 1box=1000ea | D8: ea | E8: 42 | F8: 1000 | G8: 42000 | N8: =I8+J8+K8+L8+M8 -> 0 | O8: =E8*N8 -> 0
B9: 아이스컵(16oz) | C9: 1box=1000ea | D9: ea | E9: 53 | F9: 1000 | G9: 53000 | N9: =I9+J9+K9+L9+M9 -> 0 | O9: =E9*N9 -> 0
B10: 아이스컵(24oz) | C10: 1box=1000ea | D10: ea | E10: 65 | F10: 1000 | G10: 65000 | N10: =I10+J10+K10+L10+M10 -> 0 | O10: =E10*N10 -> 0
B11: 아이스컵 돔뚜껑(93Ø) | C11: 1box=1000ea | D11: ea | E11: 18.5 | F11: 1000 | G11: 18500 | N11: =I11+J11+K11+L11+M11 -> 0 | O11: =E11*N11 -> 0
B12: 아이스컵 돔뚜껑(98Ø) | C12: 1box=1000ea | D12: ea | E12: 20 | F12: 1000 | G12: 20000 | N12: =I12+J12+K12+L12+M12 -> 0 | O12: =E12*N12 -> 0
B13: 아이스컵 평뚜껑(98Ø) | C13: 1box=1000ea | D13: ea | E13: 19 | F13: 1000 | G13: 19000 | N13: =I13+J13+K13+L13+M13 -> 0 | O13: =E13*N13 -> 0
B14: 10/13홀더 (1도인쇄) | C14: 1box=1000ea | D14: ea | E14: 17.5 | F14: 1000 | G14: 17500 | N14: =I14+J14+K14+L14+M14 -> 0 | O14: =E14*N14 -> 0
B15: 12/16홀더(1도인쇄) | C15: 1box=1000ea | D15: ea | E15: 18 | F15: 1000 | G15: 18000 | N15: =I15+J15+K15+L15+M15 -> 0 | O15: =E15*N15 -> 0
B16: 21cm 일자 스트로우 (투명) | C16: 1box=10000ea | D16: ea | E16: 6.9 | F16: 10000 | G16: 69000 | N16: =I16+J16+K16+L16+M16 -> 0 | O16: =E16*N16 -> 0
B17: 21cm 버블티 스트로우 | C17: 1box=3200ea | D17: ea | E17: 22.1875 | F17: 3200 | G17: 71000 | N17: =I17+J17+K17+L17+M17 -> 0 | O17: =E17*N17 -> 0
... B37: 메티에 헤이즐럿시럽(700ml) | C37: 1box=8ea | D37: ea | E37: 6870 | F37: 8 | G37: 54960 | N37: =I37+J37+K37+L37+M37 -> 0 | O37: =E37*N37 -> 0
B38: 메티에 바닐라시럽(750ml) | C38: 1box=8ea | D38: ea | E38: 7360 | F38: 8 | G38: =E38*F38 -> 58880 | N38: =I38+J38+K38+L38+M38 -> 0 | O38: =E38*N38 -> 0
B39: 메티에 헤이즐럿시럽(750ml) | C39: 1box=8ea | D39: ea | E39: 7360 | F39: 8 | G39: =E39*F39 -> 58880 | N39: =I39+J39+K39+L39+M39 -> 0 | O39: =E39*N39 -> 0
A40: 성원애드피아 | B40: 적립쿠폰 | C40: 1bundle=500ea | D40: ea | E40: 6.4 | F40: 500 | G40: 3200 | N40: =I40+J40+K40+L40+M40 -> 0 | O40: =E40*N40 -> 0
B41: 유통기한 스티커 | C41: 1bundle=1000ea | D41: ea | E41: 4.69 | F41: 1000 | G41: 4690 | N41: =I41+J41+K41+L41+M41 -> 0 | O41: =E41*N41 -> 0
A42: 휴럼 | B42: 민트초코파우더 | C42: 1box = 12ea | D42: ea | E42: 7700 | F42: 12 | G42: 92400 | N42: =I42+J42+K42+L42+M42 -> 0 | O42: =E42*N42 -> 0
B43: 다크초코파우더 | C43: 1box = 12ea | D43: ea | E43: 6200 | F43: 12 | G43: 74400 | N43: =I43+J43+K43+L43+M43 -> 0 | O43: =E43*N43 -> 0
B44: 청귤베이스 | C44: 1box = 12ea | D44: ea | E44: 6700 | F44: 12 | G44: 80400 | N44: =I44+J44+K44+L44+M44 -> 0 | O44: =E44*N44 -> 0
B45: 요거에스플레인 | C45: 1box=12ea | D45: ea | E45: 7250 | F45: 12 | G45: 87000 | N45: =I45+J45+K45+L45+M45 -> 0 | O45: =E45*N45 -> 0
B46: 흑당베이스 | C46: 1kg x 12ea | D46: ea | E46: 5300 | F46: 12 | G46: 63600 | N46: =I46+J46+K46+L46+M46 -> 0 | O46: =E46*N46 -> 0
B47: 쿠키앤크림 파우더 | C47: 1kg x 12ea | D47: ea | E47: 6600 | F47: 12 | G47: 79200 | N47: =I47+J47+K47+L47+M47 -> 0 | O47: =E47*N47 -> 0
B48: 자몽 베이스 | C48: 1.8kg x 6ea | D48: ea | E48: 14500 | F48: 6 | G48: 87000 | N48: =I48+J48+K48+L48+M48 -> 0 | O48: =E48*N48 -> 0
B49: 수박 베이스 | C49: 1.8kg x 6ea | D49: ea | E49: 11000 | F49: 6 | G49: 66000 | N49: =I49+J49+K49+L49+M49 -> 0 | O49: =E49*N49 -> 0
B50: 17곡 파우더 | C50: 1kg x 12ea | D50: ea | E50: 4500 | F50: 12 | G50: 54000 | N50: =I50+J50+K50+L50+M50 -> 0 | O50: =E50*N50 -> 0
B51: 토피넛파우더 | C51: 1box=12ea | D51: ea | E51: 6700 | F51: 12 | G51: 80400 | N51: =I51+J51+K51+L51+M51 -> 0 | O51: =E51*N51 -> 0
A52: 세미기업 | B52: 딸기스무디 원액 | C52: 1.8kg x 6ea | D52: ea | E52: 6900 | F52: 6 | G52: 41400 | N52: =I52+J52+K52+L52+M52 -> 0 | O52: =E52*N52 -> 0
B53: 망고스무디 원액 | C53: 1.8kg x 6ea | D53: ea | E53: 6900 | F53: 6 | G53: 41400 | N53: =I53+J53+K53+L53+M53 -> 0 | O53: =E53*N53 -> 0
B54: 베리믹스스무디 원액 | C54: 1.8kg x 6ea | D54: ea | E54: 6800 | F54: 6 | G54: 40800 | N54: =I54+J54+K54+L54+M54 -> 0 | O54: =E54*N54 -> 0
B55: 베버시티 레몬에이드 | C55: 1kg x 4ea | D55: ea | E55: 15000 | F55: 4 | G55: 60000 | N55: =I55+J55+K55+L55+M55 -> 0 | O55: =E55*N55 -> 0
B56: 녹차라떼 | C56: 500g x 6ea | D56: ea | E56: 5300 | F56: 6 | G56: 31800 | N56: =I56+J56+K56+L56+M56 -> 0 | O56: =E56*N56 -> 0
B57: 홍차라떼 | C57: 500g x 6ea | D57: ea | E57: 6600 | F57: 6 | G57: 39600 | N57: =I57+J57+K57+L57+M57 -> 0 | O57: =E57*N57 -> 0
B58: 고구마페이스트 | C58: 1kg x 10ea | D58: ea | E58: 5600 | F58: 10 | G58: 56000 | N58: =I58+J58+K58+L58+M58 -> 0 | O58: =E58*N58 -> 0
B59: 토라니 초코소스 | C59: 1.89L x 4ea | D59: ea | E59: 14100 | F59: 4 | G59: 56400 | N59: =I59+J59+K59+L59+M59 -> 0 | O59: =E59*N59 -> 0
B60: 토라니 카라멜소스 | C60: 1.89L x 4ea | D60: ea | E60: 15100 | F60: 4 | G60: 60400 | N60: =I60+J60+K60+L60+M60 -> 0 | O60: =E60*N60 -> 0
B61: 베버시티 청포도에이드 | C61: 1kg x 4ea | D61: ea | E61: 15300 | F61: 4 | G61: 61200 | N61: =I61+J61+K61+L61+M61 -> 0 | O61: =E61*N61 -> 0
...

Sheet 잇다카페_외부원두영업
A1: 카페 쿠피 3월 발주 관리 대장 (교육용,R&D,삼의원(잇다카페))
A4: 협력사 | B4: 품목명 | C4: 규격 | D4: 단위 | E4: 입고단가 | F4: 입고단위 | G4: 입고단위단가 | H4: 전월 재고 | I4: 1주차 발주 | J4: 2주차 발주 | K4: 3주차 발주 | L4: 4주차 발주 | M4: 5주차 발주 | N4: 월 발주량 | O4: 월 발주 금액
A5: 비스토리코리아 | B5: 종이컵(-12oz) | C5: 1box=1000ea | D5: ea | E5: 37 | F5: 1000 | G5: 37000 | N5: =I5+J5+K5+L5+M5 -> 0 | O5: =E5*N5 -> 0
B6: 종이컵-16oz | C6: 1box=1000ea | D6: ea | E6: 43 | F6: 1000 | G6: 43000 | N6: =I6+J6+K6+L6+M6 -> 0 | O6: =E6*N6 -> 0
B7: 종이컵뚜껑 (12,16oz) | C7: 1box=1000ea | D7: ea | E7: 20 | F7: 1000 | G7: 20000 | N7: =I7+J7+K7+L7+M7 -> 0 | O7: =E7*N7 -> 0
B8: 아이스(페트)컵(14oz) | C8: 1box=1000ea | D8: ea | E8: 42 | F8: 1000 | G8: 42000 | N8: =I8+J8+K8+L8+M8 -> 0 | O8: =E8*N8 -> 0
B9: 아이스컵(16oz) | C9: 1box=1000ea | D9: ea | E9: 53 | F9: 1000 | G9: 53000 | N9: =I9+J9+K9+L9+M9 -> 0 | O9: =E9*N9 -> 0
B10: 아이스컵(24oz) | C10: 1box=1000ea | D10: ea | E10: 65 | F10: 1000 | G10: 65000 | N10: =I10+J10+K10+L10+M10 -> 0 | O10: =E10*N10 -> 0
B11: 아이스컵 돔뚜껑(93Ø) | C11: 1box=1000ea | D11: ea | E11: 18.5 | F11: 1000 | G11: 18500 | N11: =I11+J11+K11+L11+M11 -> 0 | O11: =E11*N11 -> 0
B12: 아이스컵 돔뚜껑(98Ø) | C12: 1box=1000ea | D12: ea | E12: 20 | F12: 1000 | G12: 20000 | N12: =I12+J12+K12+L12+M12 -> 0 | O12: =E12*N12 -> 0
B13: 아이스컵 평뚜껑(98Ø) | C13: 1box=1000ea | D13: ea | E13: 19 | F13: 1000 | G13: 19000 | N13: =I13+J13+K13+L13+M13 -> 0 | O13: =E13*N13 -> 0
B14: 10/13홀더 (1도인쇄) | C14: 1box=1000ea | D14: ea | E14: 17.5 | F14: 1000 | G14: 17500 | N14: =I14+J14+K14+L14+M14 -> 0 | O14: =E14*N14 -> 0
B15: 12/16홀더(1도인쇄) | C15: 1box=1000ea | D15: ea | E15: 18 | F15: 1000 | G15: 18000 | N15: =I15+J15+K15+L15+M15 -> 0 | O15: =E15*N15 -> 0
B16: 21cm 일자 스트로우 (투명) | C16: 1box=10000ea | D16: ea | E16: 6.9 | F16: 10000 | G16: 69000 | N16: =I16+J16+K16+L16+M16 -> 0 | O16: =E16*N16 -> 0
B17: 21cm 버블티 스트로우 | C17: 1box=3200ea | D17: ea | E17: 22.1875 | F17: 3200 | G17: 71000 | N17: =I17+J17+K17+L17+M17 -> 0 | O17: =E17*N17 -> 0
... B37: 메티에 헤이즐럿시럽(700ml) | C37: 1box=8ea | D37: ea | E37: 6870 | F37: 8 | G37: 54960 | N37: =I37+J37+K37+L37+M37 -> 0 | O37: =E37*N37 -> 0
B38: 메티에 바닐라시럽(750ml) | C38: 1box=8ea | D38: ea | E38: 7360 | F38: 8 | G38: =E38*F38 -> 58880 | N38: =I38+J38+K38+L38+M38 -> 0 | O38: =E38*N38 -> 0
B39: 메티에 헤이즐럿시럽(750ml) | C39: 1box=8ea | D39: ea | E39: 7360 | F39: 8 | G39: =E39*F39 -> 58880 | N39: =I39+J39+K39+L39+M39 -> 0 | O39: =E39*N39 -> 0
A40: 성원애드피아 | B40: 적립쿠폰 | C40: 1bundle=500ea | D40: ea | E40: 6.4 | F40: 500 | G40: 3200 | N40: =I40+J40+K40+L40+M40 -> 0 | O40: =E40*N40 -> 0
B41: 유통기한 스티커 | C41: 1bundle=1000ea | D41: ea | E41: 4.69 | F41: 1000 | G41: 4690 | N41: =I41+J41+K41+L41+M41 -> 0 | O41: =E41*N41 -> 0
A42: 휴럼 | B42: 민트초코파우더 | C42: 1box = 12ea | D42: ea | E42: 7700 | F42: 12 | G42: 92400 | N42: =I42+J42+K42+L42+M42 -> 0 | O42: =E42*N42 -> 0
B43: 다크초코파우더 | C43: 1box = 12ea | D43: ea | E43: 6200 | F43: 12 | G43: 74400 | N43: =I43+J43+K43+L43+M43 -> 0 | O43: =E43*N43 -> 0
B44: 청귤베이스 | C44: 1box = 12ea | D44: ea | E44: 6700 | F44: 12 | G44: 80400 | N44: =I44+J44+K44+L44+M44 -> 0 | O44: =E44*N44 -> 0
B45: 요거에스플레인 | C45: 1box=12ea | D45: ea | E45: 7250 | F45: 12 | G45: 87000 | N45: =I45+J45+K45+L45+M45 -> 0 | O45: =E45*N45 -> 0
B46: 흑당베이스 | C46: 1kg x 12ea | D46: ea | E46: 5300 | F46: 12 | G46: 63600 | N46: =I46+J46+K46+L46+M46 -> 0 | O46: =E46*N46 -> 0
B47: 쿠키앤크림 파우더 | C47: 1kg x 12ea | D47: ea | E47: 6600 | F47: 12 | G47: 79200 | N47: =I47+J47+K47+L47+M47 -> 0 | O47: =E47*N47 -> 0
B48: 자몽 베이스 | C48: 1.8kg x 6ea | D48: ea | E48: 14500 | F48: 6 | G48: 87000 | N48: =I48+J48+K48+L48+M48 -> 0 | O48: =E48*N48 -> 0
B49: 수박 베이스 | C49: 1.8kg x 6ea | D49: ea | E49: 11000 | F49: 6 | G49: 66000 | N49: =I49+J49+K49+L49+M49 -> 0 | O49: =E49*N49 -> 0
B50: 17곡 파우더 | C50: 1kg x 12ea | D50: ea | E50: 4500 | F50: 12 | G50: 54000 | N50: =I50+J50+K50+L50+M50 -> 0 | O50: =E50*N50 -> 0
B51: 토피넛파우더 | C51: 1box=12ea | D51: ea | E51: 6700 | F51: 12 | G51: 80400 | N51: =I51+J51+K51+L51+M51 -> 0 | O51: =E51*N51 -> 0
A52: 세미기업 | B52: 딸기스무디 원액 | C52: 1.8kg x 6ea | D52: ea | E52: 6900 | F52: 6 | G52: 41400 | N52: =I52+J52+K52+L52+M52 -> 0 | O52: =E52*N52 -> 0
B53: 망고스무디 원액 | C53: 1.8kg x 6ea | D53: ea | E53: 6900 | F53: 6 | G53: 41400 | N53: =I53+J53+K53+L53+M53 -> 0 | O53: =E53*N53 -> 0
B54: 베리믹스스무디 원액 | C54: 1.8kg x 6ea | D54: ea | E54: 6800 | F54: 6 | G54: 40800 | N54: =I54+J54+K54+L54+M54 -> 0 | O54: =E54*N54 -> 0
B55: 베버시티 레몬에이드 | C55: 1kg x 4ea | D55: ea | E55: 15000 | F55: 4 | G55: 60000 | N55: =I55+J55+K55+L55+M55 -> 0 | O55: =E55*N55 -> 0
B56: 녹차라떼 | C56: 500g x 6ea | D56: ea | E56: 5300 | F56: 6 | G56: 31800 | N56: =I56+J56+K56+L56+M56 -> 0 | O56: =E56*N56 -> 0
B57: 홍차라떼 | C57: 500g x 6ea | D57: ea | E57: 6600 | F57: 6 | G57: 39600 | N57: =I57+J57+K57+L57+M57 -> 0 | O57: =E57*N57 -> 0
B58: 고구마페이스트 | C58: 1kg x 10ea | D58: ea | E58: 5600 | F58: 10 | G58: 56000 | N58: =I58+J58+K58+L58+M58 -> 0 | O58: =E58*N58 -> 0
B59: 토라니 초코소스 | C59: 1.89L x 4ea | D59: ea | E59: 14100 | F59: 4 | G59: 56400 | N59: =I59+J59+K59+L59+M59 -> 0 | O59: =E59*N59 -> 0
B60: 토라니 카라멜소스 | C60: 1.89L x 4ea | D60: ea | E60: 15100 | F60: 4 | G60: 60400 | N60: =I60+J60+K60+L60+M60 -> 0 | O60: =E60*N60 -> 0
B61: 베버시티 청포도에이드 | C61: 1kg x 4ea | D61: ea | E61: 15300 | F61: 4 | G61: 61200 | N61: =I61+J61+K61+L61+M61 -> 0 | O61: =E61*N61 -> 0
...

Sheet 푸른솔
A1: 카페 쿠피 3월 발주 관리 대장 (푸른솔)
A4: 협력사 | B4: 품목명 | C4: 규격 | D4: 단위 | E4: 입고단가 | F4: 입고단위 | G4: 입고단위단가 | H4: 전월 재고 | I4: 1주차 발주 | J4: 2주차 발주 | K4: 3주차 발주 | L4: 4주차 발주 | M4: 5주차 발주 | N4: 월 발주량 | O4: 월 발주 금액
A5: 비스토리코리아 | B5: 종이컵(-12oz) | C5: 1box=1000ea | D5: ea | E5: 37 | F5: 1000 | G5: 37000 | N5: =I5+J5+K5+L5+M5 -> 0 | O5: =E5*N5 -> 0
B6: 종이컵-16oz | C6: 1box=1000ea | D6: ea | E6: 43 | F6: 1000 | G6: 43000 | H6: 550 | L6: 1000 | N6: =I6+J6+K6+L6+M6 -> 1000 | O6: =E6*N6 -> 43000
B7: 종이컵뚜껑 (12,16oz) | C7: 1box=1000ea | D7: ea | E7: 20 | F7: 1000 | G7: 20000 | H7: 400 | L7: 1000 | N7: =I7+J7+K7+L7+M7 -> 1000 | O7: =E7*N7 -> 20000
B8: 아이스(페트)컵(14oz) | C8: 1box=1000ea | D8: ea | E8: 42 | F8: 1000 | G8: 42000 | N8: =I8+J8+K8+L8+M8 -> 0 | O8: =E8*N8 -> 0
B9: 아이스컵(16oz) | C9: 1box=1000ea | D9: ea | E9: 53 | F9: 1000 | G9: 53000 | H9: 850 | K9: 1000 | N9: =I9+J9+K9+L9+M9 -> 1000 | O9: =E9*N9 -> 53000
B10: 아이스컵(24oz) | C10: 1box=1000ea | D10: ea | E10: 65 | F10: 1000 | G10: 65000 | H10: 1200 | N10: =I10+J10+K10+L10+M10 -> 0 | O10: =E10*N10 -> 0
B11: 아이스컵 돔뚜껑(93Ø) | C11: 1box=1000ea | D11: ea | E11: 18.5 | F11: 1000 | G11: 18500 | H11: 900 | K11: 1000 | N11: =I11+J11+K11+L11+M11 -> 1000 | O11: =E11*N11 -> 18500
B12: 아이스컵 돔뚜껑(98Ø) | C12: 1box=1000ea | D12: ea | E12: 20 | F12: 1000 | G12: 20000 | H12: 150 | N12: =I12+J12+K12+L12+M12 -> 0 | O12: =E12*N12 -> 0
B13: 아이스컵 평뚜껑(98Ø) | C13: 1box=1000ea | D13: ea | E13: 19 | F13: 1000 | G13: 19000 | H13: 1000 | N13: =I13+J13+K13+L13+M13 -> 0 | O13: =E13*N13 -> 0
B14: 10/13홀더 (1도인쇄) | C14: 1box=1000ea | D14: ea | E14: 17.5 | F14: 1000 | G14: 17500 | N14: =I14+J14+K14+L14+M14 -> 0 | O14: =E14*N14 -> 0
B15: 12/16홀더(1도인쇄) | C15: 1box=1000ea | D15: ea | E15: 18 | F15: 1000 | G15: 18000 | K15: 1000 | L15: 1000 | N15: =I15+J15+K15+L15+M15 -> 2000 | O15: =E15*N15 -> 36000
B16: 21cm 일자 스트로우 (투명) | C16: 1box=10000ea | D16: ea | E16: 6.9 | F16: 10000 | G16: 69000 | H16: 500 | K16: 500 | L16: 500 | N16: =I16+J16+K16+L16+M16 -> 1000 | O16: =E16*N16 -> 6900
B17: 21cm 버블티 스트로우 | C17: 1box=3200ea | D17: ea | E17: 22.1875 | F17: 3200 | G17: 71000 | H17: 200 | N17: =I17+J17+K17+L17+M17 -> 0 | O17: =E17*N17 -> 0
B18: 25cm 일자 스트로우 (블랙) | C18: 1box=10000ea | D18: ea | E18: 7.2 | F18: 10000 | G18: 72000 | H18: 1000 | N18: =I18+J18+K18+L18+M18 -> 0 | O18: =E18*N18 -> 0
B19: 21cm 종이 스트로우 | C19: 1box=5000ea | D19: ea | E19: 18 | F19: 5000 | G19: 90000 | N19: =I19+J19+K19+L19+M19 -> 0 | O19: =E19*N19 -> 0
B20: 21cm 종이 버블 스트로우 | C20: 1box=4000ea | D20: ea | E20: 26.7 | F20: 4000 | G20: 106800 | H20: 400 | N20: =I20+J20+K20+L20+M20 -> 0 | O20: =E20*N20 -> 0
B21: 25cm 버블티 스트로우 | C21: 1box=3200ea | D21: ea | E21: 22.8125 | F21: 3200 | G21: 73000 | H21: 200 | N21: =I21+J21+K21+L21+M21 -> 0 | O21: =E21*N21 -> 0
B22: 캐리어 무지(크라프트지) | C22: 1box=200ea | D22: ea | E22: 112.5 | F22: 200 | G22: 22500 | H22: 200 | N22: =I22+J22+K22+L22+M22 -> 0 | O22: =E22*N22 -> 0
B23: 갈색무지냅킨 | C23: 1box=8000ea | D23: ea | E23: 3.625 | F23: 8000 | G23: 29000 | H23: 7200 | N23: =I23+J23+K23+L23+M23 -> 0 | O23: =E23*N23 -> 0
B24: 커피머신세정제 | C24: 1ea | D24: kg | E24: 12000 | F24: 1 | G24: 12000 | N24: =I24+J24+K24+L24+M24 -> 0 | O24: =E24*N24 -> 0
B25: 15cm 개별포장커피스틱 | C25: 1box=10000ea | D25: ea | E25: 6.4 | F25: 10000 | G25: 64000 | H25: 2000 | N25: =I25+J25+K25+L25+M25 -> 0 | O25: =E25*N25 -> 0
B26: 18cm 개별포장커피스틱 | C26: 1box=10000ea | D26: ea | E26: 6.8 | F26: 10000 | G26: 68000 | N26: =I26+J26+K26+L26+M26 -> 0 | O26: =E26*N26 -> 0
B27: opp 비닐봉투 18*25 | C27: 1pack=200ea | D27: ea | E27: 25 | F27: 200 | G27: 5000 | N27: =I27+J27+K27+L27+M27 -> 0 | O27: =E27*N27 -> 0
B28: 콤부차오리지날 | C28: 1box=12ea | D28: ea | E28: 2100 | F28: 12 | G28: 25200 | H28: 15 | N28: =I28+J28+K28+L28+M28 -> 0 | O28: =E28*N28 -> 0
B29: 콤부차진저레몬 | C29: 1box=12ea | D29: ea | E29: 2100 | F29: 12 | G29: 25200 | H29: 12 | N29: =I29+J29+K29+L29+M29 -> 0 | O29: =E29*N29 -> 0
B30: 콤부차석류 | C30: 1box=12ea | D30: ea | E30: 2100 | F30: 12 | G30: 25200 | H30: 4 | N30: =I30+J30+K30+L30+M30 -> 0 | O30: =E30*N30 -> 0
B31: 슈가시럽 | C31: 1box=6ea | D31: ea | E31: 2800 | F31: 6 | G31: 16800 | H31: 2 | N31: =I31+J31+K31+L31+M31 -> 0 | O31: =E31*N31 -> 0
B32: 슈가시럽(24년인상) | C32: 1box=6ea | D32: ea | E32: 3200 | F32: 6 | G32: 19200 | L32: 1 | N32: =I32+J32+K32+L32+M32 -> 1 | O32: =E32*N32 -> 3200
B33: 삼다수 | C33: 1box=20ea | D33: ea | E33: 410 | F33: 20 | G33: 8200 | H33: 18 | N33: =I33+J33+K33+L33+M33 -> 0 | O33: =E33*N33 -> 0
B34: 립톤 복숭아파우더(907g) | C34: 1box=12ea | D34: ea | E34: 7200 | F34: 12 | G34: 86400 | H34: 8 | J34: 2 | K34: 3 | L34: 2 | N34: =I34+J34+K34+L34+M34 -> 7 | O34: =E34*N34 -> 50400
B35: 초정탄산수(1.5L) | C35: 1box=12ea | D35: ea | E35: 1350 | F35: 12 | G35: 16200 | H35: 5 | J35: 2 | K35: 4 | N35: =I35+J35+K35+L35+M35 -> 6 | O35: =E35*N35 -> 8100
B36: 메티에 바닐라시럽(700ml) | C36: 1box=8ea | D36: ea | E36: 6870 | F36: 8 | G36: 54960 | H36: 3 | I36: 1 | K36: 3 | L36: 1 | N36: =I36+J36+K36+L36+M36 -> 5 | O36: =E36*N36 -> 34350
B37: 메티에 헤이즐럿시럽(700ml) | C37: 1box=8ea | D37: ea | E37: 6870 | F37: 8 | G37: 54960 | H37: 2 | K37: 1 | L37: 1 | N37: =I37+J37+K37+L37+M37 -> 2 | O37: =E37*N37 -> 13740
B38: 메티에 바닐라시럽(750ml) | C38: 1box=8ea | D38: ea | E38: 7360 | F38: 8 | G38: =E38*F38 -> 58880 | N38: =I38+J38+K38+L38+M38 -> 0 | O38: =E38*N38 -> 0
B39: 메티에 헤이즐럿시럽(750ml) | C39: 1box=8ea | D39: ea | E39: 7360 | F39: 8 | G39: =E39*F39 -> 58880 | N39: =I39+J39+K39+L39+M39 -> 0 | O39: =E39*N39 -> 0
A40: 성원애드피아 | B40: 적립쿠폰 | C40: 1bundle=500ea | D40: ea | E40: 6.4 | F40: 500 | G40: 3200 | I40: 200 | K40: 100 | N40: =I40+J40+K40+L40+M40 -> 300 | O40: =E40*N40 -> 1920
B41: 유통기한 스티커 | C41: 1bundle=1000ea | D41: ea | E41: 4.69 | F41: 1000 | G41: 4690 | N41: =I41+J41+K41+L41+M41 -> 0 | O41: =E41*N41 -> 0
A42: 휴럼 | B42: 민트초코파우더 | C42: 1box = 12ea | D42: ea | E42: 7700 | F42: 12 | G42: 92400 | H42: 2 | N42: =I42+J42+K42+L42+M42 -> 0 | O42: =E42*N42 -> 0
...

Sheet 의과대학
A1: 카페 쿠피 3월 발주 관리 대장 (의과대학)
A4: 협력사 | B4: 품목명 | C4: 규격 | D4: 단위 | E4: 입고단가 | F4: 입고단위 | G4: 입고단위단가 | H4: 전월 재고 | I4: 1주차 발주 | J4: 2주차 발주 | K4: 3주차 발주 | L4: 4주차 발주 | M4: 5주차 발주 | N4: 월 발주량 | O4: 월 발주 금액
A5: 비스토리코리아 | B5: 종이컵(-12oz) | C5: 1box=1000ea | D5: ea | E5: 37 | F5: 1000 | G5: 37000 | H5: 800 | N5: =I5+J5+K5+L5+M5 -> 0 | O5: =E5*N5 -> 0
B6: 종이컵-16oz | C6: 1box=1000ea | D6: ea | E6: 43 | F6: 1000 | G6: 43000 | H6: 1150 | N6: =I6+J6+K6+L6+M6 -> 0 | O6: =E6*N6 -> 0
B7: 종이컵뚜껑 (12,16oz) | C7: 1box=1000ea | D7: ea | E7: 20 | F7: 1000 | G7: 20000 | H7: 700 | N7: =I7+J7+K7+L7+M7 -> 0 | O7: =E7*N7 -> 0
B8: 아이스(페트)컵(14oz) | C8: 1box=1000ea | D8: ea | E8: 42 | F8: 1000 | G8: 42000 | N8: =I8+J8+K8+L8+M8 -> 0 | O8: =E8*N8 -> 0
B9: 아이스컵(16oz) | C9: 1box=1000ea | D9: ea | E9: 53 | F9: 1000 | G9: 53000 | H9: 1550 | N9: =I9+J9+K9+L9+M9 -> 0 | O9: =E9*N9 -> 0
B10: 아이스컵(24oz) | C10: 1box=1000ea | D10: ea | E10: 65 | F10: 1000 | G10: 65000 | H10: 500 | N10: =I10+J10+K10+L10+M10 -> 0 | O10: =E10*N10 -> 0
B11: 아이스컵 돔뚜껑(93Ø) | C11: 1box=1000ea | D11: ea | E11: 18.5 | F11: 1000 | G11: 18500 | H11: 1100 | N11: =I11+J11+K11+L11+M11 -> 0 | O11: =E11*N11 -> 0
B12: 아이스컵 돔뚜껑(98Ø) | C12: 1box=1000ea | D12: ea | E12: 20 | F12: 1000 | G12: 20000 | H12: 550 | N12: =I12+J12+K12+L12+M12 -> 0 | O12: =E12*N12 -> 0
B13: 아이스컵 평뚜껑(98Ø) | C13: 1box=1000ea | D13: ea | E13: 19 | F13: 1000 | G13: 19000 | N13: =I13+J13+K13+L13+M13 -> 0 | O13: =E13*N13 -> 0
B14: 10/13홀더 (1도인쇄) | C14: 1box=1000ea | D14: ea | E14: 17.5 | F14: 1000 | G14: 17500 | N14: =I14+J14+K14+L14+M14 -> 0 | O14: =E14*N14 -> 0
B15: 12/16홀더(1도인쇄) | C15: 1box=1000ea | D15: ea | E15: 18 | F15: 1000 | G15: 18000 | H15: 1000 | N15: =I15+J15+K15+L15+M15 -> 0 | O15: =E15*N15 -> 0
B16: 21cm 일자 스트로우 (투명) | C16: 1box=10000ea | D16: ea | E16: 6.9 | F16: 10000 | G16: 69000 | H16: 1000 | N16: =I16+J16+K16+L16+M16 -> 0 | O16: =E16*N16 -> 0
B17: 21cm 버블티 스트로우 | C17: 1box=3200ea | D17: ea | E17: 22.1875 | F17: 3200 | G17: 71000 | H17: 200 | N17: =I17+J17+K17+L17+M17 -> 0 | O17: =E17*N17 -> 0
B18: 25cm 일자 스트로우 (블랙) | C18: 1box=10000ea | D18: ea | E18: 7.2 | F18: 10000 | G18: 72000 | H18: 1000 | N18: =I18+J18+K18+L18+M18 -> 0 | O18: =E18*N18 -> 0
B19: 21cm 종이 스트로우 | C19: 1box=5000ea | D19: ea | E19: 18 | F19: 5000 | G19: 90000 | N19: =I19+J19+K19+L19+M19 -> 0 | O19: =E19*N19 -> 0
B20: 21cm 종이 버블 스트로우 | C20: 1box=4000ea | D20: ea | E20: 26.7 | F20: 4000 | G20: 106800 | N20: =I20+J20+K20+L20+M20 -> 0 | O20: =E20*N20 -> 0
B21: 25cm 버블티 스트로우 | C21: 1box=3200ea | D21: ea | E21: 22.8125 | F21: 3200 | G21: 73000 | H21: 200 | N21: =I21+J21+K21+L21+M21 -> 0 | O21: =E21*N21 -> 0
B22: 캐리어 무지(크라프트지) | C22: 1box=200ea | D22: ea | E22: 112.5 | F22: 200 | G22: 22500 | H22: 125 | N22: =I22+J22+K22+L22+M22 -> 0 | O22: =E22*N22 -> 0
B23: 갈색무지냅킨 | C23: 1box=8000ea | D23: ea | E23: 3.625 | F23: 8000 | G23: 29000 | H23: 1200 | N23: =I23+J23+K23+L23+M23 -> 0 | O23: =E23*N23 -> 0
B24: 커피머신세정제 | C24: 1ea | D24: kg | E24: 12000 | F24: 1 | G24: 12000 | N24: =I24+J24+K24+L24+M24 -> 0 | O24: =E24*N24 -> 0
B25: 15cm 개별포장커피스틱 | C25: 1box=10000ea | D25: ea | E25: 6.4 | F25: 10000 | G25: 64000 | H25: 4000 | N25: =I25+J25+K25+L25+M25 -> 0 | O25: =E25*N25 -> 0
B26: 18cm 개별포장커피스틱 | C26: 1box=10000ea | D26: ea | E26: 6.8 | F26: 10000 | G26: 68000 | N26: =I26+J26+K26+L26+M26 -> 0 | O26: =E26*N26 -> 0
B27: opp 비닐봉투 18*25 | C27: 1pack=200ea | D27: ea | E27: 25 | F27: 200 | G27: 5000 | N27: =I27+J27+K27+L27+M27 -> 0 | O27: =E27*N27 -> 0
B28: 콤부차오리지날 | C28: 1box=12ea | D28: ea | E28: 2100 | F28: 12 | G28: 25200 | N28: =I28+J28+K28+L28+M28 -> 0 | O28: =E28*N28 -> 0
B29: 콤부차진저레몬 | C29: 1box=12ea | D29: ea | E29: 2100 | F29: 12 | G29: 25200 | N29: =I29+J29+K29+L29+M29 -> 0 | O29: =E29*N29 -> 0
B30: 콤부차석류 | C30: 1box=12ea | D30: ea | E30: 2100 | F30: 12 | G30: 25200 | N30: =I30+J30+K30+L30+M30 -> 0 | O30: =E30*N30 -> 0
B31: 슈가시럽 | C31: 1box=6ea | D31: ea | E31: 2800 | F31: 6 | G31: 16800 | N31: =I31+J31+K31+L31+M31 -> 0 | O31: =E31*N31 -> 0
B32: 슈가시럽(24년인상) | C32: 1box=6ea | D32: ea | E32: 3200 | F32: 6 | G32: 19200 | L32: 1 | N32: =I32+J32+K32+L32+M32 -> 1 | O32: =E32*N32 -> 3200
B33: 삼다수 | C33: 1box=20ea | D33: ea | E33: 410 | F33: 20 | G33: 8200 | H33: 1 | N33: =I33+J33+K33+L33+M33 -> 0 | O33: =E33*N33 -> 0
B34: 립톤 복숭아파우더(907g) | C34: 1box=12ea | D34: ea | E34: 7200 | F34: 12 | G34: 86400 | H34: 5 | K34: 2 | N34: =I34+J34+K34+L34+M34 -> 2 | O34: =E34*N34 -> 14400
B35: 초정탄산수(1.5L) | C35: 1box=12ea | D35: ea | E35: 1350 | F35: 12 | G35: 16200 | H35: 5 | N35: =I35+J35+K35+L35+M35 -> 0 | O35: =E35*N35 -> 0
B36: 메티에 바닐라시럽(700ml) | C36: 1box=8ea | D36: ea | E36: 6870 | F36: 8 | G36: 54960 | H36: 1 | L36: 1 | N36: =I36+J36+K36+L36+M36 -> 1 | O36: =E36*N36 -> 6870
B37: 메티에 헤이즐럿시럽(700ml) | C37: 1box=8ea | D37: ea | E37: 6870 | F37: 8 | G37: 54960 | H37: 1 | N37: =I37+J37+K37+L37+M37 -> 0 | O37: =E37*N37 -> 0
B38: 메티에 바닐라시럽(750ml) | C38: 1box=8ea | D38: ea | E38: 7360 | F38: 8 | G38: =E38*F38 -> 58880 | N38: =I38+J38+K38+L38+M38 -> 0 | O38: =E38*N38 -> 0
B39: 메티에 헤이즐럿시럽(750ml) | C39: 1box=8ea | D39: ea | E39: 7360 | F39: 8 | G39: =E39*F39 -> 58880 | N39: =I39+J39+K39+L39+M39 -> 0 | O39: =E39*N39 -> 0
A40: 성원애드피아 | B40: 적립쿠폰 | C40: 1bundle=500ea | D40: ea | E40: 6.4 | F40: 500 | G40: 3200 | I40: 100 | N40: =I40+J40+K40+L40+M40 -> 100 | O40: =E40*N40 -> 640
B41: 유통기한 스티커 | C41: 1bundle=1000ea | D41: ea | E41: 4.69 | F41: 1000 | G41: 4690 | N41: =I41+J41+K41+L41+M41 -> 0 | O41: =E41*N41 -> 0
A42: 휴럼 | B42: 민트초코파우더 | C42: 1box = 12ea | D42: ea | E42: 7700 | F42: 12 | G42: 92400 | H42: 1 | N42: =I42+J42+K42+L42+M42 -> 0 | O42: =E42*N42 -> 0
...

Sheet 중앙도서관
A1: 카페 쿠피 3월 발주 관리 대장 (중앙도서관)
A4: 협력사 | B4: 품목명 | C4: 규격 | D4: 단위 | E4: 입고단가 | F4: 입고단위 | G4: 입고단위단가 | H4: 전월 재고 | I4: 1주차 발주 | J4: 2주차 발주 | K4: 3주차 발주 | L4: 4주차 발주 | M4: 5주차 발주 | N4: 월 발주량 | O4: 월 발주 금액
A5: 비스토리코리아 | B5: 종이컵(-12oz) | C5: 1box=1000ea | D5: ea | E5: 37 | F5: 1000 | G5: 37000 | N5: =I5+J5+K5+L5+M5 -> 0 | O5: =E5*N5 -> 0
B6: 종이컵-16oz | C6: 1box=1000ea | D6: ea | E6: 43 | F6: 1000 | G6: 43000 | H6: 200 | J6: 1000 | N6: =I6+J6+K6+L6+M6 -> 1000 | O6: =E6*N6 -> 43000
B7: 종이컵뚜껑 (12,16oz) | C7: 1box=1000ea | D7: ea | E7: 20 | F7: 1000 | G7: 20000 | H7: 400 | N7: =I7+J7+K7+L7+M7 -> 0 | O7: =E7*N7 -> 0
B8: 아이스(페트)컵(14oz) | C8: 1box=1000ea | D8: ea | E8: 42 | F8: 1000 | G8: 42000 | N8: =I8+J8+K8+L8+M8 -> 0 | O8: =E8*N8 -> 0
B9: 아이스컵(16oz) | C9: 1box=1000ea | D9: ea | E9: 53 | F9: 1000 | G9: 53000 | H9: 600 | J9: 1000 | N9: =I9+J9+K9+L9+M9 -> 1000 | O9: =E9*N9 -> 53000
B10: 아이스컵(24oz) | C10: 1box=1000ea | D10: ea | E10: 65 | F10: 1000 | G10: 65000 | H10: 400 | N10: =I10+J10+K10+L10+M10 -> 0 | O10: =E10*N10 -> 0
B11: 아이스컵 돔뚜껑(93Ø) | C11: 1box=1000ea | D11: ea | E11: 18.5 | F11: 1000 | G11: 18500 | H11: 1200 | L11: 1000 | N11: =I11+J11+K11+L11+M11 -> 1000 | O11: =E11*N11 -> 18500
B12: 아이스컵 돔뚜껑(98Ø) | C12: 1box=1000ea | D12: ea | E12: 20 | F12: 1000 | G12: 20000 | H12: 250 | N12: =I12+J12+K12+L12+M12 -> 0 | O12: =E12*N12 -> 0
